<?xml version="1.0" ?>
<!-- =================================================================================== -->
<!-- |    This document was autogenerated by xacro from robot.xacro                    | -->
<!-- |    EDITING THIS FILE BY HAND IS NOT RECOMMENDED                                 | -->
<!-- =================================================================================== -->
<robot name="galbot_one">
  <link name="torso_base_link">
    <inertial>
      <origin xyz="0.009452 -0.0097068 -0.041989"/>
      <mass value="1.5697"/>
      <inertia ixx="0.018397" ixy="-6.5897E-07" ixz="0.00030036" iyy="0.013058" iyz="0.00016843" izz="0.0082332"/>
    </inertial>
    <visual>
      <geometry>
        <mesh filename="package://galbot_one_description/meshes/torso/torso_base_link.glb"/>
      </geometry>
    </visual>
    <collision>
      <origin xyz="0 0 0.3035"/>
      <geometry>
        <box size="0.232789 0.271990 0.248400"/>
      </geometry>
    </collision>
    <collision>
      <origin xyz="0 0 0.0965"/>
      <geometry>
        <box size="0.155192 0.181326 0.165600"/>
      </geometry>
    </collision>
  </link>
  <!-- omni_chassis_leg_mount_link and its joint come from chassis.xacro -->
  <joint name="leg_joint" type="fixed">
    <origin rpy="1.5707963267948966 0 0"/>
    <parent link="omni_chassis_leg_mount_link"/>
    <child link="leg_base_link"/>
  </joint>
  <link name="leg_base_link">
    <inertial>
      <origin xyz="0.0027248 -0.094364 -0.050137"/>
      <mass value="0.91885"/>
      <inertia ixx="0.0043203" ixy="6.1508E-05" ixz="8.9569E-05" iyy="0.0039878" iyz="-0.0010684" izz="0.0027984"/>
    </inertial>
    <visual>
      <geometry>
        <mesh filename="package://galbot_one_description/meshes/leg/leg_base.glb"/>
      </geometry>
    </visual>
  </link>
  <link name="leg_link1">
    <inertial>
      <origin xyz="0.23294 -0.0052987 0.0039698"/>
      <mass value="4.7692"/>
      <inertia ixx="0.019082" ixy="-0.0011116" ixz="0.00034191" iyy="0.16145" iyz="-6.2146E-05" izz="0.15826"/>
    </inertial>
    <visual>
      <geometry>
        <mesh filename="package://galbot_one_description/meshes/leg/leg_link1.glb"/>
      </geometry>
    </visual>
  </link>
  <joint name="leg_joint1" type="revolute">
    <origin rpy="-3.141592653589793 0 2.756573021" xyz="0 0 -0.087"/>
    <parent link="leg_base_link"/>
    <child link="leg_link1"/>
    <axis xyz="0 0 1"/>
    <limit effort="169" lower="0" upper="0.994837674" velocity="2.3"/>
  </joint>
  <link name="leg_link2">
    <inertial>
      <origin xyz="0.19637 2.4915E-06 0.0034234"/>
      <mass value="3.6233"/>
      <inertia ixx="0.0054462" ixy="-2.1435E-06" ixz="-2.9611E-05" iyy="0.066819" iyz="5.2347E-08" izz="0.071791"/>
    </inertial>
    <visual>
      <geometry>
        <mesh filename="package://galbot_one_description/meshes/leg/leg_link2.glb"/>
      </geometry>
    </visual>
  </link>
  <joint name="leg_joint2" type="revolute">
    <origin rpy="-3.141592653589793 0 2.756573021" xyz="0.45 0 0"/>
    <parent link="leg_link1"/>
    <child link="leg_link2"/>
    <axis xyz="0 0 1"/>
    <limit effort="169" lower="0" upper="3.141592653589793" velocity="2.3"/>
  </joint>
  <link name="leg_link3">
    <inertial>
      <origin xyz="-1.1016E-05 0.012237 0.0042074"/>
      <mass value="1.7624"/>
      <inertia ixx="0.006745" ixy="-4.1776E-07" ixz="8.7932E-07" iyy="0.0066437" iyz="9.063E-05" izz="0.0073862"/>
    </inertial>
    <visual>
      <geometry>
        <mesh filename="package://galbot_one_description/meshes/leg/leg_link3.glb"/>
      </geometry>
    </visual>
  </link>
  <joint name="leg_joint3" type="revolute">
    <origin rpy="-3.141592653589793 0 -3.141592653589793" xyz="0.39 0 0"/>
    <parent link="leg_link2"/>
    <child link="leg_link3"/>
    <axis xyz="0 0 1"/>
    <limit effort="84" lower="0" upper="2.356194490192345" velocity="2.83"/>
  </joint>
  <link name="leg_link4">
    <inertial>
      <origin xyz="5.7927E-05 -3.0701E-05 0.15111"/>
      <mass value="0.37584"/>
      <inertia ixx="0.00049514" ixy="-3.0213E-07" ixz="-3.9055E-09" iyy="0.00051468" iyz="1.3486E-09" izz="0.00084078"/>
    </inertial>
    <visual>
      <geometry>
        <mesh filename="package://galbot_one_description/meshes/leg/leg_link4.glb"/>
      </geometry>
    </visual>
  </link>
  <joint name="leg_joint4" type="revolute">
    <origin rpy="1.5707963267948966 0 -3.141592653589793"/>
    <parent link="leg_link3"/>
    <child link="leg_link4"/>
    <axis xyz="0 0 1"/>
    <limit effort="30" lower="-1.5707963267948966" upper="1.5707963267948966" velocity="3.56"/>
  </joint>
  <link name="leg_torso_mount_link"/>
  <joint name="leg_torso_mount_joint" type="fixed">
    <origin/>
    <parent link="leg_link4"/>
    <child link="leg_torso_mount_link"/>
    <axis/>
  </joint>
  <joint name="torso_joint" type="fixed">
    <origin/>
    <parent link="leg_torso_mount_link"/>
    <child link="torso_base_link"/>
  </joint>
  <!-- Head mount -->
  <link name="torso_head_mount_link"/>
  <joint name="torso_head_mount_joint" type="fixed">
    <origin xyz="-0.0081669 5E-05 0.51594"/>
    <parent link="torso_base_link"/>
    <child link="torso_head_mount_link"/>
  </joint>
  <link name="arm_base"/>
  <joint name="arm_base_joint" type="fixed">
    <origin rpy="1.5707963267948966 0 0" xyz="0 0 0.39599"/>
    <parent link="torso_base_link"/>
    <child link="arm_base"/>
  </joint>
  <joint name="head_joint" type="fixed">
    <origin/>
    <parent link="torso_head_mount_link"/>
    <child link="head_base_link"/>
  </joint>
  <link name="head_base_link">
    <inertial>
      <origin xyz="0.009452 -0.0097068 -0.16194"/>
      <mass value="1.5697"/>
      <inertia ixx="0.018397" ixy="-6.5897E-07" ixz="0.00030036" iyy="0.013058" iyz="0.00016843" izz="0.0082332"/>
    </inertial>
    <visual>
      <geometry>
        <mesh filename="package://galbot_one_description/meshes/head/head_base.glb"/>
      </geometry>
    </visual>
  </link>
  <link name="head_link1">
    <inertial>
      <origin xyz="0 0.020487 -0.038531"/>
      <mass value="0.067654"/>
      <inertia ixx="6.0514E-05" ixy="9.335E-21" ixz="-2.5793E-20" iyy="6.6478E-05" iyz="-1.3077E-05" izz="2.4032E-05"/>
    </inertial>
    <visual>
      <geometry>
        <mesh filename="package://galbot_one_description/meshes/head/head_link1.glb"/>
      </geometry>
    </visual>
  </link>
  <joint name="head_joint1" type="revolute">
    <origin xyz="0 0 0.068"/>
    <parent link="head_base_link"/>
    <child link="head_link1"/>
    <axis xyz="0 0 1"/>
    <limit effort="4" lower="-1.5707963267948966" upper="1.5707963267948966" velocity="8.38"/>
  </joint>
  <link name="head_link2">
    <inertial>
      <origin xyz="0.024473 -0.053558 0.0026343"/>
      <mass value="0.34019"/>
      <inertia ixx="0.0011508" ixy="-0.00026177" ixz="-4.0924E-07" iyy="0.00085046" iyz="1.4953E-08" izz="0.0010147"/>
    </inertial>
    <visual>
      <geometry>
        <mesh filename="package://galbot_one_description/meshes/head/head_link2.glb"/>
      </geometry>
    </visual>
  </link>
  <joint name="head_joint2" type="revolute">
    <origin rpy="-1.5707963267948966 0 0"/>
    <parent link="head_link1"/>
    <child link="head_link2"/>
    <axis xyz="0 0 1"/>
    <limit effort="4" lower="-0.3665191429188092" upper="0.3665191429188092" velocity="8.38"/>
  </joint>
  <link name="left_ear_camera">
    <visual>
      <geometry>
        <mesh filename="package://sensor_models/meshes/usb_camera/camera_01.glb"/>
      </geometry>
    </visual>
  </link>
  <joint name="left_ear_camera_joint" type="fixed">
    <origin rpy="0 0 3.141592653589793" xyz="0.026644 -0.055848 0.068728"/>
    <parent link="head_link2"/>
    <child link="left_ear_camera"/>
  </joint>
  <link name="right_ear_camera">
    <visual>
      <geometry>
        <mesh filename="package://sensor_models/meshes/usb_camera/camera_01.glb"/>
      </geometry>
    </visual>
  </link>
  <joint name="right_ear_camera_joint" type="fixed">
    <origin rpy="0 3.141592653589793 0" xyz="0.026644 -0.055848 -0.068728"/>
    <parent link="head_link2"/>
    <child link="right_ear_camera"/>
  </joint>
  <link name="head_front_camera">
    <visual>
      <geometry>
        <mesh filename="package://sensor_models/meshes/realsense/d435.glb"/>
      </geometry>
    </visual>
  </link>
  <joint name="head_front_camera_joint" type="fixed">
    <origin rpy="-0.5061454830783556 1.5707963267948966 0" xyz="0.096367 -0.059381 0"/>
    <parent link="head_link2"/>
    <child link="head_front_camera"/>
  </joint>
  <link name="head_back_camera">
    <visual>
      <geometry>
        <mesh filename="package://sensor_models/meshes/realsense/d415.glb"/>
      </geometry>
    </visual>
  </link>
  <joint name="head_back_camera_joint" type="fixed">
    <origin rpy="-0.23561944901923448 -1.5707963267948966 0" xyz="-0.026524 -0.073435 0"/>
    <parent link="head_link2"/>
    <child link="head_back_camera"/>
  </joint>
  <link name="left_base_link">
    <inertial>
      <origin xyz="0.00056868 -5.0139e-06 -0.030184"/>
      <mass value="1.1015"/>
      <inertia ixx="0.00056381" ixy="1.1123e-07" ixz="2.1236e-05" iyy="0.00057439" iyz="-1.685e-07" izz="0.00068513"/>
    </inertial>
    <visual>
      <geometry>
        <mesh filename="package://galbot_one_description/meshes/arm/base.glb" scale="1 1 1"/>
      </geometry>
    </visual>
    <collision>
      <geometry>
        <cylinder length="0.091350" radius="0.044983"/>
      </geometry>
    </collision>
  </link>
  <link name="left_link1">
    <!-- Reference direction=1 (left); visual: left was rpy Z PI (= scale -1 -1 1), right was scale 1 -1 1 → scale "${-direction} -1 1". -->
    <inertial>
      <origin xyz="-3.49009164621467e-05 -0.0108339687508697 -0.00355285779638756"/>
      <mass value="1.503"/>
      <inertia ixx="0.0014148" ixy="1.786E-06" ixz="8.6353e-07" iyy="0.001774" iyz="-5.8604e-06" izz="0.0011021"/>
    </inertial>
    <visual>
      <geometry>
        <mesh filename="package://galbot_one_description/meshes/arm/link1.glb"/>
      </geometry>
    </visual>
    <collision>
      <geometry>
        <cylinder length="0.068650" radius="0.044983"/>
      </geometry>
    </collision>
  </link>
  <joint name="left_joint1" type="revolute">
    <origin xyz="0 0 0.076"/>
    <parent link="left_base_link"/>
    <child link="left_link1"/>
    <axis xyz="0 0 1"/>
    <limit effort="60" lower="-3.141592653589793" upper="3.141592653589793" velocity="1.5"/>
  </joint>
  <link name="left_link2">
    <inertial>
      <origin xyz="0.0011542937189659 0.125918427333295 0.00403909337671848"/>
      <mass value="1.45678998733303"/>
      <inertia ixx="0.00269801896410487" ixy="4.63119567548212E-05" ixz="1.77748665814381e-05" iyy="0.00131692955308753" iyz="0.000382862812261171" izz="0.00264831680492027"/>
    </inertial>
    <visual>
      <geometry>
        <mesh filename="package://galbot_one_description/meshes/arm/link2.glb" scale="1 1 1"/>
      </geometry>
    </visual>
    <collision>
      <origin rpy="1.5707963267948966 0 0" xyz="0 -0.074 0"/>
      <geometry>
        <cylinder length="0.19825" radius="0.044983"/>
      </geometry>
    </collision>
  </link>
  <joint name="left_joint2" type="revolute">
    <origin rpy="-1.5707963267948966 0 3.141592653589793"/>
    <parent link="left_link1"/>
    <child link="left_link2"/>
    <axis xyz="0 0 1"/>
    <limit effort="60" lower="-1.5707963267948966" upper="1.83" velocity="1.5"/>
  </joint>
  <link name="left_link3">
    <inertial>
      <origin xyz="0.000352305768300032 -0.00726519320891149 -0.0216211172275835"/>
      <mass value="1.19882450635199"/>
      <inertia ixx="0.00220937810713451" ixy="-1.39043584660172E-05" ixz="1.48996603867525E-06" iyy="0.00236018741531392" iyz="4.46418780437893E-05" izz="0.000843927012398976"/>
    </inertial>
    <visual>
      <geometry>
        <mesh filename="package://galbot_one_description/meshes/arm/link3.glb"/>
      </geometry>
    </visual>
    <collision>
      <origin xyz="0 0 -0.074"/>
      <geometry>
        <cylinder length="0.223485" radius="0.044983"/>
      </geometry>
    </collision>
  </link>
  <joint name="left_joint3" type="revolute">
    <origin rpy="1.5707963267948966 1.5707963267948966 0" xyz="0 -0.35 0"/>
    <parent link="left_link2"/>
    <child link="left_link3"/>
    <axis xyz="0 0 1"/>
    <limit effort="30" lower="-3.141592653589793" upper="3.141592653589793" velocity="1.5"/>
  </joint>
  <link name="left_link4">
    <inertial>
      <origin xyz="1.6053E-07 -0.0841 0.0032663"/>
      <mass value="0.86736"/>
      <inertia ixx="0.00087789" ixy="1.0686E-08" ixz="-1.4208E-07" iyy="0.00058539" iyz="-0.0001428" izz="0.00082718"/>
    </inertial>
    <visual>
      <geometry>
        <mesh filename="package://galbot_one_description/meshes/arm/link4.glb"/>
      </geometry>
    </visual>
    <collision>
      <origin rpy="1.5707963267948966 0 0" xyz=" 0 -0.14  0"/>
      <geometry>
        <cylinder length="0.16085" radius="0.044983"/>
      </geometry>
    </collision>
  </link>
  <joint name="left_joint4" type="revolute">
    <origin rpy="-1.5707963267948966 0 3.141592653589793"/>
    <parent link="left_link3"/>
    <child link="left_link4"/>
    <axis xyz="0 0 1"/>
    <limit effort="30" lower="-2.1" upper="2.1" velocity="1.5"/>
  </joint>
  <link name="left_link5">
    <!-- Reference direction=1 (left); collision: left offset + r=0.034983, right origin + r=0.044983 → blend with (1±direction)/2. -->
    <inertial>
      <origin xyz="1.5971e-06 -0.025642 -0.117744"/>
      <mass value="1.3926"/>
      <inertia ixx="0.00316702853902255" ixy="8.3315E-08" ixz="1.4879e-07" iyy="0.00325737339135618" iyz="0.000396176140685722" izz="0.000888812918742085"/>
    </inertial>
    <visual>
      <geometry>
        <mesh filename="package://galbot_one_description/meshes/arm/link5.glb"/>
      </geometry>
    </visual>
    <collision>
      <origin xyz="0 -0.04 -0.08"/>
      <geometry>
        <box size="0.07 0.02 0.2"/>
      </geometry>
    </collision>
  </link>
  <joint name="left_joint5" type="revolute">
    <origin rpy="1.5707963267948966 3.141592653589793 0" xyz="0 -0.36 0"/>
    <parent link="left_link4"/>
    <child link="left_link5"/>
    <axis xyz="0 0 1"/>
    <limit effort="10" lower="-3.141592653589793" upper="3.141592653589793" velocity="1.5"/>
  </joint>
  <link name="left_link6">
    <inertial>
      <origin xyz="-2.88922358060439E-06 -0.000979379563628591 -1.95950029232006E-05"/>
      <mass value="0.574328152865271"/>
      <inertia ixx="0.000196239414479137" ixy="-4.42040670473688E-09" ixz="-2.96256099677375E-08" iyy="0.00023336393089217" iyz="-6.88062986985096E-08" izz="0.000196560460694031"/>
    </inertial>
    <visual>
      <geometry>
        <mesh filename="package://galbot_one_description/meshes/arm/link6.glb"/>
      </geometry>
    </visual>
  </link>
  <joint name="left_joint6" type="revolute">
    <origin rpy="-1.5707963267948966 0 3.141592653589793"/>
    <parent link="left_link5"/>
    <child link="left_link6"/>
    <axis xyz="0 0 1"/>
    <limit effort="10" lower="-1.5707963267948966" upper="1.5707963267948966" velocity="1.5"/>
  </joint>
  <link name="left_link7">
    <inertial>
      <origin xyz="0.000145324653036516 0.000669639293546548 0.0517788732710871"/>
      <mass value="0.271983892475789"/>
      <inertia ixx="9.12795880546355E-05" ixy="-3.70484062161125E-07" ixz="3.02036543797804E-07" iyy="9.01051818347072E-05" iyz="-2.27095800634144E-07" izz="0.00015076316927533"/>
    </inertial>
    <visual>
      <geometry>
        <mesh filename="package://galbot_one_description/meshes/arm/link7.glb"/>
      </geometry>
    </visual>
    <collision>
      <origin rpy="0 0 0" xyz="0 0 0.025"/>
      <geometry>
        <cylinder length="0.12" radius="0.031"/>
      </geometry>
    </collision>
  </link>
  <joint name="left_joint7" type="revolute">
    <origin rpy="1.5707963267948966 0.0 0.0"/>
    <parent link="left_link6"/>
    <child link="left_link7"/>
    <axis xyz="0 0 1"/>
    <limit effort="10" lower="-3.141592653589793" upper="3.141592653589793" velocity="1.5"/>
  </joint>
  <link name="left_end_effector_mount_link"/>
  <joint name="left_end_effector_mount_joint" type="fixed">
    <origin xyz="0 0 0.0845"/>
    <parent link="left_link7"/>
    <child link="left_end_effector_mount_link"/>
  </joint>
  <joint name="left_flange_joint" type="fixed">
    <origin rpy="0 0 3.141592653589793"/>
    <parent link="left_end_effector_mount_link"/>
    <child link="left_flange_base_link"/>
  </joint>
  <link name="left_flange_base_link">
    <inertial>
      <origin xyz="0.052829 -0.00096484 0.013285"/>
      <mass value="0.25733"/>
      <inertia ixx="0.0002175" ixy="-2.5433E-06" ixz="4.0586E-06" iyy="5.3894E-05" iyz="-1.8533E-06" izz="0.00025319"/>
    </inertial>
    <visual>
      <geometry>
        <mesh filename="package://galbot_one_description/meshes/flange/flange.glb"/>
      </geometry>
    </visual>
  </link>
  <link name="left_flange_mount_link"/>
  <joint name="left_flange_mount_joint" type="fixed">
    <origin xyz="0 0 0.006"/>
    <parent link="left_flange_base_link"/>
    <child link="left_flange_mount_link"/>
  </joint>
  <joint name="left_camera_flange_joint" type="fixed">
    <origin rpy="3.141592653589793 -1.308996939 0" xyz="0.0526 -0.02 0.02054"/>
    <parent link="left_flange_base_link"/>
    <child link="left_camera_flange_link"/>
  </joint>
  <link name="left_camera_flange_link">
    <inertial>
      <origin xyz="0.052829 -0.00096484 0.013285"/>
      <mass value="0.25733"/>
      <inertia ixx="0.0002175" ixy="-2.5433E-06" ixz="4.0586E-06" iyy="5.3894E-05" iyz="-1.8533E-06" izz="0.00025319"/>
    </inertial>
    <visual>
      <geometry>
        <mesh filename="package://galbot_one_description/meshes/flange/camera_support.glb"/>
      </geometry>
    </visual>
  </link>
  <link name="left_camera_link">
    <visual>
      <geometry>
        <mesh filename="package://sensor_models/meshes/realsense/d415.glb"/>
      </geometry>
    </visual>
  </link>
  <joint name="left_camera_joint" type="fixed">
    <origin rpy="-1.5707963267948966 0 -1.5707963267948966" xyz="0.0095 -0.02 0"/>
    <parent link="left_camera_flange_link"/>
    <child link="left_camera_link"/>
  </joint>
  <link name="right_base_link">
    <inertial>
      <origin xyz="-0.00056868 5.0139e-06 -0.030184"/>
      <mass value="1.1015"/>
      <inertia ixx="0.00056381" ixy="-1.1123e-07" ixz="-2.1236e-05" iyy="0.00057439" iyz="1.685e-07" izz="0.00068513"/>
    </inertial>
    <visual>
      <geometry>
        <mesh filename="package://galbot_one_description/meshes/arm/base.glb" scale="1 -1 1"/>
      </geometry>
    </visual>
    <collision>
      <geometry>
        <cylinder length="0.091350" radius="0.044983"/>
      </geometry>
    </collision>
  </link>
  <link name="right_link1">
    <!-- Reference direction=1 (left); visual: left was rpy Z PI (= scale -1 -1 1), right was scale 1 -1 1 → scale "${-direction} -1 1". -->
    <inertial>
      <origin xyz="3.49009164621467e-05 0.0108339687508697 -0.00355285779638756"/>
      <mass value="1.503"/>
      <inertia ixx="0.0014148" ixy="1.786E-06" ixz="-8.6353e-07" iyy="0.001774" iyz="5.8604e-06" izz="0.0011021"/>
    </inertial>
    <visual>
      <geometry>
        <mesh filename="package://galbot_one_description/meshes/arm/link1.glb"/>
      </geometry>
    </visual>
    <collision>
      <geometry>
        <cylinder length="0.068650" radius="0.044983"/>
      </geometry>
    </collision>
  </link>
  <joint name="right_joint1" type="revolute">
    <origin xyz="0 0 0.076"/>
    <parent link="right_base_link"/>
    <child link="right_link1"/>
    <axis xyz="0 0 1"/>
    <limit effort="60" lower="-3.141592653589793" upper="3.141592653589793" velocity="1.5"/>
  </joint>
  <link name="right_link2">
    <inertial>
      <origin xyz="-0.0011542937189659 -0.125918427333295 0.00403909337671848"/>
      <mass value="1.45678998733303"/>
      <inertia ixx="0.00269801896410487" ixy="4.63119567548212E-05" ixz="-1.77748665814381e-05" iyy="0.00131692955308753" iyz="-0.000382862812261171" izz="0.00264831680492027"/>
    </inertial>
    <visual>
      <geometry>
        <mesh filename="package://galbot_one_description/meshes/arm/link2.glb" scale="-1 1 1"/>
      </geometry>
    </visual>
    <collision>
      <origin rpy="1.5707963267948966 0 0" xyz="0 -0.074 0"/>
      <geometry>
        <cylinder length="0.19825" radius="0.044983"/>
      </geometry>
    </collision>
  </link>
  <joint name="right_joint2" type="revolute">
    <origin rpy="-1.5707963267948966 0 3.141592653589793"/>
    <parent link="right_link1"/>
    <child link="right_link2"/>
    <axis xyz="0 0 -1"/>
    <limit effort="60" lower="-1.5707963267948966" upper="1.83" velocity="1.5"/>
  </joint>
  <link name="right_link3">
    <inertial>
      <origin xyz="0.000352305768300032 -0.00726519320891149 -0.0216211172275835"/>
      <mass value="1.19882450635199"/>
      <inertia ixx="0.00220937810713451" ixy="-1.39043584660172E-05" ixz="1.48996603867525E-06" iyy="0.00236018741531392" iyz="4.46418780437893E-05" izz="0.000843927012398976"/>
    </inertial>
    <visual>
      <geometry>
        <mesh filename="package://galbot_one_description/meshes/arm/link3.glb"/>
      </geometry>
    </visual>
    <collision>
      <origin xyz="0 0 -0.074"/>
      <geometry>
        <cylinder length="0.223485" radius="0.044983"/>
      </geometry>
    </collision>
  </link>
  <joint name="right_joint3" type="revolute">
    <origin rpy="1.5707963267948966 -1.5707963267948966 0" xyz="0 -0.35 0"/>
    <parent link="right_link2"/>
    <child link="right_link3"/>
    <axis xyz="0 0 1"/>
    <limit effort="30" lower="-3.141592653589793" upper="3.141592653589793" velocity="1.5"/>
  </joint>
  <link name="right_link4">
    <inertial>
      <origin xyz="1.6053E-07 -0.0841 0.0032663"/>
      <mass value="0.86736"/>
      <inertia ixx="0.00087789" ixy="1.0686E-08" ixz="-1.4208E-07" iyy="0.00058539" iyz="-0.0001428" izz="0.00082718"/>
    </inertial>
    <visual>
      <geometry>
        <mesh filename="package://galbot_one_description/meshes/arm/link4.glb"/>
      </geometry>
    </visual>
    <collision>
      <origin rpy="1.5707963267948966 0 0" xyz=" 0 -0.14  0"/>
      <geometry>
        <cylinder length="0.16085" radius="0.044983"/>
      </geometry>
    </collision>
  </link>
  <joint name="right_joint4" type="revolute">
    <origin rpy="-1.5707963267948966 0 3.141592653589793"/>
    <parent link="right_link3"/>
    <child link="right_link4"/>
    <axis xyz="0 0 1"/>
    <limit effort="30" lower="-2.1" upper="2.1" velocity="1.5"/>
  </joint>
  <link name="right_link5">
    <!-- Reference direction=1 (left); collision: left offset + r=0.034983, right origin + r=0.044983 → blend with (1±direction)/2. -->
    <inertial>
      <origin xyz="-1.5971e-06 0.025642 -0.117744"/>
      <mass value="1.3926"/>
      <inertia ixx="0.00316702853902255" ixy="8.3315E-08" ixz="-1.4879e-07" iyy="0.00325737339135618" iyz="-0.000396176140685722" izz="0.000888812918742085"/>
    </inertial>
    <visual>
      <geometry>
        <mesh filename="package://galbot_one_description/meshes/arm/link5.glb"/>
      </geometry>
    </visual>
    <collision>
      <origin xyz="0 -0.04 -0.08"/>
      <geometry>
        <box size="0.07 0.02 0.2"/>
      </geometry>
    </collision>
  </link>
  <joint name="right_joint5" type="revolute">
    <origin rpy="1.5707963267948966 3.141592653589793 0" xyz="0 -0.36 0"/>
    <parent link="right_link4"/>
    <child link="right_link5"/>
    <axis xyz="0 0 1"/>
    <limit effort="10" lower="-3.141592653589793" upper="3.141592653589793" velocity="1.5"/>
  </joint>
  <link name="right_link6">
    <inertial>
      <origin xyz="-2.88922358060439E-06 -0.000979379563628591 -1.95950029232006E-05"/>
      <mass value="0.574328152865271"/>
      <inertia ixx="0.000196239414479137" ixy="-4.42040670473688E-09" ixz="-2.96256099677375E-08" iyy="0.00023336393089217" iyz="-6.88062986985096E-08" izz="0.000196560460694031"/>
    </inertial>
    <visual>
      <geometry>
        <mesh filename="package://galbot_one_description/meshes/arm/link6.glb"/>
      </geometry>
    </visual>
  </link>
  <joint name="right_joint6" type="revolute">
    <origin rpy="-1.5707963267948966 0 3.141592653589793"/>
    <parent link="right_link5"/>
    <child link="right_link6"/>
    <axis xyz="0 0 1"/>
    <limit effort="10" lower="-1.5707963267948966" upper="1.5707963267948966" velocity="1.5"/>
  </joint>
  <link name="right_link7">
    <inertial>
      <origin xyz="0.000145324653036516 0.000669639293546548 0.0517788732710871"/>
      <mass value="0.271983892475789"/>
      <inertia ixx="9.12795880546355E-05" ixy="-3.70484062161125E-07" ixz="3.02036543797804E-07" iyy="9.01051818347072E-05" iyz="-2.27095800634144E-07" izz="0.00015076316927533"/>
    </inertial>
    <visual>
      <geometry>
        <mesh filename="package://galbot_one_description/meshes/arm/link7.glb"/>
      </geometry>
    </visual>
    <collision>
      <origin rpy="0 0 0" xyz="0 0 0.025"/>
      <geometry>
        <cylinder length="0.12" radius="0.031"/>
      </geometry>
    </collision>
  </link>
  <joint name="right_joint7" type="revolute">
    <origin rpy="-1.5707963267948966 3.141592653589793 3.141592653589793"/>
    <parent link="right_link6"/>
    <child link="right_link7"/>
    <axis xyz="0 0 1"/>
    <limit effort="10" lower="-3.141592653589793" upper="3.141592653589793" velocity="1.5"/>
  </joint>
  <link name="right_end_effector_mount_link"/>
  <joint name="right_end_effector_mount_joint" type="fixed">
    <origin xyz="0 0 0.0845"/>
    <parent link="right_link7"/>
    <child link="right_end_effector_mount_link"/>
  </joint>
  <joint name="right_flange_joint" type="fixed">
    <origin rpy="0 0 0.0"/>
    <parent link="right_end_effector_mount_link"/>
    <child link="right_flange_base_link"/>
  </joint>
  <link name="right_flange_base_link">
    <inertial>
      <origin xyz="0.052829 -0.00096484 0.013285"/>
      <mass value="0.25733"/>
      <inertia ixx="0.0002175" ixy="-2.5433E-06" ixz="4.0586E-06" iyy="5.3894E-05" iyz="-1.8533E-06" izz="0.00025319"/>
    </inertial>
    <visual>
      <geometry>
        <mesh filename="package://galbot_one_description/meshes/flange/flange.glb"/>
      </geometry>
    </visual>
  </link>
  <link name="right_flange_mount_link"/>
  <joint name="right_flange_mount_joint" type="fixed">
    <origin xyz="0 0 0.006"/>
    <parent link="right_flange_base_link"/>
    <child link="right_flange_mount_link"/>
  </joint>
  <joint name="right_camera_flange_joint" type="fixed">
    <origin rpy="3.141592653589793 -1.308996939 0" xyz="0.0526 -0.02 0.02054"/>
    <parent link="right_flange_base_link"/>
    <child link="right_camera_flange_link"/>
  </joint>
  <link name="right_camera_flange_link">
    <inertial>
      <origin xyz="0.052829 -0.00096484 0.013285"/>
      <mass value="0.25733"/>
      <inertia ixx="0.0002175" ixy="-2.5433E-06" ixz="4.0586E-06" iyy="5.3894E-05" iyz="-1.8533E-06" izz="0.00025319"/>
    </inertial>
    <visual>
      <geometry>
        <mesh filename="package://galbot_one_description/meshes/flange/camera_support.glb"/>
      </geometry>
    </visual>
  </link>
  <link name="right_camera_link">
    <visual>
      <geometry>
        <mesh filename="package://sensor_models/meshes/realsense/d415.glb"/>
      </geometry>
    </visual>
  </link>
  <joint name="right_camera_joint" type="fixed">
    <origin rpy="-1.5707963267948966 0 -1.5707963267948966" xyz="0.0095 -0.02 0"/>
    <parent link="right_camera_flange_link"/>
    <child link="right_camera_link"/>
  </joint>
  <!-- Robot Base Link -->
  <link name="base_link"/>
  <joint name="omni_chassis_joint" type="fixed">
    <parent link="base_link"/>
    <child link="omni_chassis_base_link"/>
  </joint>
  <link name="omni_chassis_base_link">
    <inertial>
      <origin xyz="0.00094269 0.00017452 0.09326"/>
      <mass value="8.7914"/>
      <inertia ixx="0.11584" ixy="-0.00011125" ixz="0.00045932" iyy="0.08221" iyz="2.8393E-06" izz="0.14295"/>
    </inertial>
    <visual>
      <geometry>
        <mesh filename="package://galbot_one_description/meshes/chassis/chassis.glb"/>
      </geometry>
    </visual>
    <collision>
      <origin xyz="0 0 0.11"/>
      <geometry>
        <cylinder length="0.2" radius="0.3"/>
      </geometry>
    </collision>
  </link>
  <link name="omni_chassis_leg_mount_link"/>
  <joint name="omni_chassis_leg_mount_joint" type="fixed">
    <origin rpy="0 0 0" xyz="0.134 -0.087 0.13"/>
    <parent link="omni_chassis_base_link"/>
    <child link="omni_chassis_leg_mount_link"/>
  </joint>
  <!-- 轮子链接 -->
  <link name="wheel_1">
    <inertial>
      <origin xyz="0.0026089441594678298 -1.3189703553351252e-07 2.8695680726054107e-07"/>
      <mass value="4.24803000494366"/>
      <inertia ixx="0.012235" ixy="-0.0" ixz="0.0" iyy="0.006629" iyz="0.0" izz="0.006629"/>
    </inertial>
    <visual>
      <geometry>
        <mesh filename="package://component_models/meshes/omniwheel_10.glb"/>
      </geometry>
    </visual>
  </link>
  <!-- 轮子链接 -->
  <link name="wheel_2">
    <inertial>
      <origin xyz="0.0026089441594678298 -1.3189703553351252e-07 2.8695680726054107e-07"/>
      <mass value="4.24803000494366"/>
      <inertia ixx="0.012235" ixy="-0.0" ixz="0.0" iyy="0.006629" iyz="0.0" izz="0.006629"/>
    </inertial>
    <visual>
      <geometry>
        <mesh filename="package://component_models/meshes/omniwheel_10.glb"/>
      </geometry>
    </visual>
  </link>
  <!-- 轮子链接 -->
  <link name="wheel_3">
    <inertial>
      <origin xyz="0.0026089441594678298 -1.3189703553351252e-07 2.8695680726054107e-07"/>
      <mass value="4.24803000494366"/>
      <inertia ixx="0.012235" ixy="-0.0" ixz="0.0" iyy="0.006629" iyz="0.0" izz="0.006629"/>
    </inertial>
    <visual>
      <geometry>
        <mesh filename="package://component_models/meshes/omniwheel_10.glb"/>
      </geometry>
    </visual>
  </link>
  <!-- 轮子链接 -->
  <link name="wheel_4">
    <inertial>
      <origin xyz="0.0026089441594678298 -1.3189703553351252e-07 2.8695680726054107e-07"/>
      <mass value="4.24803000494366"/>
      <inertia ixx="0.012235" ixy="-0.0" ixz="0.0" iyy="0.006629" iyz="0.0" izz="0.006629"/>
    </inertial>
    <visual>
      <geometry>
        <mesh filename="package://component_models/meshes/omniwheel_10.glb"/>
      </geometry>
    </visual>
  </link>
  <joint name="wheel1_joint" type="fixed">
    <origin rpy="0 0 -2.356194490192345" xyz="0.176493 0.176493 0.071834"/>
    <parent link="omni_chassis_base_link"/>
    <child link="wheel_1"/>
  </joint>
  <joint name="wheel2_joint" type="fixed">
    <origin rpy="0 0 -0.7853981633974483" xyz="-0.176493 0.176493 0.071834"/>
    <parent link="omni_chassis_base_link"/>
    <child link="wheel_2"/>
  </joint>
  <joint name="wheel3_joint" type="fixed">
    <origin rpy="0 0 0.7853981633974483" xyz="-0.176493 -0.176493 0.071834"/>
    <parent link="omni_chassis_base_link"/>
    <child link="wheel_3"/>
  </joint>
  <joint name="wheel4_joint" type="fixed">
    <origin rpy="0 0 2.356194490192345" xyz="0.176493 -0.176493 0.071834"/>
    <parent link="omni_chassis_base_link"/>
    <child link="wheel_4"/>
  </joint>
  <link name="chassis_lidar">
    <visual>
      <geometry>
        <mesh filename="package://sensor_models/meshes/mid360/mid360.obj"/>
      </geometry>
    </visual>
  </link>
  <joint name="chassis_lidar_joint" type="fixed">
    <parent link="omni_chassis_base_link"/>
    <child link="chassis_lidar"/>
    <origin xyz="0.222 0 0.22772"/>
  </joint>
  <joint name="left_arm_mount_joint" type="fixed">
    <origin rpy="0 3.141592653589793 0" xyz="0 0 -0.13"/>
    <parent link="arm_base"/>
    <child link="left_base_link"/>
  </joint>
  <joint name="right_arm_mount_joint" type="fixed">
    <origin xyz="0 0 0.13"/>
    <parent link="arm_base"/>
    <child link="right_base_link"/>
  </joint>
  <link name="right_gripper_base"/>
  <joint name="right_gripper_base_joint" type="fixed">
    <origin rpy="1.5707963267948966  1.5707963267948966  0"/>
    <parent link="right_gripper_base"/>
    <child link="right_gripper_base_link"/>
  </joint>
  <link name="right_gripper_base_link">
    <inertial>
      <origin xyz="0.0875969515032359 -0.000593766922509439 -0.000273353044587243"/>
      <mass value="0.229646651659589"/>
      <inertia ixx="8.60029243295527E-05" ixy="2.00063024143341E-06" ixz="2.85398505671959E-06" iyy="7.73254340691918E-05" iyz="-1.0856442426917E-07" izz="9.78281466602487E-05"/>
    </inertial>
    <visual>
      <geometry>
        <mesh filename="package://galbot_one_description/meshes/gripper_hitbot/base.glb"/>
      </geometry>
    </visual>
    <collision>
      <origin xyz="-0.1 0 0"/>
      <geometry>
        <box size="0.18000 0.047000 0.067000"/>
      </geometry>
    </collision>
  </link>
  <link name="right_gripper_l1_link">
    <inertial>
      <mass value="0.01"/>
      <inertia ixx="1e-5" ixy="0" ixz="0" iyy="1e-5" iyz="0" izz="1e-5"/>
    </inertial>
    <visual>
      <geometry>
        <mesh filename="package://galbot_one_description/meshes/gripper_hitbot/link1.glb"/>
      </geometry>
    </visual>
  </link>
  <!-- Main driven finger joint (Astribot-style: *_gripper_joint) -->
  <joint name="right_gripper_joint" type="revolute">
    <origin xyz="-0.121835 0 0.02"/>
    <parent link="right_gripper_base_link"/>
    <child link="right_gripper_l1_link"/>
    <axis xyz="0 1 0"/>
    <limit effort="2" lower="0" upper="1" velocity="3"/>
  </joint>
  <link name="right_gripper_l2_link">
    <inertial>
      <mass value="0.01"/>
      <inertia ixx="1e-5" ixy="0" ixz="0" iyy="1e-5" iyz="0" izz="1e-5"/>
    </inertial>
    <visual>
      <geometry>
        <mesh filename="package://galbot_one_description/meshes/gripper_hitbot/link2.glb"/>
      </geometry>
    </visual>
  </link>
  <joint name="right_gripper_l2_joint" type="revolute">
    <origin xyz="-0.1368 0 0.01"/>
    <parent link="right_gripper_base_link"/>
    <child link="right_gripper_l2_link"/>
    <axis xyz="0 1 0"/>
    <limit effort="2" lower="0" upper="1" velocity="3"/>
    <mimic joint="right_gripper_joint" multiplier="1.0"/>
  </joint>
  <link name="right_gripper_l3_link">
    <inertial>
      <mass value="0.01"/>
      <inertia ixx="1e-5" ixy="0" ixz="0" iyy="1e-5" iyz="0" izz="1e-5"/>
    </inertial>
    <visual>
      <geometry>
        <mesh filename="package://galbot_one_description/meshes/gripper_hitbot/link3.glb"/>
      </geometry>
    </visual>
  </link>
  <joint name="right_gripper_l3_joint" type="revolute">
    <origin xyz="-0.064985 0 0.00125"/>
    <parent link="right_gripper_l1_link"/>
    <child link="right_gripper_l3_link"/>
    <axis xyz="0 -1 0"/>
    <limit effort="2" lower="0" upper="1" velocity="3"/>
    <mimic joint="right_gripper_joint" multiplier="1.0"/>
  </joint>
  <link name="right_gripper_l4_link">
    <inertial>
      <mass value="0.01"/>
      <inertia ixx="1e-5" ixy="0" ixz="0" iyy="1e-5" iyz="0" izz="1e-5"/>
    </inertial>
    <visual>
      <geometry>
        <mesh filename="package://galbot_one_description/meshes/gripper_hitbot/link4.glb"/>
      </geometry>
    </visual>
  </link>
  <joint name="right_gripper_l4_joint" type="fixed">
    <parent link="right_gripper_l3_link"/>
    <child link="right_gripper_l4_link"/>
  </joint>
  <link name="right_gripper_l5_link">
    <inertial>
      <mass value="0.01"/>
      <inertia ixx="1e-5" ixy="0" ixz="0" iyy="1e-5" iyz="0" izz="1e-5"/>
    </inertial>
    <visual>
      <geometry>
        <mesh filename="package://galbot_one_description/meshes/gripper_hitbot/link5.glb"/>
      </geometry>
    </visual>
  </link>
  <joint name="right_gripper_l5_joint" type="fixed">
    <parent link="right_gripper_l3_link"/>
    <child link="right_gripper_l5_link"/>
  </joint>
  <link name="right_gripper_r1_link">
    <inertial>
      <mass value="0.01"/>
      <inertia ixx="1e-5" ixy="0" ixz="0" iyy="1e-5" iyz="0" izz="1e-5"/>
    </inertial>
    <visual>
      <geometry>
        <mesh filename="package://galbot_one_description/meshes/gripper_hitbot/link1.glb" scale="1 1 -1"/>
      </geometry>
    </visual>
  </link>
  <joint name="right_gripper_r1_joint" type="revolute">
    <origin xyz="-0.121835 0 -0.02"/>
    <parent link="right_gripper_base_link"/>
    <child link="right_gripper_r1_link"/>
    <axis xyz="0 -1 0"/>
    <limit effort="2" lower="0" upper="1" velocity="3"/>
    <mimic joint="right_gripper_joint" multiplier="1.0"/>
  </joint>
  <link name="right_gripper_r2_link">
    <inertial>
      <mass value="0.01"/>
      <inertia ixx="1e-5" ixy="0" ixz="0" iyy="1e-5" iyz="0" izz="1e-5"/>
    </inertial>
    <visual>
      <geometry>
        <mesh filename="package://galbot_one_description/meshes/gripper_hitbot/link2.glb" scale="1 1 -1"/>
      </geometry>
    </visual>
  </link>
  <joint name="right_gripper_r2_joint" type="revolute">
    <origin xyz="-0.1368 0 -0.01"/>
    <parent link="right_gripper_base_link"/>
    <child link="right_gripper_r2_link"/>
    <axis xyz="0 -1 0"/>
    <limit effort="2" lower="0" upper="1" velocity="3"/>
    <mimic joint="right_gripper_joint" multiplier="1.0"/>
  </joint>
  <link name="right_gripper_r3_link">
    <inertial>
      <mass value="0.01"/>
      <inertia ixx="1e-5" ixy="0" ixz="0" iyy="1e-5" iyz="0" izz="1e-5"/>
    </inertial>
    <visual>
      <geometry>
        <mesh filename="package://galbot_one_description/meshes/gripper_hitbot/link3.glb" scale="1 1 -1"/>
      </geometry>
    </visual>
  </link>
  <joint name="right_gripper_r3_joint" type="revolute">
    <origin xyz="-0.064985 0 -0.00125"/>
    <parent link="right_gripper_r1_link"/>
    <child link="right_gripper_r3_link"/>
    <axis xyz="0 1 0"/>
    <limit effort="2" lower="0" upper="1" velocity="3"/>
    <mimic joint="right_gripper_joint" multiplier="1.0"/>
  </joint>
  <link name="right_gripper_r4_link">
    <inertial>
      <mass value="0.01"/>
      <inertia ixx="1e-5" ixy="0" ixz="0" iyy="1e-5" iyz="0" izz="1e-5"/>
    </inertial>
    <visual>
      <geometry>
        <mesh filename="package://galbot_one_description/meshes/gripper_hitbot/link4.glb" scale="1 1 -1"/>
      </geometry>
    </visual>
  </link>
  <joint name="right_gripper_r4_joint" type="fixed">
    <parent link="right_gripper_r3_link"/>
    <child link="right_gripper_r4_link"/>
  </joint>
  <link name="right_gripper_r5_link">
    <inertial>
      <mass value="0.01"/>
      <inertia ixx="1e-5" ixy="0" ixz="0" iyy="1e-5" iyz="0" izz="1e-5"/>
    </inertial>
    <visual>
      <geometry>
        <mesh filename="package://galbot_one_description/meshes/gripper_hitbot/link5.glb" scale="1 1 -1"/>
      </geometry>
    </visual>
  </link>
  <joint name="right_gripper_r5_joint" type="fixed">
    <parent link="right_gripper_r3_link"/>
    <child link="right_gripper_r5_link"/>
  </joint>
  <link name="right_gripper_tcp_link"/>
  <joint name="right_tcp_joint" type="fixed">
    <origin xyz="0 0 0.21579"/>
    <parent link="right_gripper_base"/>
    <child link="right_gripper_tcp_link"/>
  </joint>
  <link name="left_gripper_base"/>
  <joint name="left_gripper_base_joint" type="fixed">
    <origin rpy="1.5707963267948966  1.5707963267948966  0"/>
    <parent link="left_gripper_base"/>
    <child link="left_gripper_base_link"/>
  </joint>
  <link name="left_gripper_base_link">
    <inertial>
      <origin xyz="0.0875969515032359 -0.000593766922509439 -0.000273353044587243"/>
      <mass value="0.229646651659589"/>
      <inertia ixx="8.60029243295527E-05" ixy="2.00063024143341E-06" ixz="2.85398505671959E-06" iyy="7.73254340691918E-05" iyz="-1.0856442426917E-07" izz="9.78281466602487E-05"/>
    </inertial>
    <visual>
      <geometry>
        <mesh filename="package://galbot_one_description/meshes/gripper_hitbot/base.glb"/>
      </geometry>
    </visual>
    <collision>
      <origin xyz="-0.1 0 0"/>
      <geometry>
        <box size="0.18000 0.047000 0.067000"/>
      </geometry>
    </collision>
  </link>
  <link name="left_gripper_l1_link">
    <inertial>
      <mass value="0.01"/>
      <inertia ixx="1e-5" ixy="0" ixz="0" iyy="1e-5" iyz="0" izz="1e-5"/>
    </inertial>
    <visual>
      <geometry>
        <mesh filename="package://galbot_one_description/meshes/gripper_hitbot/link1.glb"/>
      </geometry>
    </visual>
  </link>
  <!-- Main driven finger joint (Astribot-style: *_gripper_joint) -->
  <joint name="left_gripper_joint" type="revolute">
    <origin xyz="-0.121835 0 0.02"/>
    <parent link="left_gripper_base_link"/>
    <child link="left_gripper_l1_link"/>
    <axis xyz="0 1 0"/>
    <limit effort="2" lower="0" upper="1" velocity="3"/>
  </joint>
  <link name="left_gripper_l2_link">
    <inertial>
      <mass value="0.01"/>
      <inertia ixx="1e-5" ixy="0" ixz="0" iyy="1e-5" iyz="0" izz="1e-5"/>
    </inertial>
    <visual>
      <geometry>
        <mesh filename="package://galbot_one_description/meshes/gripper_hitbot/link2.glb"/>
      </geometry>
    </visual>
  </link>
  <joint name="left_gripper_l2_joint" type="revolute">
    <origin xyz="-0.1368 0 0.01"/>
    <parent link="left_gripper_base_link"/>
    <child link="left_gripper_l2_link"/>
    <axis xyz="0 1 0"/>
    <limit effort="2" lower="0" upper="1" velocity="3"/>
    <mimic joint="left_gripper_joint" multiplier="1.0"/>
  </joint>
  <link name="left_gripper_l3_link">
    <inertial>
      <mass value="0.01"/>
      <inertia ixx="1e-5" ixy="0" ixz="0" iyy="1e-5" iyz="0" izz="1e-5"/>
    </inertial>
    <visual>
      <geometry>
        <mesh filename="package://galbot_one_description/meshes/gripper_hitbot/link3.glb"/>
      </geometry>
    </visual>
  </link>
  <joint name="left_gripper_l3_joint" type="revolute">
    <origin xyz="-0.064985 0 0.00125"/>
    <parent link="left_gripper_l1_link"/>
    <child link="left_gripper_l3_link"/>
    <axis xyz="0 -1 0"/>
    <limit effort="2" lower="0" upper="1" velocity="3"/>
    <mimic joint="left_gripper_joint" multiplier="1.0"/>
  </joint>
  <link name="left_gripper_l4_link">
    <inertial>
      <mass value="0.01"/>
      <inertia ixx="1e-5" ixy="0" ixz="0" iyy="1e-5" iyz="0" izz="1e-5"/>
    </inertial>
    <visual>
      <geometry>
        <mesh filename="package://galbot_one_description/meshes/gripper_hitbot/link4.glb"/>
      </geometry>
    </visual>
  </link>
  <joint name="left_gripper_l4_joint" type="fixed">
    <parent link="left_gripper_l3_link"/>
    <child link="left_gripper_l4_link"/>
  </joint>
  <link name="left_gripper_l5_link">
    <inertial>
      <mass value="0.01"/>
      <inertia ixx="1e-5" ixy="0" ixz="0" iyy="1e-5" iyz="0" izz="1e-5"/>
    </inertial>
    <visual>
      <geometry>
        <mesh filename="package://galbot_one_description/meshes/gripper_hitbot/link5.glb"/>
      </geometry>
    </visual>
  </link>
  <joint name="left_gripper_l5_joint" type="fixed">
    <parent link="left_gripper_l3_link"/>
    <child link="left_gripper_l5_link"/>
  </joint>
  <link name="left_gripper_r1_link">
    <inertial>
      <mass value="0.01"/>
      <inertia ixx="1e-5" ixy="0" ixz="0" iyy="1e-5" iyz="0" izz="1e-5"/>
    </inertial>
    <visual>
      <geometry>
        <mesh filename="package://galbot_one_description/meshes/gripper_hitbot/link1.glb" scale="1 1 -1"/>
      </geometry>
    </visual>
  </link>
  <joint name="left_gripper_r1_joint" type="revolute">
    <origin xyz="-0.121835 0 -0.02"/>
    <parent link="left_gripper_base_link"/>
    <child link="left_gripper_r1_link"/>
    <axis xyz="0 -1 0"/>
    <limit effort="2" lower="0" upper="1" velocity="3"/>
    <mimic joint="left_gripper_joint" multiplier="1.0"/>
  </joint>
  <link name="left_gripper_r2_link">
    <inertial>
      <mass value="0.01"/>
      <inertia ixx="1e-5" ixy="0" ixz="0" iyy="1e-5" iyz="0" izz="1e-5"/>
    </inertial>
    <visual>
      <geometry>
        <mesh filename="package://galbot_one_description/meshes/gripper_hitbot/link2.glb" scale="1 1 -1"/>
      </geometry>
    </visual>
  </link>
  <joint name="left_gripper_r2_joint" type="revolute">
    <origin xyz="-0.1368 0 -0.01"/>
    <parent link="left_gripper_base_link"/>
    <child link="left_gripper_r2_link"/>
    <axis xyz="0 -1 0"/>
    <limit effort="2" lower="0" upper="1" velocity="3"/>
    <mimic joint="left_gripper_joint" multiplier="1.0"/>
  </joint>
  <link name="left_gripper_r3_link">
    <inertial>
      <mass value="0.01"/>
      <inertia ixx="1e-5" ixy="0" ixz="0" iyy="1e-5" iyz="0" izz="1e-5"/>
    </inertial>
    <visual>
      <geometry>
        <mesh filename="package://galbot_one_description/meshes/gripper_hitbot/link3.glb" scale="1 1 -1"/>
      </geometry>
    </visual>
  </link>
  <joint name="left_gripper_r3_joint" type="revolute">
    <origin xyz="-0.064985 0 -0.00125"/>
    <parent link="left_gripper_r1_link"/>
    <child link="left_gripper_r3_link"/>
    <axis xyz="0 1 0"/>
    <limit effort="2" lower="0" upper="1" velocity="3"/>
    <mimic joint="left_gripper_joint" multiplier="1.0"/>
  </joint>
  <link name="left_gripper_r4_link">
    <inertial>
      <mass value="0.01"/>
      <inertia ixx="1e-5" ixy="0" ixz="0" iyy="1e-5" iyz="0" izz="1e-5"/>
    </inertial>
    <visual>
      <geometry>
        <mesh filename="package://galbot_one_description/meshes/gripper_hitbot/link4.glb" scale="1 1 -1"/>
      </geometry>
    </visual>
  </link>
  <joint name="left_gripper_r4_joint" type="fixed">
    <parent link="left_gripper_r3_link"/>
    <child link="left_gripper_r4_link"/>
  </joint>
  <link name="left_gripper_r5_link">
    <inertial>
      <mass value="0.01"/>
      <inertia ixx="1e-5" ixy="0" ixz="0" iyy="1e-5" iyz="0" izz="1e-5"/>
    </inertial>
    <visual>
      <geometry>
        <mesh filename="package://galbot_one_description/meshes/gripper_hitbot/link5.glb" scale="1 1 -1"/>
      </geometry>
    </visual>
  </link>
  <joint name="left_gripper_r5_joint" type="fixed">
    <parent link="left_gripper_r3_link"/>
    <child link="left_gripper_r5_link"/>
  </joint>
  <link name="left_gripper_tcp_link"/>
  <joint name="left_tcp_joint" type="fixed">
    <origin xyz="0 0 0.21579"/>
    <parent link="left_gripper_base"/>
    <child link="left_gripper_tcp_link"/>
  </joint>
  <!-- Mount gripper on flange (fixed) -->
  <joint name="left_gripper_mount_joint" type="fixed">
    <parent link="left_flange_mount_link"/>
    <child link="left_gripper_base"/>
  </joint>
  <!-- Mount gripper on flange (fixed) -->
  <joint name="right_gripper_mount_joint" type="fixed">
    <parent link="right_flange_mount_link"/>
    <child link="right_gripper_base"/>
  </joint>
</robot>
