<?xml version="1.0" ?>
<!-- =================================================================================== -->
<!-- |    This document was autogenerated by xacro from robot.xacro                    | -->
<!-- |    EDITING THIS FILE BY HAND IS NOT RECOMMENDED                                 | -->
<!-- =================================================================================== -->
<robot name="rm65">
  <!-- Decoupled root link for external base mounting -->
  <link name="arm_root"/>
  <link name="base_link">
    <inertial>
      <origin xyz="0.000433268851866144 3.54527840972405E-05 0.0599427623574736"/>
      <mass value="0.841071174772543"/>
      <inertia ixx="0.00172611149818605" ixy="2.52724703312125E-06" ixz="3.67689528877993E-05" iyy="0.00170987425756066" iyz="-1.68009023667311E-06" izz="0.000904023916742301"/>
    </inertial>
    <visual>
      <geometry>
        <mesh filename="package://rm75_description/meshes/base_link.glb"/>
      </geometry>
    </visual>
    <collision>
      <geometry>
        <mesh filename="package://rm75_description/meshes/base_link.glb"/>
      </geometry>
    </collision>
  </link>
  <joint name="base_link_fixed" type="fixed">
    <origin rpy="-1.5708 0 0" xyz="0 0 0.2405"/>
    <parent link="base_link"/>
    <child link="arm_root"/>
  </joint>
  <link name="link1">
    <inertial>
      <origin xyz="0.0251854224372461 1.19160585601655E-08 -0.021107996993288"/>
      <mass value="0.593563458735581"/>
      <inertia ixx="0.000561352422092522" ixy="9.8019294192418E-09" ixz="-0.000211217278563478" iyy="0.00126614121202124" iyz="1.29510293158304E-08" izz="0.0011816817861243"/>
    </inertial>
    <visual>
      <geometry>
        <mesh filename="package://rm75_description/meshes/arm/link1.glb"/>
      </geometry>
    </visual>
    <collision>
      <geometry>
        <mesh filename="package://rm75_description/meshes/arm/link1.glb"/>
      </geometry>
    </collision>
  </link>
  <link name="link2">
    <inertial>
      <origin xyz="2.72859133252335E-07 0.011077753037361 0.0761295106490881"/>
      <mass value="0.432849770310974"/>
      <inertia ixx="0.00125838173873093" ixy="5.63146579602116E-09" ixz="1.33486683063366E-09" iyy="0.00122245448121472" iyz="0.000279003475762058" izz="0.000317474184276672"/>
    </inertial>
    <visual>
      <geometry>
        <mesh filename="package://rm75_description/meshes/arm/link2.glb"/>
      </geometry>
    </visual>
    <collision>
      <geometry>
        <mesh filename="package://rm75_description/meshes/arm/link2.glb"/>
      </geometry>
    </collision>
  </link>
  <link name="link3">
    <inertial>
      <origin xyz="6.84676164566044E-07 0.0273475408308154 -0.0235440119707943"/>
      <mass value="0.431325495678459"/>
      <inertia ixx="0.000794332771462568" ixy="1.03353218375171E-08" ixz="-2.32798826854953E-09" iyy="0.000315065343266245" iyz="-0.000142620540462618" izz="0.000730371131605455"/>
    </inertial>
    <visual>
      <geometry>
        <mesh filename="package://rm75_description/meshes/arm/link3.glb"/>
      </geometry>
    </visual>
    <collision>
      <geometry>
        <mesh filename="package://rm75_description/meshes/arm/link3.glb"/>
      </geometry>
    </collision>
  </link>
  <link name="link4">
    <inertial>
      <origin xyz="5.05312670298932E-06 0.0105690692118619 0.0595925663703773"/>
      <mass value="0.289633681619295"/>
      <inertia ixx="0.000637371004484591" ixy="-3.86643270900744E-08" ixz="7.05261290886955E-08" iyy="0.000614178164759844" iyz="0.000144610359942128" izz="0.000156483880946498"/>
    </inertial>
    <visual>
      <geometry>
        <mesh filename="package://rm75_description/meshes/arm/link4.glb"/>
      </geometry>
    </visual>
    <collision>
      <geometry>
        <mesh filename="package://rm75_description/meshes/arm/link4.glb"/>
      </geometry>
    </collision>
  </link>
  <link name="link5">
    <inertial>
      <origin xyz="1.1551661767744E-06 0.0215394748352686 -0.0180424468598241"/>
      <mass value="0.239419768320061"/>
      <inertia ixx="0.000285938919722783" ixy="2.21994116852616E-09" ixz="3.07101358617598E-09" iyy="0.00011988808279186" iyz="-4.4236583260078E-05" izz="0.000262727540304212"/>
    </inertial>
    <visual>
      <geometry>
        <mesh filename="package://rm75_description/meshes/arm/link5.glb"/>
      </geometry>
    </visual>
    <collision>
      <geometry>
        <mesh filename="package://rm75_description/meshes/arm/link5.glb"/>
      </geometry>
    </collision>
  </link>
  <link name="link6">
    <inertial>
      <origin xyz="3.19794787018954E-06 0.00736804250989373 0.0593808368101291"/>
      <mass value="0.218799761431682"/>
      <inertia ixx="0.000350540363914436" ixy="-1.7705645712277E-08" ixz="3.41781620449632E-08" iyy="0.000334482418423991" iyz="7.82431228462317E-05" izz="0.000104927867487584"/>
    </inertial>
    <visual>
      <geometry>
        <mesh filename="package://rm75_description/meshes/arm/link6.glb"/>
      </geometry>
    </visual>
    <collision>
      <geometry>
        <mesh filename="package://rm75_description/meshes/arm/link6.glb"/>
      </geometry>
    </collision>
  </link>
  <link name="link7">
    <inertial>
      <origin xyz="0.000714238382876259 -0.000396711987952758 -0.0126723660946126"/>
      <mass value="0.0649018034311231"/>
      <inertia ixx="2.02766547502765E-05" ixy="-1.32505200276848E-06" ixz="-2.58450915224912E-08" iyy="1.87986725225022E-05" iyz="3.39471452123283E-09" izz="3.17885459163081E-05"/>
    </inertial>
    <visual>
      <geometry>
        <mesh filename="package://rm75_description/meshes/ee/ee_basic.glb"/>
      </geometry>
    </visual>
    <collision>
      <geometry>
        <mesh filename="package://rm75_description/meshes/ee/ee_basic.glb"/>
      </geometry>
    </collision>
  </link>
  <joint name="joint1" type="revolute">
    <parent link="arm_root"/>
    <child link="link1"/>
    <axis xyz="0 -1 0"/>
    <limit effort="60" lower="-3.1" upper="3.1" velocity="3.14"/>
  </joint>
  <joint name="joint2" type="revolute">
    <origin rpy="1.5708 0 0"/>
    <parent link="link1"/>
    <child link="link2"/>
    <axis xyz="0 1 0"/>
    <limit effort="60" lower="-2.268" upper="2.268" velocity="3.14"/>
  </joint>
  <joint name="joint3" type="revolute">
    <origin rpy="-1.5708 0 0" xyz="0 0 0.256"/>
    <parent link="link2"/>
    <child link="link3"/>
    <axis xyz="0 -1 0"/>
    <limit effort="30" lower="-3.1" upper="3.1" velocity="3.92"/>
  </joint>
  <joint name="joint4" type="revolute">
    <origin rpy="1.5708 0 0"/>
    <parent link="link3"/>
    <child link="link4"/>
    <axis xyz="0 1 0"/>
    <limit effort="30" lower="-2.355" upper="2.355" velocity="3.92"/>
  </joint>
  <joint name="joint5" type="revolute">
    <origin rpy="-1.5708 0 0" xyz="0 0 0.21"/>
    <parent link="link4"/>
    <child link="link5"/>
    <axis xyz="0 -1 0"/>
    <limit effort="10" lower="-3.1" upper="3.1" velocity="3.92"/>
  </joint>
  <joint name="joint6" type="revolute">
    <origin rpy="1.5708 0 0"/>
    <parent link="link5"/>
    <child link="link6"/>
    <axis xyz="0 1 0"/>
    <limit effort="10" lower="-2.233" upper="2.233" velocity="3.92"/>
  </joint>
  <joint name="joint7" type="revolute">
    <origin xyz="0 0 0.115"/>
    <parent link="link6"/>
    <child link="link7"/>
    <axis xyz="0 0 1"/>
    <limit effort="10" lower="-6.28" upper="6.28" velocity="3.925"/>
  </joint>
  <!-- End effector link for gripper attachment -->
  <link name="ee">
  </link>
  <joint name="ee_joint" type="fixed">
    <origin xyz="0 0 0.02905"/>
    <parent link="link7"/>
    <child link="ee"/>
  </joint>
</robot>
