<?xml version="1.0" ?>
<!-- =================================================================================== -->
<!-- |    This document was autogenerated by xacro from robot.xacro                    | -->
<!-- |    EDITING THIS FILE BY HAND IS NOT RECOMMENDED                                 | -->
<!-- =================================================================================== -->
<robot name="AgileX Aloha">
  <link name="base_footprint"/>
  <joint name="base_joint" type="fixed">
    <origin xyz="0 0 0.143"/>
    <parent link="base_footprint"/>
    <child link="base_link"/>
    <axis/>
  </joint>
  <link name="base_link">
    <visual>
      <geometry>
        <mesh filename="package://agilex_aloha_description/meshes/tracer/tracer_base_link.obj"/>
      </geometry>
    </visual>
    <collision>
      <geometry>
        <mesh filename="package://agilex_aloha_description/meshes/tracer/tracer_base_link.obj"/>
      </geometry>
    </collision>
  </link>
  <link name="inertial_link">
    <inertial>
      <mass value="132.3898489950015"/>
      <origin xyz="0.015 0.0231316650320557 0"/>
      <inertia ixx="0.185196122711036" ixy="4.30144213829512E-08" ixz="5.81037523686401E-08" iyy="0.364893736238929" iyz="-0.000386720198091934" izz="0.223868521722778"/>
    </inertial>
  </link>
  <joint name="inertial_joint" type="fixed">
    <origin/>
    <parent link="base_link"/>
    <child link="inertial_link"/>
  </joint>
  <link name="right_wheel_link">
    <inertial>
      <mass value="6"/>
      <inertia ixx="0.7171" ixy="0" ixz="0" iyy="0.1361" iyz="0" izz="0.7171"/>
    </inertial>
    <visual>
      <geometry>
        <mesh filename="package://agilex_aloha_description/meshes/tracer/tracer_wheel.obj"/>
      </geometry>
    </visual>
    <collision>
      <geometry>
        <mesh filename="package://agilex_aloha_description/meshes/tracer/tracer_wheel.obj"/>
      </geometry>
    </collision>
  </link>
  <joint name="right_wheel" type="continuous">
    <parent link="base_link"/>
    <child link="right_wheel_link"/>
    <origin xyz="0 -0.17 -0.082"/>
    <axis xyz="0 1 0"/>
  </joint>
  <link name="left_wheel_link">
    <inertial>
      <mass value="6"/>
      <inertia ixx="0.7171" ixy="0" ixz="0" iyy="0.1361" iyz="0" izz="0.7171"/>
    </inertial>
    <visual>
      <geometry>
        <mesh filename="package://agilex_aloha_description/meshes/tracer/tracer_wheel.obj"/>
      </geometry>
    </visual>
    <collision>
      <geometry>
        <mesh filename="package://agilex_aloha_description/meshes/tracer/tracer_wheel.obj"/>
      </geometry>
    </collision>
  </link>
  <joint name="left_wheel" type="continuous">
    <parent link="base_link"/>
    <child link="left_wheel_link"/>
    <origin xyz="0 0.17 -0.082"/>
    <axis xyz="0 1 0"/>
  </joint>
  <link name="fl_castor_link">
    <inertial>
      <mass value="1"/>
      <inertia ixx="0.7171" ixy="0" ixz="0" iyy="0.1361" iyz="0" izz="0.7171"/>
    </inertial>
    <visual>
      <geometry>
        <mesh filename="package://agilex_aloha_description/meshes/tracer/castor_joint.obj"/>
      </geometry>
    </visual>
  </link>
  <joint name="fl_castor_wheel" type="continuous">
    <parent link="base_link"/>
    <child link="fl_castor_link"/>
    <origin rpy="-1.57 0 0" xyz="0.19 0.17 -0.038"/>
    <axis xyz="0 1 0"/>
  </joint>
  <link name="fr_castor_link">
    <inertial>
      <mass value="1"/>
      <inertia ixx="0.7171" ixy="0" ixz="0" iyy="0.1361" iyz="0" izz="0.7171"/>
    </inertial>
    <visual>
      <geometry>
        <mesh filename="package://agilex_aloha_description/meshes/tracer/castor_joint.obj"/>
      </geometry>
    </visual>
  </link>
  <joint name="fr_castor_wheel" type="continuous">
    <origin rpy="-1.57 0 0" xyz="0.18955 -0.17 -0.0380886"/>
    <parent link="base_link"/>
    <child link="fr_castor_link"/>
    <axis xyz="0 1 0"/>
  </joint>
  <link name="rr_castor_link">
    <inertial>
      <mass value="1"/>
      <inertia ixx="0.7171" ixy="0" ixz="0" iyy="0.1361" iyz="0" izz="0.7171"/>
    </inertial>
    <visual>
      <geometry>
        <mesh filename="package://agilex_aloha_description/meshes/tracer/castor_joint.obj"/>
      </geometry>
    </visual>
  </link>
  <joint name="rr_castor_wheel" type="continuous">
    <origin rpy="-1.57 0 0" xyz="-0.18955 -0.17 -0.0380886"/>
    <parent link="base_link"/>
    <child link="rr_castor_link"/>
    <axis xyz="0 1 0"/>
  </joint>
  <link name="rl_castor_link">
    <inertial>
      <mass value="1"/>
      <inertia ixx="0.7171" ixy="0" ixz="0" iyy="0.1361" iyz="0" izz="0.7171"/>
    </inertial>
    <visual>
      <geometry>
        <mesh filename="package://agilex_aloha_description/meshes/tracer/castor_joint.obj"/>
      </geometry>
    </visual>
  </link>
  <joint name="rl_castor_wheel" type="continuous">
    <origin rpy="-1.57 0 0" xyz="-0.18955 0.17 -0.0380886"/>
    <parent link="base_link"/>
    <child link="rl_castor_link"/>
    <axis xyz="0 1 0"/>
  </joint>
  <link name="fl_wheel_link">
    <inertial>
      <mass value="1"/>
      <inertia ixx="0.3131" ixy="0" ixz="0" iyy="0.3131" iyz="0" izz="0.1361"/>
    </inertial>
    <visual>
      <geometry>
        <mesh filename="package://agilex_aloha_description/meshes/tracer/castor.obj"/>
      </geometry>
    </visual>
    <collision>
      <geometry>
        --&gt;
				
        <mesh filename="package://agilex_aloha_description/meshes/tracer/castor.obj"/>
      </geometry>
    </collision>
  </link>
  <joint name="fl_wheel" type="continuous">
    <parent link="fl_castor_link"/>
    <child link="fl_wheel_link"/>
    <dynamics damping="0.0" friction="0.0"/>
    <origin xyz="-0.022 0.06385 0"/>
    <axis xyz="0 0 1"/>
  </joint>
  <link name="fr_wheel_link">
    <inertial>
      <mass value="1"/>
      <inertia ixx="0.3131" ixy="0" ixz="0" iyy="0.3131" iyz="0" izz="0.1361"/>
    </inertial>
    <visual>
      <geometry>
        <mesh filename="package://agilex_aloha_description/meshes/tracer/castor.obj"/>
      </geometry>
    </visual>
    <collision>
      <geometry>
        --&gt;
				
        <mesh filename="package://agilex_aloha_description/meshes/tracer/castor.obj"/>
      </geometry>
    </collision>
  </link>
  <joint name="fr_wheel" type="continuous">
    <parent link="fr_castor_link"/>
    <child link="fr_wheel_link"/>
    <dynamics damping="0.0" friction="0.0"/>
    <origin xyz="-0.022 0.06385 0"/>
    <axis xyz="0 0 1"/>
  </joint>
  <link name="rr_wheel_link">
    <inertial>
      <mass value="1"/>
      <inertia ixx="0.3131" ixy="0" ixz="0" iyy="0.3131" iyz="0" izz="0.1361"/>
    </inertial>
    <visual>
      <geometry>
        <mesh filename="package://agilex_aloha_description/meshes/tracer/castor.obj"/>
      </geometry>
    </visual>
    <collision>
      <geometry>
        <mesh filename="package://agilex_aloha_description/meshes/tracer/castor.obj"/>
      </geometry>
    </collision>
  </link>
  <joint name="rr_wheel" type="continuous">
    <parent link="rr_castor_link"/>
    <child link="rr_wheel_link"/>
    <dynamics damping="0.0" friction="0.0"/>
    <origin xyz="-0.022 0.06385 0"/>
    <axis xyz="0 0 1"/>
  </joint>
  <link name="rl_wheel_link">
    <inertial>
      <mass value="1"/>
      <inertia ixx="0.3131" ixy="0" ixz="0" iyy="0.3131" iyz="0" izz="0.1361"/>
    </inertial>
    <visual>
      <geometry>
        <mesh filename="package://agilex_aloha_description/meshes/tracer/castor.obj"/>
      </geometry>
    </visual>
    <collision>
      <geometry>
        <mesh filename="package://agilex_aloha_description/meshes/tracer/castor.obj"/>
      </geometry>
    </collision>
  </link>
  <joint name="rl_wheel" type="continuous">
    <parent link="rl_castor_link"/>
    <child link="rl_wheel_link"/>
    <dynamics damping="0.0" friction="0.0"/>
    <origin xyz="-0.022 0.06385 0"/>
    <axis xyz="0 0 1"/>
  </joint>
  <!-- aloha base -->
  <link name="body_Link">
    <inertial>
      <origin xyz="0.015107 -0.027922 0.00013672"/>
      <mass value="3.736"/>
      <inertia ixx="0.097545" ixy="-9.2609E-06" ixz="0.00015366" iyy="0.045841" iyz="-0.0020459" izz="0.084773"/>
    </inertial>
    <visual>
      <geometry>
        <mesh filename="package://agilex_aloha_description/meshes/aloha_v2/body.obj"/>
      </geometry>
    </visual>
    <collision>
      <geometry>
        <mesh filename="package://agilex_aloha_description/meshes/aloha_v2/body.obj"/>
      </geometry>
    </collision>
  </link>
  <joint name="body_joint" type="fixed">
    <origin xyz="0 0 0.168"/>
    <parent link="base_footprint"/>
    <child link="body_Link"/>
    <axis/>
  </joint>
  <link name="camera_link">
    <inertial>
      <origin xyz="-0.011443 2.4833E-05 -0.0012615"/>
      <mass value="0.020053"/>
      <inertia ixx="1.1181E-05" ixy="1.204E-07" ixz="4.9068E-08" iyy="2.2587E-06" iyz="5.7637E-07" izz="1.0097E-05"/>
    </inertial>
    <visual>
      <geometry>
        <mesh filename="package://sensor_models/meshes/dabai/dabai.obj"/>
      </geometry>
    </visual>
  </link>
  <joint name="camera_joint" type="fixed">
    <origin rpy="0 0.825 0" xyz="0.24007 0 0.91661"/>
    <parent link="body_Link"/>
    <child link="camera_link"/>
  </joint>
  <link name="lidar_link">
    <inertial>
      <origin xyz="-0.0022133 -0.00090659 0.025996"/>
      <mass value="0.048617"/>
      <inertia ixx="1.0358E-05" ixy="9.2377E-09" ixz="-2.6386E-07" iyy="1.0387E-05" iyz="-2.6377E-07" izz="1.7919E-05"/>
    </inertial>
    <visual>
      <geometry>
        <mesh filename="package://sensor_models/meshes/mid360/mid360.obj"/>
      </geometry>
    </visual>
  </link>
  <joint name="lidar_joint" type="fixed">
    <origin xyz="0.27289 0 0.01488"/>
    <parent link="body_Link"/>
    <child link="lidar_link"/>
  </joint>
  <!--***************************** front-left ****************************** -->
  <link name="left_base_link">
    <inertial>
      <origin xyz="-0.00473641164191482 2.56829134630247E-05 0.041451518036016"/>
      <mass value="1.02"/>
      <inertia ixx="0.00267433" ixy="-0.00000073" ixz="-0.00017389" iyy="0.00282612" iyz="0.0000004" izz="0.00089624"/>
    </inertial>
    <visual>
      <geometry>
        <mesh filename="package://piper_description/meshes/visual/base_link.obj"/>
      </geometry>
    </visual>
    <collision>
      <geometry>
        <mesh filename="package://piper_description/meshes/collision/base_link.obj"/>
      </geometry>
    </collision>
  </link>
  <link name="left_link1">
    <inertial>
      <origin xyz="0.000121504734057468 0.000104632162460536 -0.00438597309559853"/>
      <mass value="0.71"/>
      <inertia ixx="0.00048916" ixy="-0.00000036" ixz="-0.00000224" iyy="0.00040472" iyz="-0.00000242" izz="0.00043982"/>
    </inertial>
    <visual>
      <geometry>
        <mesh filename="package://piper_description/meshes/visual/link1.obj"/>
      </geometry>
    </visual>
    <collision>
      <geometry>
        <mesh filename="package://piper_description/meshes/collision/link1.obj"/>
      </geometry>
    </collision>
  </link>
  <joint name="left_joint1" type="revolute">
    <origin rpy="0 0 0" xyz="0 0 0.123"/>
    <parent link="left_base_link"/>
    <child link="left_link1"/>
    <axis xyz="0 0 1"/>
    <limit effort="100" lower="-2.618" upper="2.618" velocity="5"/>
  </joint>
  <link name="left_link2">
    <inertial>
      <origin rpy="0 0 0" xyz="0.198666145229743 -0.010926924140076 0.00142121714502687"/>
      <mass value="1.17"/>
      <inertia ixx="0.00116918" ixy="-0.00180037" ixz="0.00025146" iyy="0.06785384" iyz="-0.00000455" izz="0.06774489"/>
    </inertial>
    <visual>
      <geometry>
        <mesh filename="package://piper_description/meshes/visual/link2.obj"/>
      </geometry>
    </visual>
    <collision>
      <geometry>
        <mesh filename="package://piper_description/meshes/collision/link2.obj"/>
      </geometry>
    </collision>
  </link>
  <joint name="left_joint2" type="revolute">
    <origin rpy="1.5708 -0.1359 -3.1416" xyz="0 0 0"/>
    <parent link="left_link1"/>
    <child link="left_link2"/>
    <axis xyz="0 0 1"/>
    <limit effort="100" lower="0" upper="3.14" velocity="5"/>
  </joint>
  <link name="left_link3">
    <inertial>
      <origin rpy="0 0 0" xyz="-0.0202737662122021 -0.133914995944595 -0.000458682652737356"/>
      <mass value="0.5"/>
      <inertia ixx="0.01361711" ixy="0.00165794" ixz="-0.00000048" iyy="0.00045024" iyz="-0.00000045" izz="0.01380322"/>
    </inertial>
    <visual>
      <geometry>
        <mesh filename="package://piper_description/meshes/visual/link3.obj"/>
      </geometry>
    </visual>
    <collision>
      <geometry>
        <mesh filename="package://piper_description/meshes/collision/link3.obj"/>
      </geometry>
    </collision>
  </link>
  <joint name="left_joint3" type="revolute">
    <origin rpy="0 0 -1.7939" xyz="0.28503 0 0"/>
    <parent link="left_link2"/>
    <child link="left_link3"/>
    <axis xyz="0 0 1"/>
    <limit effort="100" lower="-2.967" upper="0" velocity="5"/>
  </joint>
  <link name="left_link4">
    <inertial>
      <origin rpy="0 0 0" xyz="-9.66635791618542E-05 0.000876064475651083 -0.00496880904640868"/>
      <mass value="0.38"/>
      <inertia ixx="0.00018501" ixy="0.00000054" ixz="0.00000120" iyy="0.00018965" iyz="-0.00000841" izz="0.00015484"/>
    </inertial>
    <visual>
      <geometry>
        <mesh filename="package://piper_description/meshes/visual/link4.obj"/>
      </geometry>
    </visual>
    <collision>
      <geometry>
        <mesh filename="package://piper_description/meshes/collision/link4.obj"/>
      </geometry>
    </collision>
  </link>
  <joint name="left_joint4" type="revolute">
    <origin rpy="1.5708 0 0" xyz="-0.021984 -0.25075 0"/>
    <parent link="left_link3"/>
    <child link="left_link4"/>
    <axis xyz="0 0 1"/>
    <limit effort="100" lower="-1.745" upper="1.745" velocity="5"/>
  </joint>
  <link name="left_link5">
    <inertial>
      <origin rpy="0 0 0" xyz="-4.10554118924211E-05 -0.0566486692356075 -0.0037205791677906"/>
      <mass value="0.383"/>
      <inertia ixx="0.00166169" ixy="0.00000006" ixz="-0.00000007" iyy="0.00018510" iyz="0.00001026" izz="0.00164321"/>
    </inertial>
    <visual>
      <geometry>
        <mesh filename="package://piper_description/meshes/visual/link5.obj"/>
      </geometry>
    </visual>
    <collision>
      <geometry>
        <mesh filename="package://piper_description/meshes/collision/link5.obj"/>
      </geometry>
    </collision>
  </link>
  <joint name="left_joint5" type="revolute">
    <origin rpy="-1.5708 0 0" xyz="0 0 0"/>
    <parent link="left_link4"/>
    <child link="left_link5"/>
    <axis xyz="0 0 1"/>
    <limit effort="100" lower="-1.22" upper="1.22" velocity="5"/>
  </joint>
  <joint name="left_joint6" type="revolute">
    <origin rpy="1.5708 0 0" xyz="0 -0.091 0"/>
    <parent link="left_link5"/>
    <child link="left_link6"/>
    <axis xyz="0 0 1"/>
    <limit effort="100" lower="-2.0944" upper="2.0944" velocity="3"/>
  </joint>
  <link name="left_link6">
    <inertial>
      <origin xyz="-0.000183807162235591 8.05033155577911E-05 0.0321436689908876"/>
      <mass value="0.657"/>
      <inertia ixx="0.00092934" ixy="0.00000034" ixz="-0.00000738" iyy="0.00071447" iyz="0.00000005" izz="0.00039442"/>
    </inertial>
    <visual>
      <geometry>
        <mesh filename="package://piper_description/meshes/visual/link6.obj"/>
      </geometry>
    </visual>
    <collision>
      <geometry>
        <mesh filename="package://piper_description/meshes/collision/link6_collision_0.obj"/>
      </geometry>
    </collision>
    <collision>
      <geometry>
        <mesh filename="package://piper_description/meshes/collision/link6_collision_1.obj"/>
      </geometry>
    </collision>
    <collision>
      <geometry>
        <mesh filename="package://piper_description/meshes/collision/link6_collision_2.obj"/>
      </geometry>
    </collision>
  </link>
  <link name="left_link7">
    <inertial>
      <origin xyz="0.00065123185041968 -0.0491929869131989 0.00972258769184025"/>
      <mass value="0.025"/>
      <inertia ixx="0.00007371" ixy="-0.00000113" ixz="0.00000021" iyy="0.00000781" iyz="-0.00001372" izz="0.0000747"/>
    </inertial>
    <visual>
      <geometry>
        <mesh filename="package://piper_description/meshes/visual/gripper.obj"/>
      </geometry>
    </visual>
    <collision>
      <geometry>
        <mesh filename="package://piper_description/meshes/collision/gripper.obj"/>
      </geometry>
    </collision>
  </link>
  <joint name="left_gripper_joint" type="prismatic">
    <origin xyz="0 0 0.1358"/>
    <parent link="left_link6"/>
    <child link="left_link7"/>
    <axis xyz="0 -1 0"/>
    <limit effort="10" lower="0" upper="0.035" velocity="1"/>
  </joint>
  <link name="left_link8">
    <inertial>
      <origin xyz="0.000651231850419722 -0.0491929869131991 0.00972258769184024"/>
      <mass value="0.025"/>
      <inertia ixx="0.00007371" ixy="-0.00000113" ixz="0.00000021" iyy="0.00000781" iyz="-0.00001372" izz="0.0000747"/>
    </inertial>
    <visual>
      <geometry>
        <mesh filename="package://piper_description/meshes/visual/gripper.obj" scale="1 -1 1"/>
      </geometry>
    </visual>
    <collision>
      <geometry>
        <mesh filename="package://piper_description/meshes/collision/gripper.obj" scale="1 -1 1"/>
      </geometry>
    </collision>
  </link>
  <joint name="left_joint8" type="prismatic">
    <origin xyz="0 0 0.1358"/>
    <parent link="left_link6"/>
    <child link="left_link8"/>
    <mimic joint="left_gripper_joint" multiplier="1" offset="0"/>
    <axis xyz="0 1 0"/>
    <limit effort="10" lower="0" upper="0.035" velocity="1"/>
  </joint>
  <link name="left_gripper_center"/>
  <joint name="left_gripper_center_fixed" type="fixed">
    <parent link="left_link6"/>
    <child link="left_gripper_center"/>
    <origin rpy="0 -1.57 0" xyz="0 0 0.1358"/>
  </joint>
  <link name="left_camera"/>
  <joint name="left_camera_fixed" type="fixed">
    <origin rpy="-0.3463 0 -1.5708" xyz="-0.073 0 0.041"/>
    <parent link="left_link6"/>
    <child link="left_camera"/>
  </joint>
  <joint name="left_base_joint" type="fixed">
    <origin xyz="0.23875 0.3 0.607"/>
    <parent link="body_Link"/>
    <child link="left_base_link"/>
    <axis xyz="0 0 1"/>
  </joint>
  <link name="right_base_link">
    <inertial>
      <origin xyz="-0.00473641164191482 2.56829134630247E-05 0.041451518036016"/>
      <mass value="1.02"/>
      <inertia ixx="0.00267433" ixy="-0.00000073" ixz="-0.00017389" iyy="0.00282612" iyz="0.0000004" izz="0.00089624"/>
    </inertial>
    <visual>
      <geometry>
        <mesh filename="package://piper_description/meshes/visual/base_link.obj"/>
      </geometry>
    </visual>
    <collision>
      <geometry>
        <mesh filename="package://piper_description/meshes/collision/base_link.obj"/>
      </geometry>
    </collision>
  </link>
  <link name="right_link1">
    <inertial>
      <origin xyz="0.000121504734057468 0.000104632162460536 -0.00438597309559853"/>
      <mass value="0.71"/>
      <inertia ixx="0.00048916" ixy="-0.00000036" ixz="-0.00000224" iyy="0.00040472" iyz="-0.00000242" izz="0.00043982"/>
    </inertial>
    <visual>
      <geometry>
        <mesh filename="package://piper_description/meshes/visual/link1.obj"/>
      </geometry>
    </visual>
    <collision>
      <geometry>
        <mesh filename="package://piper_description/meshes/collision/link1.obj"/>
      </geometry>
    </collision>
  </link>
  <joint name="right_joint1" type="revolute">
    <origin rpy="0 0 0" xyz="0 0 0.123"/>
    <parent link="right_base_link"/>
    <child link="right_link1"/>
    <axis xyz="0 0 1"/>
    <limit effort="100" lower="-2.618" upper="2.618" velocity="5"/>
  </joint>
  <link name="right_link2">
    <inertial>
      <origin rpy="0 0 0" xyz="0.198666145229743 -0.010926924140076 0.00142121714502687"/>
      <mass value="1.17"/>
      <inertia ixx="0.00116918" ixy="-0.00180037" ixz="0.00025146" iyy="0.06785384" iyz="-0.00000455" izz="0.06774489"/>
    </inertial>
    <visual>
      <geometry>
        <mesh filename="package://piper_description/meshes/visual/link2.obj"/>
      </geometry>
    </visual>
    <collision>
      <geometry>
        <mesh filename="package://piper_description/meshes/collision/link2.obj"/>
      </geometry>
    </collision>
  </link>
  <joint name="right_joint2" type="revolute">
    <origin rpy="1.5708 -0.1359 -3.1416" xyz="0 0 0"/>
    <parent link="right_link1"/>
    <child link="right_link2"/>
    <axis xyz="0 0 1"/>
    <limit effort="100" lower="0" upper="3.14" velocity="5"/>
  </joint>
  <link name="right_link3">
    <inertial>
      <origin rpy="0 0 0" xyz="-0.0202737662122021 -0.133914995944595 -0.000458682652737356"/>
      <mass value="0.5"/>
      <inertia ixx="0.01361711" ixy="0.00165794" ixz="-0.00000048" iyy="0.00045024" iyz="-0.00000045" izz="0.01380322"/>
    </inertial>
    <visual>
      <geometry>
        <mesh filename="package://piper_description/meshes/visual/link3.obj"/>
      </geometry>
    </visual>
    <collision>
      <geometry>
        <mesh filename="package://piper_description/meshes/collision/link3.obj"/>
      </geometry>
    </collision>
  </link>
  <joint name="right_joint3" type="revolute">
    <origin rpy="0 0 -1.7939" xyz="0.28503 0 0"/>
    <parent link="right_link2"/>
    <child link="right_link3"/>
    <axis xyz="0 0 1"/>
    <limit effort="100" lower="-2.967" upper="0" velocity="5"/>
  </joint>
  <link name="right_link4">
    <inertial>
      <origin rpy="0 0 0" xyz="-9.66635791618542E-05 0.000876064475651083 -0.00496880904640868"/>
      <mass value="0.38"/>
      <inertia ixx="0.00018501" ixy="0.00000054" ixz="0.00000120" iyy="0.00018965" iyz="-0.00000841" izz="0.00015484"/>
    </inertial>
    <visual>
      <geometry>
        <mesh filename="package://piper_description/meshes/visual/link4.obj"/>
      </geometry>
    </visual>
    <collision>
      <geometry>
        <mesh filename="package://piper_description/meshes/collision/link4.obj"/>
      </geometry>
    </collision>
  </link>
  <joint name="right_joint4" type="revolute">
    <origin rpy="1.5708 0 0" xyz="-0.021984 -0.25075 0"/>
    <parent link="right_link3"/>
    <child link="right_link4"/>
    <axis xyz="0 0 1"/>
    <limit effort="100" lower="-1.745" upper="1.745" velocity="5"/>
  </joint>
  <link name="right_link5">
    <inertial>
      <origin rpy="0 0 0" xyz="-4.10554118924211E-05 -0.0566486692356075 -0.0037205791677906"/>
      <mass value="0.383"/>
      <inertia ixx="0.00166169" ixy="0.00000006" ixz="-0.00000007" iyy="0.00018510" iyz="0.00001026" izz="0.00164321"/>
    </inertial>
    <visual>
      <geometry>
        <mesh filename="package://piper_description/meshes/visual/link5.obj"/>
      </geometry>
    </visual>
    <collision>
      <geometry>
        <mesh filename="package://piper_description/meshes/collision/link5.obj"/>
      </geometry>
    </collision>
  </link>
  <joint name="right_joint5" type="revolute">
    <origin rpy="-1.5708 0 0" xyz="0 0 0"/>
    <parent link="right_link4"/>
    <child link="right_link5"/>
    <axis xyz="0 0 1"/>
    <limit effort="100" lower="-1.22" upper="1.22" velocity="5"/>
  </joint>
  <joint name="right_joint6" type="revolute">
    <origin rpy="1.5708 0 0" xyz="0 -0.091 0"/>
    <parent link="right_link5"/>
    <child link="right_link6"/>
    <axis xyz="0 0 1"/>
    <limit effort="100" lower="-2.0944" upper="2.0944" velocity="3"/>
  </joint>
  <link name="right_link6">
    <inertial>
      <origin xyz="-0.000183807162235591 8.05033155577911E-05 0.0321436689908876"/>
      <mass value="0.657"/>
      <inertia ixx="0.00092934" ixy="0.00000034" ixz="-0.00000738" iyy="0.00071447" iyz="0.00000005" izz="0.00039442"/>
    </inertial>
    <visual>
      <geometry>
        <mesh filename="package://piper_description/meshes/visual/link6.obj"/>
      </geometry>
    </visual>
    <collision>
      <geometry>
        <mesh filename="package://piper_description/meshes/collision/link6_collision_0.obj"/>
      </geometry>
    </collision>
    <collision>
      <geometry>
        <mesh filename="package://piper_description/meshes/collision/link6_collision_1.obj"/>
      </geometry>
    </collision>
    <collision>
      <geometry>
        <mesh filename="package://piper_description/meshes/collision/link6_collision_2.obj"/>
      </geometry>
    </collision>
  </link>
  <link name="right_link7">
    <inertial>
      <origin xyz="0.00065123185041968 -0.0491929869131989 0.00972258769184025"/>
      <mass value="0.025"/>
      <inertia ixx="0.00007371" ixy="-0.00000113" ixz="0.00000021" iyy="0.00000781" iyz="-0.00001372" izz="0.0000747"/>
    </inertial>
    <visual>
      <geometry>
        <mesh filename="package://piper_description/meshes/visual/gripper.obj"/>
      </geometry>
    </visual>
    <collision>
      <geometry>
        <mesh filename="package://piper_description/meshes/collision/gripper.obj"/>
      </geometry>
    </collision>
  </link>
  <joint name="right_gripper_joint" type="prismatic">
    <origin xyz="0 0 0.1358"/>
    <parent link="right_link6"/>
    <child link="right_link7"/>
    <axis xyz="0 -1 0"/>
    <limit effort="10" lower="0" upper="0.035" velocity="1"/>
  </joint>
  <link name="right_link8">
    <inertial>
      <origin xyz="0.000651231850419722 -0.0491929869131991 0.00972258769184024"/>
      <mass value="0.025"/>
      <inertia ixx="0.00007371" ixy="-0.00000113" ixz="0.00000021" iyy="0.00000781" iyz="-0.00001372" izz="0.0000747"/>
    </inertial>
    <visual>
      <geometry>
        <mesh filename="package://piper_description/meshes/visual/gripper.obj" scale="1 -1 1"/>
      </geometry>
    </visual>
    <collision>
      <geometry>
        <mesh filename="package://piper_description/meshes/collision/gripper.obj" scale="1 -1 1"/>
      </geometry>
    </collision>
  </link>
  <joint name="right_joint8" type="prismatic">
    <origin xyz="0 0 0.1358"/>
    <parent link="right_link6"/>
    <child link="right_link8"/>
    <mimic joint="right_gripper_joint" multiplier="1" offset="0"/>
    <axis xyz="0 1 0"/>
    <limit effort="10" lower="0" upper="0.035" velocity="1"/>
  </joint>
  <link name="right_gripper_center"/>
  <joint name="right_gripper_center_fixed" type="fixed">
    <parent link="right_link6"/>
    <child link="right_gripper_center"/>
    <origin rpy="0 -1.57 0" xyz="0 0 0.1358"/>
  </joint>
  <link name="right_camera"/>
  <joint name="right_camera_fixed" type="fixed">
    <origin rpy="-0.3463 0 -1.5708" xyz="-0.073 0 0.041"/>
    <parent link="right_link6"/>
    <child link="right_camera"/>
  </joint>
  <joint name="right_base_joint" type="fixed">
    <origin xyz="0.23875 -0.3 0.607"/>
    <parent link="body_Link"/>
    <child link="right_base_link"/>
    <axis xyz="0 0 1"/>
  </joint>
</robot>
