<?xml version="1.0" ?>
<!-- =================================================================================== -->
<!-- |    This document was autogenerated by xacro from robot.xacro                    | -->
<!-- |    EDITING THIS FILE BY HAND IS NOT RECOMMENDED                                 | -->
<!-- =================================================================================== -->
<robot name="AgileX Aloha">
  <link name="base_footprint"/>
  <joint name="base_joint" type="fixed">
    <origin xyz="0 0 0.143"/>
    <parent link="base_footprint"/>
    <child link="base_link"/>
    <axis/>
  </joint>
  <link name="base_link">
    <visual>
      <geometry>
        <mesh filename="package://agilex_aloha_description/meshes/tracer/tracer_base_link.obj"/>
      </geometry>
    </visual>
    <collision>
      <geometry>
        <mesh filename="package://agilex_aloha_description/meshes/tracer/tracer_base_link.obj"/>
      </geometry>
    </collision>
  </link>
  <link name="inertial_link">
    <inertial>
      <mass value="132.3898489950015"/>
      <origin xyz="0.015 0.0231316650320557 0"/>
      <inertia ixx="0.185196122711036" ixy="4.30144213829512E-08" ixz="5.81037523686401E-08" iyy="0.364893736238929" iyz="-0.000386720198091934" izz="0.223868521722778"/>
    </inertial>
  </link>
  <joint name="inertial_joint" type="fixed">
    <origin/>
    <parent link="base_link"/>
    <child link="inertial_link"/>
  </joint>
  <link name="right_wheel_link">
    <inertial>
      <mass value="6"/>
      <inertia ixx="0.7171" ixy="0" ixz="0" iyy="0.1361" iyz="0" izz="0.7171"/>
    </inertial>
    <visual>
      <geometry>
        <mesh filename="package://agilex_aloha_description/meshes/tracer/tracer_wheel.obj"/>
      </geometry>
    </visual>
    <collision>
      <geometry>
        <mesh filename="package://agilex_aloha_description/meshes/tracer/tracer_wheel.obj"/>
      </geometry>
    </collision>
  </link>
  <joint name="right_wheel" type="continuous">
    <parent link="base_link"/>
    <child link="right_wheel_link"/>
    <origin xyz="0 -0.17 -0.082"/>
    <axis xyz="0 1 0"/>
  </joint>
  <link name="left_wheel_link">
    <inertial>
      <mass value="6"/>
      <inertia ixx="0.7171" ixy="0" ixz="0" iyy="0.1361" iyz="0" izz="0.7171"/>
    </inertial>
    <visual>
      <geometry>
        <mesh filename="package://agilex_aloha_description/meshes/tracer/tracer_wheel.obj"/>
      </geometry>
    </visual>
    <collision>
      <geometry>
        <mesh filename="package://agilex_aloha_description/meshes/tracer/tracer_wheel.obj"/>
      </geometry>
    </collision>
  </link>
  <joint name="left_wheel" type="continuous">
    <parent link="base_link"/>
    <child link="left_wheel_link"/>
    <origin xyz="0 0.17 -0.082"/>
    <axis xyz="0 1 0"/>
  </joint>
  <link name="fl_castor_link">
    <inertial>
      <mass value="1"/>
      <inertia ixx="0.7171" ixy="0" ixz="0" iyy="0.1361" iyz="0" izz="0.7171"/>
    </inertial>
    <visual>
      <geometry>
        <mesh filename="package://agilex_aloha_description/meshes/tracer/castor_joint.obj"/>
      </geometry>
    </visual>
  </link>
  <joint name="fl_castor_wheel" type="continuous">
    <parent link="base_link"/>
    <child link="fl_castor_link"/>
    <origin rpy="-1.57 0 0" xyz="0.19 0.17 -0.038"/>
    <axis xyz="0 1 0"/>
  </joint>
  <link name="fr_castor_link">
    <inertial>
      <mass value="1"/>
      <inertia ixx="0.7171" ixy="0" ixz="0" iyy="0.1361" iyz="0" izz="0.7171"/>
    </inertial>
    <visual>
      <geometry>
        <mesh filename="package://agilex_aloha_description/meshes/tracer/castor_joint.obj"/>
      </geometry>
    </visual>
  </link>
  <joint name="fr_castor_wheel" type="continuous">
    <origin rpy="-1.57 0 0" xyz="0.18955 -0.17 -0.0380886"/>
    <parent link="base_link"/>
    <child link="fr_castor_link"/>
    <axis xyz="0 1 0"/>
  </joint>
  <link name="rr_castor_link">
    <inertial>
      <mass value="1"/>
      <inertia ixx="0.7171" ixy="0" ixz="0" iyy="0.1361" iyz="0" izz="0.7171"/>
    </inertial>
    <visual>
      <geometry>
        <mesh filename="package://agilex_aloha_description/meshes/tracer/castor_joint.obj"/>
      </geometry>
    </visual>
  </link>
  <joint name="rr_castor_wheel" type="continuous">
    <origin rpy="-1.57 0 0" xyz="-0.18955 -0.17 -0.0380886"/>
    <parent link="base_link"/>
    <child link="rr_castor_link"/>
    <axis xyz="0 1 0"/>
  </joint>
  <link name="rl_castor_link">
    <inertial>
      <mass value="1"/>
      <inertia ixx="0.7171" ixy="0" ixz="0" iyy="0.1361" iyz="0" izz="0.7171"/>
    </inertial>
    <visual>
      <geometry>
        <mesh filename="package://agilex_aloha_description/meshes/tracer/castor_joint.obj"/>
      </geometry>
    </visual>
  </link>
  <joint name="rl_castor_wheel" type="continuous">
    <origin rpy="-1.57 0 0" xyz="-0.18955 0.17 -0.0380886"/>
    <parent link="base_link"/>
    <child link="rl_castor_link"/>
    <axis xyz="0 1 0"/>
  </joint>
  <link name="fl_wheel_link">
    <inertial>
      <mass value="1"/>
      <inertia ixx="0.3131" ixy="0" ixz="0" iyy="0.3131" iyz="0" izz="0.1361"/>
    </inertial>
    <visual>
      <geometry>
        <mesh filename="package://agilex_aloha_description/meshes/tracer/castor.obj"/>
      </geometry>
    </visual>
    <collision>
      <geometry>
        --&gt;
				
        <mesh filename="package://agilex_aloha_description/meshes/tracer/castor.obj"/>
      </geometry>
    </collision>
  </link>
  <joint name="fl_wheel" type="continuous">
    <parent link="fl_castor_link"/>
    <child link="fl_wheel_link"/>
    <dynamics damping="0.0" friction="0.0"/>
    <origin xyz="-0.022 0.06385 0"/>
    <axis xyz="0 0 1"/>
  </joint>
  <link name="fr_wheel_link">
    <inertial>
      <mass value="1"/>
      <inertia ixx="0.3131" ixy="0" ixz="0" iyy="0.3131" iyz="0" izz="0.1361"/>
    </inertial>
    <visual>
      <geometry>
        <mesh filename="package://agilex_aloha_description/meshes/tracer/castor.obj"/>
      </geometry>
    </visual>
    <collision>
      <geometry>
        --&gt;
				
        <mesh filename="package://agilex_aloha_description/meshes/tracer/castor.obj"/>
      </geometry>
    </collision>
  </link>
  <joint name="fr_wheel" type="continuous">
    <parent link="fr_castor_link"/>
    <child link="fr_wheel_link"/>
    <dynamics damping="0.0" friction="0.0"/>
    <origin xyz="-0.022 0.06385 0"/>
    <axis xyz="0 0 1"/>
  </joint>
  <link name="rr_wheel_link">
    <inertial>
      <mass value="1"/>
      <inertia ixx="0.3131" ixy="0" ixz="0" iyy="0.3131" iyz="0" izz="0.1361"/>
    </inertial>
    <visual>
      <geometry>
        <mesh filename="package://agilex_aloha_description/meshes/tracer/castor.obj"/>
      </geometry>
    </visual>
    <collision>
      <geometry>
        <mesh filename="package://agilex_aloha_description/meshes/tracer/castor.obj"/>
      </geometry>
    </collision>
  </link>
  <joint name="rr_wheel" type="continuous">
    <parent link="rr_castor_link"/>
    <child link="rr_wheel_link"/>
    <dynamics damping="0.0" friction="0.0"/>
    <origin xyz="-0.022 0.06385 0"/>
    <axis xyz="0 0 1"/>
  </joint>
  <link name="rl_wheel_link">
    <inertial>
      <mass value="1"/>
      <inertia ixx="0.3131" ixy="0" ixz="0" iyy="0.3131" iyz="0" izz="0.1361"/>
    </inertial>
    <visual>
      <geometry>
        <mesh filename="package://agilex_aloha_description/meshes/tracer/castor.obj"/>
      </geometry>
    </visual>
    <collision>
      <geometry>
        <mesh filename="package://agilex_aloha_description/meshes/tracer/castor.obj"/>
      </geometry>
    </collision>
  </link>
  <joint name="rl_wheel" type="continuous">
    <parent link="rl_castor_link"/>
    <child link="rl_wheel_link"/>
    <dynamics damping="0.0" friction="0.0"/>
    <origin xyz="-0.022 0.06385 0"/>
    <axis xyz="0 0 1"/>
  </joint>
  <link name="body_link">
    <inertial>
      <origin xyz="0.015107 -0.027922 0.00013672"/>
      <mass value="3.736"/>
      <inertia ixx="0.097545" ixy="-9.2609E-06" ixz="0.00015366" iyy="0.045841" iyz="-0.0020459" izz="0.084773"/>
    </inertial>
    <visual>
      <geometry>
        <mesh filename="package://agilex_aloha_description/meshes/aloha_v1/body_link.obj"/>
      </geometry>
    </visual>
    <collision>
      <geometry>
        <mesh filename="package://agilex_aloha_description/meshes/aloha_v1/body_link.obj"/>
      </geometry>
    </collision>
  </link>
  <joint name="box2" type="fixed">
    <origin xyz="0 0 0.15"/>
    <parent link="base_footprint"/>
    <child link="body_link"/>
  </joint>
  <link name="camera_base_link">
    <inertial>
      <origin xyz="-0.00862442289199344 -5.31672329634469E-08 0.170092831004467"/>
      <mass value="0.336269569361489"/>
      <inertia ixx="0.00580628296841397" ixy="3.98435937176716E-10" ixz="-2.42350052877161E-05" iyy="0.00582602200678083" iyz="2.9180594404216E-10" izz="0.000186894283496158"/>
    </inertial>
    <visual>
      <geometry>
        <mesh filename="package://agilex_aloha_description/meshes/aloha_v1/camera_support.obj"/>
      </geometry>
    </visual>
    <collision>
      <geometry>
        <mesh filename="package://agilex_aloha_description/meshes/aloha_v1/camera_support.obj"/>
      </geometry>
    </collision>
  </link>
  <joint name="camera_to_box1" type="fixed">
    <origin xyz="0.18 0 0.626"/>
    <parent link="body_link"/>
    <child link="camera_base_link"/>
    <axis/>
  </joint>
  <link name="camera_link1">
    <inertial>
      <origin xyz="-0.0292387906463559 0.000126439620513119 -0.000724950892729725"/>
      <mass value="0.0877001598245188"/>
      <inertia ixx="7.77343248794949E-05" ixy="2.44922634558373E-07" ixz="1.73341747661077E-08" iyy="9.73521513961785E-06" iyz="-2.86133018917868E-09" izz="7.74948757118157E-05"/>
    </inertial>
    <visual>
      <geometry>
        <mesh filename="package://agilex_aloha_description/meshes/aloha_v1/camera_stand.obj"/>
      </geometry>
    </visual>
    <visual>
      <geometry>
        <mesh filename="package://sensor_models/meshes/d435/d435.obj"/>
      </geometry>
    </visual>
  </link>
  <joint name="camera_joint1" type="fixed">
    <origin rpy="0 0.26931 0" xyz="0.071198 0 0.10384"/>
    <parent link="camera_base_link"/>
    <child link="camera_link1"/>
  </joint>
  <link name="camera_link2">
    <inertial>
      <origin xyz="-0.0292307474530399 0.000126438461566014 -0.000753459207498031"/>
      <mass value="0.0877001605148491"/>
      <inertia ixx="7.77338961798341E-05" ixy="2.44922367048273E-07" ixz="1.80373226250749E-08" iyy="9.73521616927317E-06" iyz="-2.86130173714525E-09" izz="7.74953085203139E-05"/>
    </inertial>
    <visual>
      <geometry>
        <mesh filename="package://agilex_aloha_description/meshes/aloha_v1/camera_stand.obj"/>
      </geometry>
    </visual>
    <visual>
      <geometry>
        <mesh filename="package://sensor_models/meshes/d435/d435.obj"/>
      </geometry>
    </visual>
  </link>
  <joint name="camera_joint2" type="fixed">
    <origin rpy="0 0.011358 0" xyz="-0.14 0 0.5"/>
    <parent link="camera_link1"/>
    <child link="camera_link2"/>
  </joint>
  <link name="lidar_link">
    <inertial>
      <origin xyz="-0.0022133 -0.00090659 0.025996"/>
      <mass value="0.048617"/>
      <inertia ixx="1.0358E-05" ixy="9.2377E-09" ixz="-2.6386E-07" iyy="1.0387E-05" iyz="-2.6377E-07" izz="1.7919E-05"/>
    </inertial>
    <visual>
      <geometry>
        <mesh filename="package://sensor_models/meshes/livox/mid360.glb"/>
      </geometry>
    </visual>
  </link>
  <joint name="lidar_joint" type="fixed">
    <origin xyz="0.22937 0 0.040672"/>
    <parent link="body_link"/>
    <child link="lidar_link"/>
  </joint>
  <joint name="fl_base_joint" type="fixed">
    <origin xyz="0.233 0.3 0.7775"/>
    <parent link="base_footprint"/>
    <child link="left_base_link"/>
    <axis xyz="0.0 0.0 1.0"/>
  </joint>
  <joint name="fr_base_joint" type="fixed">
    <origin xyz="0.233 -0.3 0.7775"/>
    <parent link="base_footprint"/>
    <child link="right_base_link"/>
    <axis xyz="0.0 0.0 1.0"/>
  </joint>
  <link name="left_base_link">
    <inertial>
      <origin xyz="-3.0001E-05 3.0589E-05 0.027324"/>
      <mass value="0.43995"/>
      <inertia ixx="0.00017" ixy="0.00000" ixz="0.00000" iyy="0.00017" iyz="0.00000" izz="0.00016"/>
    </inertial>
    <visual>
      <geometry>
        <mesh filename="package://arx5_description/meshes/x5/base_link.obj"/>
      </geometry>
    </visual>
    <collision>
      <geometry>
        <mesh filename="package://arx5_description/meshes/x5/base_link.obj"/>
      </geometry>
    </collision>
  </link>
  <link name="left_link1">
    <inertial>
      <origin xyz="0.0054231 -0.0080289 0.017086"/>
      <mass value="0.066982"/>
      <inertia ixx="0.00008" ixy="0.00000" ixz="0.00001" iyy="0.00003" iyz="0.00000" izz="0.00008"/>
    </inertial>
    <visual>
      <geometry>
        <mesh filename="package://arx5_description/meshes/x5/link1.obj"/>
      </geometry>
    </visual>
    <collision>
      <geometry>
        <mesh filename="package://arx5_description/meshes/x5/link1.obj"/>
      </geometry>
    </collision>
  </link>
  <joint name="left_joint1" type="revolute">
    <origin xyz="0 0 0.0605"/>
    <parent link="left_base_link"/>
    <child link="left_link1"/>
    <axis xyz="0 0 1"/>
    <limit effort="100" lower="-2.87" upper="3.14" velocity="5"/>
  </joint>
  <link name="left_link2">
    <inertial>
      <origin xyz="-0.13237 0.0020852 0.00010549"/>
      <mass value="1.0795"/>
      <inertia ixx="0.00051" ixy="0.00001" ixz="-0.00004" iyy="0.01599" iyz="0.00000" izz="0.01605"/>
    </inertial>
    <visual>
      <geometry>
        <mesh filename="package://arx5_description/meshes/x5/link2.obj"/>
      </geometry>
    </visual>
    <collision>
      <geometry>
        <mesh filename="package://arx5_description/meshes/x5/link2.obj"/>
      </geometry>
    </collision>
  </link>
  <joint name="left_joint2" type="revolute">
    <origin xyz="0.02 0 0.04"/>
    <parent link="left_link1"/>
    <child link="left_link2"/>
    <axis xyz="0 1 0"/>
    <limit effort="100" lower="0" upper="3.66" velocity="5"/>
  </joint>
  <link name="left_link3">
    <inertial>
      <origin xyz="0.18531 0.00068376 -0.051638"/>
      <mass value="0.54534"/>
      <inertia ixx="0.00036" ixy="-0.00003" ixz="-0.00039" iyy="0.00423" iyz="0.00001" izz="0.00420"/>
    </inertial>
    <visual>
      <geometry>
        <mesh filename="package://arx5_description/meshes/x5/link3.obj"/>
      </geometry>
    </visual>
    <collision>
      <geometry>
        <mesh filename="package://arx5_description/meshes/x5/link3.obj"/>
      </geometry>
    </collision>
  </link>
  <joint name="left_joint3" type="revolute">
    <origin rpy="3.1416 0 0" xyz="-0.264 0 0"/>
    <parent link="left_link2"/>
    <child link="left_link3"/>
    <axis xyz="0 1 0"/>
    <limit effort="100" lower="0" upper="3.14" velocity="5"/>
  </joint>
  <link name="left_link4">
    <inertial>
      <origin xyz="0.040231 0.0044807 -0.035335"/>
      <mass value="0.11714"/>
      <inertia ixx="0.00019" ixy="-0.00002" ixz="-0.00009" iyy="0.00023" iyz="0.00002" izz="0.00014"/>
    </inertial>
    <visual>
      <geometry>
        <mesh filename="package://arx5_description/meshes/x5/link4.obj"/>
      </geometry>
    </visual>
    <collision>
      <geometry>
        <mesh filename="package://arx5_description/meshes/x5/link4.obj"/>
      </geometry>
    </collision>
  </link>
  <joint name="left_joint4" type="revolute">
    <origin xyz="0.245 0 -0.056"/>
    <parent link="left_link3"/>
    <child link="left_link4"/>
    <axis xyz="0 1 0"/>
    <limit effort="100" lower="-1.57" upper="1.57" velocity="5"/>
  </joint>
  <link name="left_link5">
    <inertial>
      <origin xyz="0.003612 -1.5455E-05 0.055214"/>
      <mass value="0.63488"/>
      <inertia ixx="0.00083" ixy="0.00000" ixz="0.00007" iyy="0.00082" iyz="0.00000" izz="0.00026"/>
    </inertial>
    <visual>
      <origin xyz="0.0037 0 0"/>
      <geometry>
        <mesh filename="package://arx5_description/meshes/x5/link5.obj"/>
      </geometry>
    </visual>
    <collision>
      <geometry>
        <mesh filename="package://arx5_description/meshes/x5/link5.obj"/>
      </geometry>
    </collision>
  </link>
  <joint name="left_joint5" type="revolute">
    <origin xyz="0.06775 0.0005 -0.0865"/>
    <parent link="left_link4"/>
    <child link="left_link5"/>
    <axis xyz="0 0 1"/>
    <limit effort="100" lower="-1.57" upper="1.57" velocity="5"/>
  </joint>
  <link name="left_link6">
    <inertial>
      <origin xyz="0.041697 2.4368E-05 0.00014464"/>
      <mass value="0.44089"/>
      <inertia ixx="0.00038" ixy="0.00000" ixz="0.00000" iyy="0.00028" iyz="0.00000" izz="0.00050"/>
    </inertial>
    <visual>
      <geometry>
        <mesh filename="package://arx5_description/meshes/x5/link6.obj"/>
      </geometry>
    </visual>
    <collision>
      <geometry>
        <mesh filename="package://arx5_description/meshes/x5/link6.obj"/>
      </geometry>
    </collision>
  </link>
  <joint name="left_joint6" type="revolute">
    <origin rpy="-3.1416 0 0" xyz="0.02895 0 0.0865"/>
    <parent link="left_link5"/>
    <child link="left_link6"/>
    <axis xyz="1 0 0"/>
    <limit effort="100" lower="-1.57" upper="1.57" velocity="5"/>
  </joint>
  <link name="left_link7">
    <inertial>
      <origin xyz="-0.00035522 -0.007827 -0.0029883"/>
      <mass value="0.064798"/>
      <inertia ixx="0.00002" ixy="0.00000" ixz="0.00000" iyy="0.00003" iyz="0.00000" izz="0.00003"/>
    </inertial>
    <visual>
      <geometry>
        <mesh filename="package://arx5_description/meshes/x5/link7.obj"/>
      </geometry>
    </visual>
    <collision>
      <geometry>
        <mesh filename="package://arx5_description/meshes/x5/link7.obj"/>
      </geometry>
    </collision>
  </link>
  <joint name="left_gripper_joint" type="prismatic">
    <origin xyz="0.08657 0.024896 -0.0002436"/>
    <parent link="left_link6"/>
    <child link="left_link7"/>
    <axis xyz="0 1 0"/>
    <limit effort="100" lower="0" upper="0.044" velocity="5"/>
  </joint>
  <link name="left_link8">
    <inertial>
      <origin xyz="-0.00035522 0.0078277 0.0024201"/>
      <mass value="0.064798"/>
      <inertia ixx="0.00002" ixy="0.00000" ixz="0.00000" iyy="0.00003" iyz="0.00000" izz="0.00003"/>
    </inertial>
    <visual>
      <geometry>
        <mesh filename="package://arx5_description/meshes/x5/link8.obj"/>
      </geometry>
    </visual>
    <collision>
      <geometry>
        <mesh filename="package://arx5_description/meshes/x5/link8.obj"/>
      </geometry>
    </collision>
  </link>
  <joint name="left_joint8" type="prismatic">
    <origin xyz="0.08657 -0.0249 -0.00024366"/>
    <parent link="left_link6"/>
    <child link="left_link8"/>
    <axis xyz="0 -1 0"/>
    <limit effort="100" lower="0" upper="0.044" velocity="5"/>
    <mimic joint="left_gripper_joint" multiplier="1" offset="0"/>
  </joint>
  <link name="left_gripper_center"/>
  <joint name="left_gripper_center_fixed" type="fixed">
    <parent link="left_link6"/>
    <child link="left_gripper_center"/>
    <origin xyz="0.145 0 0"/>
  </joint>
  <link name="left_left_pad"/>
  <joint name="left_left_pad_joint" type="fixed">
    <parent link="left_link7"/>
    <child link="left_left_pad"/>
    <origin xyz="0.05843 -0.0249 0"/>
  </joint>
  <link name="left_right_pad"/>
  <joint name="left_right_pad_joint" type="fixed">
    <parent link="left_link8"/>
    <child link="left_right_pad"/>
    <origin xyz="0.05843 0.0249 0"/>
  </joint>
  <link name="left_camera_support">
    <visual>
      <geometry>
        <mesh filename="package://arx5_description/meshes/camera_stand/stand_d435.obj"/>
      </geometry>
    </visual>
  </link>
  <joint name="left_camera_support_fixed" type="fixed">
    <parent link="left_link6"/>
    <child link="left_camera_support"/>
    <origin xyz="0.045 0 0.021"/>
  </joint>
  <link name="left_camera">
    <visual>
      <geometry>
        <mesh filename="package://sensor_models/meshes/d435/d435.obj"/>
      </geometry>
    </visual>
  </link>
  <joint name="left_camera_fixed" type="fixed">
    <origin xyz="0.03 0 0.034113"/>
    <parent link="left_camera_support"/>
    <child link="left_camera"/>
  </joint>
  <link name="right_base_link">
    <inertial>
      <origin xyz="-3.0001E-05 3.0589E-05 0.027324"/>
      <mass value="0.43995"/>
      <inertia ixx="0.00017" ixy="0.00000" ixz="0.00000" iyy="0.00017" iyz="0.00000" izz="0.00016"/>
    </inertial>
    <visual>
      <geometry>
        <mesh filename="package://arx5_description/meshes/x5/base_link.obj"/>
      </geometry>
    </visual>
    <collision>
      <geometry>
        <mesh filename="package://arx5_description/meshes/x5/base_link.obj"/>
      </geometry>
    </collision>
  </link>
  <link name="right_link1">
    <inertial>
      <origin xyz="0.0054231 -0.0080289 0.017086"/>
      <mass value="0.066982"/>
      <inertia ixx="0.00008" ixy="0.00000" ixz="0.00001" iyy="0.00003" iyz="0.00000" izz="0.00008"/>
    </inertial>
    <visual>
      <geometry>
        <mesh filename="package://arx5_description/meshes/x5/link1.obj"/>
      </geometry>
    </visual>
    <collision>
      <geometry>
        <mesh filename="package://arx5_description/meshes/x5/link1.obj"/>
      </geometry>
    </collision>
  </link>
  <joint name="right_joint1" type="revolute">
    <origin xyz="0 0 0.0605"/>
    <parent link="right_base_link"/>
    <child link="right_link1"/>
    <axis xyz="0 0 1"/>
    <limit effort="100" lower="-2.87" upper="3.14" velocity="5"/>
  </joint>
  <link name="right_link2">
    <inertial>
      <origin xyz="-0.13237 0.0020852 0.00010549"/>
      <mass value="1.0795"/>
      <inertia ixx="0.00051" ixy="0.00001" ixz="-0.00004" iyy="0.01599" iyz="0.00000" izz="0.01605"/>
    </inertial>
    <visual>
      <geometry>
        <mesh filename="package://arx5_description/meshes/x5/link2.obj"/>
      </geometry>
    </visual>
    <collision>
      <geometry>
        <mesh filename="package://arx5_description/meshes/x5/link2.obj"/>
      </geometry>
    </collision>
  </link>
  <joint name="right_joint2" type="revolute">
    <origin xyz="0.02 0 0.04"/>
    <parent link="right_link1"/>
    <child link="right_link2"/>
    <axis xyz="0 1 0"/>
    <limit effort="100" lower="0" upper="3.66" velocity="5"/>
  </joint>
  <link name="right_link3">
    <inertial>
      <origin xyz="0.18531 0.00068376 -0.051638"/>
      <mass value="0.54534"/>
      <inertia ixx="0.00036" ixy="-0.00003" ixz="-0.00039" iyy="0.00423" iyz="0.00001" izz="0.00420"/>
    </inertial>
    <visual>
      <geometry>
        <mesh filename="package://arx5_description/meshes/x5/link3.obj"/>
      </geometry>
    </visual>
    <collision>
      <geometry>
        <mesh filename="package://arx5_description/meshes/x5/link3.obj"/>
      </geometry>
    </collision>
  </link>
  <joint name="right_joint3" type="revolute">
    <origin rpy="3.1416 0 0" xyz="-0.264 0 0"/>
    <parent link="right_link2"/>
    <child link="right_link3"/>
    <axis xyz="0 1 0"/>
    <limit effort="100" lower="0" upper="3.14" velocity="5"/>
  </joint>
  <link name="right_link4">
    <inertial>
      <origin xyz="0.040231 0.0044807 -0.035335"/>
      <mass value="0.11714"/>
      <inertia ixx="0.00019" ixy="-0.00002" ixz="-0.00009" iyy="0.00023" iyz="0.00002" izz="0.00014"/>
    </inertial>
    <visual>
      <geometry>
        <mesh filename="package://arx5_description/meshes/x5/link4.obj"/>
      </geometry>
    </visual>
    <collision>
      <geometry>
        <mesh filename="package://arx5_description/meshes/x5/link4.obj"/>
      </geometry>
    </collision>
  </link>
  <joint name="right_joint4" type="revolute">
    <origin xyz="0.245 0 -0.056"/>
    <parent link="right_link3"/>
    <child link="right_link4"/>
    <axis xyz="0 1 0"/>
    <limit effort="100" lower="-1.57" upper="1.57" velocity="5"/>
  </joint>
  <link name="right_link5">
    <inertial>
      <origin xyz="0.003612 -1.5455E-05 0.055214"/>
      <mass value="0.63488"/>
      <inertia ixx="0.00083" ixy="0.00000" ixz="0.00007" iyy="0.00082" iyz="0.00000" izz="0.00026"/>
    </inertial>
    <visual>
      <origin xyz="0.0037 0 0"/>
      <geometry>
        <mesh filename="package://arx5_description/meshes/x5/link5.obj"/>
      </geometry>
    </visual>
    <collision>
      <geometry>
        <mesh filename="package://arx5_description/meshes/x5/link5.obj"/>
      </geometry>
    </collision>
  </link>
  <joint name="right_joint5" type="revolute">
    <origin xyz="0.06775 0.0005 -0.0865"/>
    <parent link="right_link4"/>
    <child link="right_link5"/>
    <axis xyz="0 0 1"/>
    <limit effort="100" lower="-1.57" upper="1.57" velocity="5"/>
  </joint>
  <link name="right_link6">
    <inertial>
      <origin xyz="0.041697 2.4368E-05 0.00014464"/>
      <mass value="0.44089"/>
      <inertia ixx="0.00038" ixy="0.00000" ixz="0.00000" iyy="0.00028" iyz="0.00000" izz="0.00050"/>
    </inertial>
    <visual>
      <geometry>
        <mesh filename="package://arx5_description/meshes/x5/link6.obj"/>
      </geometry>
    </visual>
    <collision>
      <geometry>
        <mesh filename="package://arx5_description/meshes/x5/link6.obj"/>
      </geometry>
    </collision>
  </link>
  <joint name="right_joint6" type="revolute">
    <origin rpy="-3.1416 0 0" xyz="0.02895 0 0.0865"/>
    <parent link="right_link5"/>
    <child link="right_link6"/>
    <axis xyz="1 0 0"/>
    <limit effort="100" lower="-1.57" upper="1.57" velocity="5"/>
  </joint>
  <link name="right_link7">
    <inertial>
      <origin xyz="-0.00035522 -0.007827 -0.0029883"/>
      <mass value="0.064798"/>
      <inertia ixx="0.00002" ixy="0.00000" ixz="0.00000" iyy="0.00003" iyz="0.00000" izz="0.00003"/>
    </inertial>
    <visual>
      <geometry>
        <mesh filename="package://arx5_description/meshes/x5/link7.obj"/>
      </geometry>
    </visual>
    <collision>
      <geometry>
        <mesh filename="package://arx5_description/meshes/x5/link7.obj"/>
      </geometry>
    </collision>
  </link>
  <joint name="right_gripper_joint" type="prismatic">
    <origin xyz="0.08657 0.024896 -0.0002436"/>
    <parent link="right_link6"/>
    <child link="right_link7"/>
    <axis xyz="0 1 0"/>
    <limit effort="100" lower="0" upper="0.044" velocity="5"/>
  </joint>
  <link name="right_link8">
    <inertial>
      <origin xyz="-0.00035522 0.0078277 0.0024201"/>
      <mass value="0.064798"/>
      <inertia ixx="0.00002" ixy="0.00000" ixz="0.00000" iyy="0.00003" iyz="0.00000" izz="0.00003"/>
    </inertial>
    <visual>
      <geometry>
        <mesh filename="package://arx5_description/meshes/x5/link8.obj"/>
      </geometry>
    </visual>
    <collision>
      <geometry>
        <mesh filename="package://arx5_description/meshes/x5/link8.obj"/>
      </geometry>
    </collision>
  </link>
  <joint name="right_joint8" type="prismatic">
    <origin xyz="0.08657 -0.0249 -0.00024366"/>
    <parent link="right_link6"/>
    <child link="right_link8"/>
    <axis xyz="0 -1 0"/>
    <limit effort="100" lower="0" upper="0.044" velocity="5"/>
    <mimic joint="right_gripper_joint" multiplier="1" offset="0"/>
  </joint>
  <link name="right_gripper_center"/>
  <joint name="right_gripper_center_fixed" type="fixed">
    <parent link="right_link6"/>
    <child link="right_gripper_center"/>
    <origin xyz="0.145 0 0"/>
  </joint>
  <link name="right_left_pad"/>
  <joint name="right_left_pad_joint" type="fixed">
    <parent link="right_link7"/>
    <child link="right_left_pad"/>
    <origin xyz="0.05843 -0.0249 0"/>
  </joint>
  <link name="right_right_pad"/>
  <joint name="right_right_pad_joint" type="fixed">
    <parent link="right_link8"/>
    <child link="right_right_pad"/>
    <origin xyz="0.05843 0.0249 0"/>
  </joint>
  <link name="right_camera_support">
    <visual>
      <geometry>
        <mesh filename="package://arx5_description/meshes/camera_stand/stand_d435.obj"/>
      </geometry>
    </visual>
  </link>
  <joint name="right_camera_support_fixed" type="fixed">
    <parent link="right_link6"/>
    <child link="right_camera_support"/>
    <origin xyz="0.045 0 0.021"/>
  </joint>
  <link name="right_camera">
    <visual>
      <geometry>
        <mesh filename="package://sensor_models/meshes/d435/d435.obj"/>
      </geometry>
    </visual>
  </link>
  <joint name="right_camera_fixed" type="fixed">
    <origin xyz="0.03 0 0.034113"/>
    <parent link="right_camera_support"/>
    <child link="right_camera"/>
  </joint>
</robot>
