<?xml version="1.0" ?>
<!-- =================================================================================== -->
<!-- |    This document was autogenerated by xacro from robot.xacro                    | -->
<!-- |    EDITING THIS FILE BY HAND IS NOT RECOMMENDED                                 | -->
<!-- =================================================================================== -->
<robot name="arx_lift">
  <link name="left_base_link">
    <inertial>
      <origin xyz="-3.0001E-05 3.0589E-05 0.027324"/>
      <mass value="0.43995"/>
      <inertia ixx="0.00017" ixy="0.00000" ixz="0.00000" iyy="0.00017" iyz="0.00000" izz="0.00016"/>
    </inertial>
    <visual>
      <geometry>
        <mesh filename="package://arx5_description/meshes/x5/base_link.obj"/>
      </geometry>
    </visual>
    <collision>
      <geometry>
        <mesh filename="package://arx5_description/meshes/x5/base_link.obj"/>
      </geometry>
    </collision>
  </link>
  <link name="left_link1">
    <inertial>
      <origin xyz="0.0054231 -0.0080289 0.017086"/>
      <mass value="0.066982"/>
      <inertia ixx="0.00008" ixy="0.00000" ixz="0.00001" iyy="0.00003" iyz="0.00000" izz="0.00008"/>
    </inertial>
    <visual>
      <geometry>
        <mesh filename="package://arx5_description/meshes/x5/link1.obj"/>
      </geometry>
    </visual>
    <collision>
      <geometry>
        <mesh filename="package://arx5_description/meshes/x5/link1.obj"/>
      </geometry>
    </collision>
  </link>
  <joint name="left_joint1" type="revolute">
    <origin xyz="0 0 0.0605"/>
    <parent link="left_base_link"/>
    <child link="left_link1"/>
    <axis xyz="0 0 1"/>
    <limit effort="100" lower="-2.87" upper="3.14" velocity="5"/>
  </joint>
  <link name="left_link2">
    <inertial>
      <origin xyz="-0.13237 0.0020852 0.00010549"/>
      <mass value="1.0795"/>
      <inertia ixx="0.00051" ixy="0.00001" ixz="-0.00004" iyy="0.01599" iyz="0.00000" izz="0.01605"/>
    </inertial>
    <visual>
      <geometry>
        <mesh filename="package://arx5_description/meshes/x5/link2.obj"/>
      </geometry>
    </visual>
    <collision>
      <geometry>
        <mesh filename="package://arx5_description/meshes/x5/link2.obj"/>
      </geometry>
    </collision>
  </link>
  <joint name="left_joint2" type="revolute">
    <origin xyz="0.02 0 0.04"/>
    <parent link="left_link1"/>
    <child link="left_link2"/>
    <axis xyz="0 1 0"/>
    <limit effort="100" lower="0" upper="3.66" velocity="5"/>
  </joint>
  <link name="left_link3">
    <inertial>
      <origin xyz="0.18531 0.00068376 -0.051638"/>
      <mass value="0.54534"/>
      <inertia ixx="0.00036" ixy="-0.00003" ixz="-0.00039" iyy="0.00423" iyz="0.00001" izz="0.00420"/>
    </inertial>
    <visual>
      <geometry>
        <mesh filename="package://arx5_description/meshes/x5/link3.obj"/>
      </geometry>
    </visual>
    <collision>
      <geometry>
        <mesh filename="package://arx5_description/meshes/x5/link3.obj"/>
      </geometry>
    </collision>
  </link>
  <joint name="left_joint3" type="revolute">
    <origin rpy="3.1416 0 0" xyz="-0.264 0 0"/>
    <parent link="left_link2"/>
    <child link="left_link3"/>
    <axis xyz="0 1 0"/>
    <limit effort="100" lower="0" upper="3.14" velocity="5"/>
  </joint>
  <link name="left_link4">
    <inertial>
      <origin xyz="0.040231 0.0044807 -0.035335"/>
      <mass value="0.11714"/>
      <inertia ixx="0.00019" ixy="-0.00002" ixz="-0.00009" iyy="0.00023" iyz="0.00002" izz="0.00014"/>
    </inertial>
    <visual>
      <geometry>
        <mesh filename="package://arx5_description/meshes/x5/link4.obj"/>
      </geometry>
    </visual>
    <collision>
      <geometry>
        <mesh filename="package://arx5_description/meshes/x5/link4.obj"/>
      </geometry>
    </collision>
  </link>
  <joint name="left_joint4" type="revolute">
    <origin xyz="0.245 0 -0.056"/>
    <parent link="left_link3"/>
    <child link="left_link4"/>
    <axis xyz="0 1 0"/>
    <limit effort="100" lower="-1.57" upper="1.57" velocity="5"/>
  </joint>
  <link name="left_link5">
    <inertial>
      <origin xyz="0.003612 -1.5455E-05 0.055214"/>
      <mass value="0.63488"/>
      <inertia ixx="0.00083" ixy="0.00000" ixz="0.00007" iyy="0.00082" iyz="0.00000" izz="0.00026"/>
    </inertial>
    <visual>
      <origin xyz="0.0037 0 0"/>
      <geometry>
        <mesh filename="package://arx5_description/meshes/x5/link5.obj"/>
      </geometry>
    </visual>
    <collision>
      <geometry>
        <mesh filename="package://arx5_description/meshes/x5/link5.obj"/>
      </geometry>
    </collision>
  </link>
  <joint name="left_joint5" type="revolute">
    <origin xyz="0.06775 0.0005 -0.0865"/>
    <parent link="left_link4"/>
    <child link="left_link5"/>
    <axis xyz="0 0 1"/>
    <limit effort="100" lower="-1.57" upper="1.57" velocity="5"/>
  </joint>
  <link name="left_link6">
    <inertial>
      <origin xyz="0.041697 2.4368E-05 0.00014464"/>
      <mass value="0.44089"/>
      <inertia ixx="0.00038" ixy="0.00000" ixz="0.00000" iyy="0.00028" iyz="0.00000" izz="0.00050"/>
    </inertial>
    <visual>
      <geometry>
        <mesh filename="package://arx5_description/meshes/x5/link6.obj"/>
      </geometry>
    </visual>
    <collision>
      <geometry>
        <mesh filename="package://arx5_description/meshes/x5/link6.obj"/>
      </geometry>
    </collision>
  </link>
  <joint name="left_joint6" type="revolute">
    <origin rpy="-3.1416 0 0" xyz="0.02895 0 0.0865"/>
    <parent link="left_link5"/>
    <child link="left_link6"/>
    <axis xyz="1 0 0"/>
    <limit effort="100" lower="-1.57" upper="1.57" velocity="5"/>
  </joint>
  <link name="left_link7">
    <inertial>
      <origin xyz="-0.00035522 -0.007827 -0.0029883"/>
      <mass value="0.064798"/>
      <inertia ixx="0.00002" ixy="0.00000" ixz="0.00000" iyy="0.00003" iyz="0.00000" izz="0.00003"/>
    </inertial>
    <visual>
      <geometry>
        <mesh filename="package://arx5_description/meshes/x5/link7.obj"/>
      </geometry>
    </visual>
    <collision>
      <geometry>
        <mesh filename="package://arx5_description/meshes/x5/link7.obj"/>
      </geometry>
    </collision>
  </link>
  <joint name="left_gripper_joint" type="prismatic">
    <origin xyz="0.08657 0.024896 -0.0002436"/>
    <parent link="left_link6"/>
    <child link="left_link7"/>
    <axis xyz="0 1 0"/>
    <limit effort="100" lower="0" upper="0.044" velocity="5"/>
  </joint>
  <link name="left_link8">
    <inertial>
      <origin xyz="-0.00035522 0.0078277 0.0024201"/>
      <mass value="0.064798"/>
      <inertia ixx="0.00002" ixy="0.00000" ixz="0.00000" iyy="0.00003" iyz="0.00000" izz="0.00003"/>
    </inertial>
    <visual>
      <geometry>
        <mesh filename="package://arx5_description/meshes/x5/link8.obj"/>
      </geometry>
    </visual>
    <collision>
      <geometry>
        <mesh filename="package://arx5_description/meshes/x5/link8.obj"/>
      </geometry>
    </collision>
  </link>
  <joint name="left_joint8" type="prismatic">
    <origin xyz="0.08657 -0.0249 -0.00024366"/>
    <parent link="left_link6"/>
    <child link="left_link8"/>
    <axis xyz="0 -1 0"/>
    <limit effort="100" lower="0" upper="0.044" velocity="5"/>
    <mimic joint="left_gripper_joint" multiplier="1" offset="0"/>
  </joint>
  <link name="left_gripper_center"/>
  <joint name="left_gripper_center_fixed" type="fixed">
    <parent link="left_link6"/>
    <child link="left_gripper_center"/>
    <origin xyz="0.145 0 0"/>
  </joint>
  <link name="left_left_pad"/>
  <joint name="left_left_pad_joint" type="fixed">
    <parent link="left_link7"/>
    <child link="left_left_pad"/>
    <origin xyz="0.05843 -0.0249 0"/>
  </joint>
  <link name="left_right_pad"/>
  <joint name="left_right_pad_joint" type="fixed">
    <parent link="left_link8"/>
    <child link="left_right_pad"/>
    <origin xyz="0.05843 0.0249 0"/>
  </joint>
  <link name="left_camera_support">
    <visual>
      <geometry>
        <mesh filename="package://arx5_description/meshes/camera_stand/stand_d405.obj"/>
      </geometry>
    </visual>
  </link>
  <joint name="left_camera_support_fixed" type="fixed">
    <parent link="left_link6"/>
    <child link="left_camera_support"/>
    <origin xyz="0.045 0 0.021"/>
  </joint>
  <link name="left_camera">
    <visual>
      <geometry>
        <mesh filename="package://sensor_models/meshes/d405/d405.obj"/>
      </geometry>
    </visual>
  </link>
  <joint name="left_camera_fixed" type="fixed">
    <origin rpy="0 0.523 0" xyz="0.0385 0 0.0475"/>
    <parent link="left_camera_support"/>
    <child link="left_camera"/>
  </joint>
  <link name="right_base_link">
    <inertial>
      <origin xyz="-3.0001E-05 3.0589E-05 0.027324"/>
      <mass value="0.43995"/>
      <inertia ixx="0.00017" ixy="0.00000" ixz="0.00000" iyy="0.00017" iyz="0.00000" izz="0.00016"/>
    </inertial>
    <visual>
      <geometry>
        <mesh filename="package://arx5_description/meshes/x5/base_link.obj"/>
      </geometry>
    </visual>
    <collision>
      <geometry>
        <mesh filename="package://arx5_description/meshes/x5/base_link.obj"/>
      </geometry>
    </collision>
  </link>
  <link name="right_link1">
    <inertial>
      <origin xyz="0.0054231 -0.0080289 0.017086"/>
      <mass value="0.066982"/>
      <inertia ixx="0.00008" ixy="0.00000" ixz="0.00001" iyy="0.00003" iyz="0.00000" izz="0.00008"/>
    </inertial>
    <visual>
      <geometry>
        <mesh filename="package://arx5_description/meshes/x5/link1.obj"/>
      </geometry>
    </visual>
    <collision>
      <geometry>
        <mesh filename="package://arx5_description/meshes/x5/link1.obj"/>
      </geometry>
    </collision>
  </link>
  <joint name="right_joint1" type="revolute">
    <origin xyz="0 0 0.0605"/>
    <parent link="right_base_link"/>
    <child link="right_link1"/>
    <axis xyz="0 0 1"/>
    <limit effort="100" lower="-2.87" upper="3.14" velocity="5"/>
  </joint>
  <link name="right_link2">
    <inertial>
      <origin xyz="-0.13237 0.0020852 0.00010549"/>
      <mass value="1.0795"/>
      <inertia ixx="0.00051" ixy="0.00001" ixz="-0.00004" iyy="0.01599" iyz="0.00000" izz="0.01605"/>
    </inertial>
    <visual>
      <geometry>
        <mesh filename="package://arx5_description/meshes/x5/link2.obj"/>
      </geometry>
    </visual>
    <collision>
      <geometry>
        <mesh filename="package://arx5_description/meshes/x5/link2.obj"/>
      </geometry>
    </collision>
  </link>
  <joint name="right_joint2" type="revolute">
    <origin xyz="0.02 0 0.04"/>
    <parent link="right_link1"/>
    <child link="right_link2"/>
    <axis xyz="0 1 0"/>
    <limit effort="100" lower="0" upper="3.66" velocity="5"/>
  </joint>
  <link name="right_link3">
    <inertial>
      <origin xyz="0.18531 0.00068376 -0.051638"/>
      <mass value="0.54534"/>
      <inertia ixx="0.00036" ixy="-0.00003" ixz="-0.00039" iyy="0.00423" iyz="0.00001" izz="0.00420"/>
    </inertial>
    <visual>
      <geometry>
        <mesh filename="package://arx5_description/meshes/x5/link3.obj"/>
      </geometry>
    </visual>
    <collision>
      <geometry>
        <mesh filename="package://arx5_description/meshes/x5/link3.obj"/>
      </geometry>
    </collision>
  </link>
  <joint name="right_joint3" type="revolute">
    <origin rpy="3.1416 0 0" xyz="-0.264 0 0"/>
    <parent link="right_link2"/>
    <child link="right_link3"/>
    <axis xyz="0 1 0"/>
    <limit effort="100" lower="0" upper="3.14" velocity="5"/>
  </joint>
  <link name="right_link4">
    <inertial>
      <origin xyz="0.040231 0.0044807 -0.035335"/>
      <mass value="0.11714"/>
      <inertia ixx="0.00019" ixy="-0.00002" ixz="-0.00009" iyy="0.00023" iyz="0.00002" izz="0.00014"/>
    </inertial>
    <visual>
      <geometry>
        <mesh filename="package://arx5_description/meshes/x5/link4.obj"/>
      </geometry>
    </visual>
    <collision>
      <geometry>
        <mesh filename="package://arx5_description/meshes/x5/link4.obj"/>
      </geometry>
    </collision>
  </link>
  <joint name="right_joint4" type="revolute">
    <origin xyz="0.245 0 -0.056"/>
    <parent link="right_link3"/>
    <child link="right_link4"/>
    <axis xyz="0 1 0"/>
    <limit effort="100" lower="-1.57" upper="1.57" velocity="5"/>
  </joint>
  <link name="right_link5">
    <inertial>
      <origin xyz="0.003612 -1.5455E-05 0.055214"/>
      <mass value="0.63488"/>
      <inertia ixx="0.00083" ixy="0.00000" ixz="0.00007" iyy="0.00082" iyz="0.00000" izz="0.00026"/>
    </inertial>
    <visual>
      <origin xyz="0.0037 0 0"/>
      <geometry>
        <mesh filename="package://arx5_description/meshes/x5/link5.obj"/>
      </geometry>
    </visual>
    <collision>
      <geometry>
        <mesh filename="package://arx5_description/meshes/x5/link5.obj"/>
      </geometry>
    </collision>
  </link>
  <joint name="right_joint5" type="revolute">
    <origin xyz="0.06775 0.0005 -0.0865"/>
    <parent link="right_link4"/>
    <child link="right_link5"/>
    <axis xyz="0 0 1"/>
    <limit effort="100" lower="-1.57" upper="1.57" velocity="5"/>
  </joint>
  <link name="right_link6">
    <inertial>
      <origin xyz="0.041697 2.4368E-05 0.00014464"/>
      <mass value="0.44089"/>
      <inertia ixx="0.00038" ixy="0.00000" ixz="0.00000" iyy="0.00028" iyz="0.00000" izz="0.00050"/>
    </inertial>
    <visual>
      <geometry>
        <mesh filename="package://arx5_description/meshes/x5/link6.obj"/>
      </geometry>
    </visual>
    <collision>
      <geometry>
        <mesh filename="package://arx5_description/meshes/x5/link6.obj"/>
      </geometry>
    </collision>
  </link>
  <joint name="right_joint6" type="revolute">
    <origin rpy="-3.1416 0 0" xyz="0.02895 0 0.0865"/>
    <parent link="right_link5"/>
    <child link="right_link6"/>
    <axis xyz="1 0 0"/>
    <limit effort="100" lower="-1.57" upper="1.57" velocity="5"/>
  </joint>
  <link name="right_link7">
    <inertial>
      <origin xyz="-0.00035522 -0.007827 -0.0029883"/>
      <mass value="0.064798"/>
      <inertia ixx="0.00002" ixy="0.00000" ixz="0.00000" iyy="0.00003" iyz="0.00000" izz="0.00003"/>
    </inertial>
    <visual>
      <geometry>
        <mesh filename="package://arx5_description/meshes/x5/link7.obj"/>
      </geometry>
    </visual>
    <collision>
      <geometry>
        <mesh filename="package://arx5_description/meshes/x5/link7.obj"/>
      </geometry>
    </collision>
  </link>
  <joint name="right_gripper_joint" type="prismatic">
    <origin xyz="0.08657 0.024896 -0.0002436"/>
    <parent link="right_link6"/>
    <child link="right_link7"/>
    <axis xyz="0 1 0"/>
    <limit effort="100" lower="0" upper="0.044" velocity="5"/>
  </joint>
  <link name="right_link8">
    <inertial>
      <origin xyz="-0.00035522 0.0078277 0.0024201"/>
      <mass value="0.064798"/>
      <inertia ixx="0.00002" ixy="0.00000" ixz="0.00000" iyy="0.00003" iyz="0.00000" izz="0.00003"/>
    </inertial>
    <visual>
      <geometry>
        <mesh filename="package://arx5_description/meshes/x5/link8.obj"/>
      </geometry>
    </visual>
    <collision>
      <geometry>
        <mesh filename="package://arx5_description/meshes/x5/link8.obj"/>
      </geometry>
    </collision>
  </link>
  <joint name="right_joint8" type="prismatic">
    <origin xyz="0.08657 -0.0249 -0.00024366"/>
    <parent link="right_link6"/>
    <child link="right_link8"/>
    <axis xyz="0 -1 0"/>
    <limit effort="100" lower="0" upper="0.044" velocity="5"/>
    <mimic joint="right_gripper_joint" multiplier="1" offset="0"/>
  </joint>
  <link name="right_gripper_center"/>
  <joint name="right_gripper_center_fixed" type="fixed">
    <parent link="right_link6"/>
    <child link="right_gripper_center"/>
    <origin xyz="0.145 0 0"/>
  </joint>
  <link name="right_left_pad"/>
  <joint name="right_left_pad_joint" type="fixed">
    <parent link="right_link7"/>
    <child link="right_left_pad"/>
    <origin xyz="0.05843 -0.0249 0"/>
  </joint>
  <link name="right_right_pad"/>
  <joint name="right_right_pad_joint" type="fixed">
    <parent link="right_link8"/>
    <child link="right_right_pad"/>
    <origin xyz="0.05843 0.0249 0"/>
  </joint>
  <link name="right_camera_support">
    <visual>
      <geometry>
        <mesh filename="package://arx5_description/meshes/camera_stand/stand_d405.obj"/>
      </geometry>
    </visual>
  </link>
  <joint name="right_camera_support_fixed" type="fixed">
    <parent link="right_link6"/>
    <child link="right_camera_support"/>
    <origin xyz="0.045 0 0.021"/>
  </joint>
  <link name="right_camera">
    <visual>
      <geometry>
        <mesh filename="package://sensor_models/meshes/d405/d405.obj"/>
      </geometry>
    </visual>
  </link>
  <joint name="right_camera_fixed" type="fixed">
    <origin rpy="0 0.523 0" xyz="0.0385 0 0.0475"/>
    <parent link="right_camera_support"/>
    <child link="right_camera"/>
  </joint>
  <link name="base_link">
    <inertial>
      <origin xyz="0.015300075250394498 -0.0039712791148939055 0.21685783167580347"/>
      <mass value="67.7696558151508"/>
      <inertia ixx="7.900786" ixy="-0.021075" ixz="0.25289" iyy="8.068966" iyz="0.12408" izz="2.254894"/>
    </inertial>
    <visual>
      <geometry>
        <mesh filename="package://arx_lift_description/meshes/base/base_link.obj"/>
      </geometry>
    </visual>
    <collision>
      <geometry>
        <mesh filename="package://arx_lift_description/meshes/base/base_link.obj"/>
      </geometry>
    </collision>
  </link>
  <!-- 轮子链接 -->
  <link name="wheel_1">
    <inertial>
      <origin xyz="0.0026089441594678298 -1.3189703553351252e-07 2.8695680726054107e-07"/>
      <mass value="4.24803000494366"/>
      <inertia ixx="0.012235" ixy="-0.0" ixz="0.0" iyy="0.006629" iyz="0.0" izz="0.006629"/>
    </inertial>
    <visual>
      <geometry>
        <mesh filename="package://arx_lift_description/meshes/base/wheel.obj"/>
      </geometry>
    </visual>
    <collision>
      <geometry>
        <mesh filename="package://arx_lift_description/meshes/base/wheel.obj"/>
      </geometry>
    </collision>
  </link>
  <!-- 轮子链接 -->
  <link name="wheel_2">
    <inertial>
      <origin xyz="0.0026089441594678298 -1.3189703553351252e-07 2.8695680726054107e-07"/>
      <mass value="4.24803000494366"/>
      <inertia ixx="0.012235" ixy="-0.0" ixz="0.0" iyy="0.006629" iyz="0.0" izz="0.006629"/>
    </inertial>
    <visual>
      <geometry>
        <mesh filename="package://arx_lift_description/meshes/base/wheel.obj"/>
      </geometry>
    </visual>
    <collision>
      <geometry>
        <mesh filename="package://arx_lift_description/meshes/base/wheel.obj"/>
      </geometry>
    </collision>
  </link>
  <!-- 轮子链接 -->
  <link name="wheel_3">
    <inertial>
      <origin xyz="0.0026089441594678298 -1.3189703553351252e-07 2.8695680726054107e-07"/>
      <mass value="4.24803000494366"/>
      <inertia ixx="0.012235" ixy="-0.0" ixz="0.0" iyy="0.006629" iyz="0.0" izz="0.006629"/>
    </inertial>
    <visual>
      <geometry>
        <mesh filename="package://arx_lift_description/meshes/base/wheel.obj"/>
      </geometry>
    </visual>
    <collision>
      <geometry>
        <mesh filename="package://arx_lift_description/meshes/base/wheel.obj"/>
      </geometry>
    </collision>
  </link>
  <!-- 轮子关节定义 -->
  <joint name="wheel1_joint" type="fixed">
    <origin rpy="0.0 0.0 -2.0943951023931953" xyz="0.182349 0.315838 0.03"/>
    <parent link="base_link"/>
    <child link="wheel_1"/>
  </joint>
  <joint name="wheel2_joint" type="fixed">
    <origin rpy="0.0 0.0 2.0943951023931953" xyz="0.182349 -0.315838 0.03"/>
    <parent link="base_link"/>
    <child link="wheel_2"/>
  </joint>
  <joint name="wheel3_joint" type="fixed">
    <origin xyz="-0.364699 0.0 0.03"/>
    <parent link="base_link"/>
    <child link="wheel_3"/>
  </joint>
  <link name="lift_link">
    <inertial>
      <origin xyz="0.13956899916103924 0 0.07323798891482189"/>
      <mass value="17.38744536890084"/>
      <inertia ixx="0.187458" ixy="-0.000206" ixz="0.023942" iyy="0.178157" iyz="-0.000153" izz="0.29708"/>
    </inertial>
    <visual>
      <geometry>
        <mesh filename="package://arx_lift_description/meshes/body/lift.obj"/>
      </geometry>
    </visual>
    <collision>
      <geometry>
        <mesh filename="package://arx_lift_description/meshes/body/lift.obj"/>
      </geometry>
    </collision>
  </link>
  <joint name="lift_joint" type="prismatic">
    <origin xyz="-0.032 0 0.233"/>
    <parent link="base_link"/>
    <child link="lift_link"/>
    <axis xyz="0.0 0.0 1.0"/>
    <limit effort="1000" lower="0.0" upper="0.86" velocity="100"/>
  </joint>
  <link name="h_base_link">
    <inertial>
      <origin xyz="-0.0020743076738515215 0 0.024619861716967787"/>
      <mass value="0.9930933606993821"/>
      <inertia ixx="0.000391" ixy="-0.0" ixz="1.7e-05" iyy="0.000452" iyz="0.0" izz="0.000532"/>
    </inertial>
    <visual>
      <geometry>
        <mesh filename="package://arx_lift_description/meshes/body/h_base.obj"/>
      </geometry>
    </visual>
    <collision>
      <geometry>
        <mesh filename="package://arx_lift_description/meshes/body/h_base.obj"/>
      </geometry>
    </collision>
  </link>
  <link name="head_link1">
    <inertial>
      <origin xyz="-1.2166451790474E-08 0.000155101086835956 0.0414775143344981"/>
      <mass value="0.429406588376073"/>
      <inertia ixx="0.00027" ixy="0.00000" ixz="0.00000" iyy="0.00026" iyz="-0.00001" izz="0.00018"/>
    </inertial>
    <visual>
      <geometry>
        <mesh filename="package://arx_lift_description/meshes/body/neck.obj"/>
      </geometry>
    </visual>
    <collision>
      <geometry>
        <mesh filename="package://arx_lift_description/meshes/body/neck.obj"/>
      </geometry>
    </collision>
  </link>
  <link name="head_link2">
    <inertial>
      <origin xyz="0.0145474612596931 0.0229595215513494 0.0787914285814235"/>
      <mass value="1.54420437039843"/>
      <inertia ixx="0.00576" ixy="-0.00007" ixz="0.00018" iyy="0.00477" iyz="0.00015" izz="0.00768"/>
    </inertial>
    <visual>
      <geometry>
        <mesh filename="package://arx_lift_description/meshes/body/head.obj"/>
      </geometry>
    </visual>
    <collision>
      <geometry>
        <mesh filename="package://arx_lift_description/meshes/body/head.obj"/>
      </geometry>
    </collision>
  </link>
  <joint name="head_joint1" type="continuous">
    <origin xyz="0.0 0.0 0.046"/>
    <parent link="h_base_link"/>
    <child link="head_link1"/>
    <axis xyz="0.0 0.0 1.0"/>
    <limit effort="100" lower="-1.5707963267948966" upper="1.5707963267948966" velocity="100"/>
  </joint>
  <joint name="head_joint2" type="continuous">
    <origin xyz="0.0 -0.025 0.049"/>
    <parent link="head_link1"/>
    <child link="head_link2"/>
    <axis xyz="0.0 -1.0 0.0"/>
    <limit effort="100" lower="-0.7853981633974483" upper="0.7853981633974483" velocity="100"/>
  </joint>
  <joint name="h_fixed" type="fixed">
    <parent link="lift_link"/>
    <child link="h_base_link"/>
    <origin xyz="0.258786 0 0.220008"/>
  </joint>
  <link name="head_camera">
    <visual>
      <geometry>
        <mesh filename="package://sensor_models/meshes/d405/d405.obj"/>
      </geometry>
    </visual>
  </link>
  <joint name="head_camera_joint" type="fixed">
    <origin xyz="0.095 0.025 0.06"/>
    <parent link="head_link2"/>
    <child link="head_camera"/>
  </joint>
  <joint name="arm_left_fixed" type="fixed">
    <parent link="lift_link"/>
    <child link="left_base_link"/>
    <origin xyz="0.208 0.25000 0.092"/>
  </joint>
  <joint name="arm_right_fixed" type="fixed">
    <parent link="lift_link"/>
    <child link="right_base_link"/>
    <origin xyz="0.208 -0.25000 0.092"/>
  </joint>
</robot>
