<?xml version="1.0" ?>
<!-- =================================================================================== -->
<!-- |    This document was autogenerated by xacro from robot.xacro                    | -->
<!-- |    EDITING THIS FILE BY HAND IS NOT RECOMMENDED                                 | -->
<!-- =================================================================================== -->
<!-- This URDF was automatically created by SolidWorks to URDF Exporter! Originally created by Stephen Brawner (brawner@gmail.com)
     Commit Version: 1.6.0-4-g7f85cfe  Build Version: 1.6.7995.38578
     For more information, please see http://wiki.ros.org/sw_urdf_exporter -->
<robot name="DexForce W1">
  <link name="base_link">
    <inertial>
      <origin xyz="-6.9481412e-03 -2.8983362e-03  1.0943608e-01"/>
      <mass value="51.3211"/>
      <inertia ixx="1.6616493e+4" ixy="-2.2400581e+3" ixz="0.0" iyy="-2.2400581e+3" iyz="1.6616324e+4" izz="0.0"/>
    </inertial>
    <visual>
      <geometry>
        <mesh filename="package://dexforce_w1_description/meshes/Visual/Common/base_link.glb"/>
      </geometry>
    </visual>
    <collision>
      <geometry>
        <mesh filename="package://dexforce_w1_description/meshes/Collision/Common/base_link.obj"/>
      </geometry>
    </collision>
  </link>
  <link name="wheel_left">
    <inertial>
      <origin xyz="1.29654835478998E-09 -0.0388109425454037 1.46411155282911E-07"/>
      <mass value="1.81841495723996"/>
      <inertia ixx="0.00458785167524735" ixy="2.63111479143607E-11" ixz="2.02429770259449E-10" iyy="0.00846145621331285" iyz="7.59817806948718E-11" izz="0.00458785310793277"/>
    </inertial>
  </link>
  <link name="wheel_right">
    <inertial>
      <origin xyz="-1.29654938174628E-09 0.0388109425454037 1.46411155255155E-07"/>
      <mass value="1.81841495723996"/>
      <inertia ixx="0.00458785167524735" ixy="2.63111168444812E-11" ixz="-2.02429769062992E-10" iyy="0.00846145621331285" iyz="-7.59817809326904E-11" izz="0.00458785310793277"/>
    </inertial>
  </link>
  <joint name="WHEEL_LEFT" type="fixed">
    <origin xyz="0 0.2539 0.053"/>
    <parent link="base_link"/>
    <child link="wheel_left"/>
    <axis xyz="0 1 0"/>
  </joint>
  <joint name="WHEEL_RIGHT" type="fixed">
    <origin xyz="0 -0.2539 0.053"/>
    <parent link="base_link"/>
    <child link="wheel_right"/>
    <axis xyz="0 -1 0"/>
  </joint>
  <link name="ankle">
    <inertial>
      <origin xyz="8.0372418e-02 -8.2420334e-06  2.0806937e-02"/>
      <mass value="6.271734"/>
      <inertia ixx="4.0e-02" ixy="-3.6858529e-07" ixz="8.4378843e-03" iyy="1.0944388e-01" iyz="-3.1525774e-03" izz="7.0360182e-02"/>
    </inertial>
    <visual>
      <geometry>
        <mesh filename="package://dexforce_w1_description/meshes/Visual/Common/Torso/torso1.glb"/>
      </geometry>
    </visual>
    <collision>
      <geometry>
        <mesh filename="package://dexforce_w1_description/meshes/Collision/Common/Torso/torso1.obj"/>
      </geometry>
    </collision>
  </link>
  <link name="knee">
    <inertial>
      <origin xyz="7.4144729e-02  3.5641805e-05  5.7481550e-03"/>
      <mass value="5.7732119"/>
      <inertia ixx="2.0e-02" ixy="-3.6600899e-03" ixz="2.7064201e-03" iyy="8.0129350e-02" iyz="-1.8650759e-03" izz="6.4174708e-02"/>
    </inertial>
    <visual>
      <geometry>
        <mesh filename="package://dexforce_w1_description/meshes/Visual/Common/Torso/torso2.glb"/>
      </geometry>
    </visual>
    <collision>
      <geometry>
        <mesh filename="package://dexforce_w1_description/meshes/Collision/Common/Torso/torso2.obj"/>
      </geometry>
    </collision>
  </link>
  <link name="buttock">
    <inertial>
      <origin xyz="5.2490838e-02  1.2635673e-05  9.2446495e-03"/>
      <mass value="7.4072832"/>
      <inertia ixx="2.0057819e-02" ixy="3.3385889e-06" ixz="3.6102235e-03" iyy="4.1292505e-02" iyz="3.9554651e-06" izz="3.5409712e-02"/>
    </inertial>
    <visual>
      <geometry>
        <mesh filename="package://dexforce_w1_description/meshes/Visual/Common/Torso/torso3.glb"/>
      </geometry>
    </visual>
    <collision>
      <geometry>
        <mesh filename="package://dexforce_w1_description/meshes/Collision/Common/Torso/torso3.obj"/>
      </geometry>
    </collision>
  </link>
  <link name="waist">
    <inertial>
      <origin xyz="6.4016818e-03  4.8188781e-04  2.0011730e-01"/>
      <mass value="6.40803"/>
      <inertia ixx="9.4768963e-02" ixy="3.6070706e-04" ixz="1.5765521e-03" iyy="7.8791635e-02" iyz="-7.5017650e-03" izz="3.8690356e-02"/>
    </inertial>
    <visual>
      <geometry>
        <mesh filename="package://dexforce_w1_description/meshes/Visual/Common/Torso/torso4.glb"/>
      </geometry>
    </visual>
    <collision>
      <geometry>
        <mesh filename="package://dexforce_w1_description/meshes/Collision/Common/Torso/torso4.obj"/>
      </geometry>
    </collision>
  </link>
  <joint name="body_joint1" type="revolute">
    <origin rpy="1.5707963267948966 0 0" xyz="0 0 0.292"/>
    <parent link="base_link"/>
    <child link="ankle"/>
    <axis xyz="0 0 -1"/>
    <limit effort="100" lower="-1.5707963267948966" upper="1.5707963267948966" velocity="0.8726646259971648"/>
  </joint>
  <joint name="body_joint2" type="revolute">
    <origin xyz="0 0.34 0"/>
    <parent link="ankle"/>
    <child link="knee"/>
    <axis xyz="0 0 -1"/>
    <limit effort="100" lower="-2.705260340591211" upper="2.705260340591211" velocity="1.3089969389957472"/>
  </joint>
  <joint name="body_joint3" type="revolute">
    <origin xyz="0 0.34 0"/>
    <parent link="knee"/>
    <child link="buttock"/>
    <axis xyz="0 0 -1"/>
    <limit effort="100" lower="-1.9198621771937625" upper="1.5707963267948966" velocity="0.8726646259971648"/>
  </joint>
  <joint name="body_joint4" type="revolute">
    <origin rpy="-1.5707963267948966 0 0" xyz="0 0.1578 0"/>
    <parent link="buttock"/>
    <child link="waist"/>
    <axis xyz="0 0 1"/>
    <limit effort="100" lower="-2.9670597283903604" upper="2.9670597283903604" velocity="1.3089969389957472"/>
  </joint>
  <link name="waist_to_neck_connector"/>
  <link name="neck_base"/>
  <link name="neck1">
    <inertial>
      <origin xyz="8.0771079e-05 -4.9617728e-03  5.2251935e-02 "/>
      <mass value="0.9607041"/>
      <inertia ixx="1.76988687535663E-05" ixy="-3.29843265585722E-14" ixz="1.12004314355796E-12" iyy="1.698812924773E-05" iyz="4.19769754584448E-06" izz="1.42153718545556E-05"/>
    </inertial>
    <visual>
      <geometry>
        <mesh filename="package://dexforce_w1_description/meshes/Visual/Common/Head/head1.glb"/>
      </geometry>
    </visual>
    <collision>
      <geometry>
        <mesh filename="package://dexforce_w1_description/meshes/Collision/Common/Head/head1.obj"/>
      </geometry>
    </collision>
  </link>
  <link name="neck2">
    <inertial>
      <origin xyz="3.5749562e-02  3.9029998e-02  5.9305750e-03"/>
      <mass value="0.76222648"/>
      <inertia ixx="0.00119162799314456" ixy="0.000139409177964968" ixz="-1.74009535043774E-06" iyy="0.00102931058067242" iyz="-1.913284242482E-06" izz="0.00092225648400233"/>
    </inertial>
    <visual>
      <geometry>
        <mesh filename="package://dexforce_w1_description/meshes/Visual/Common/Head/head2.glb"/>
      </geometry>
    </visual>
    <collision>
      <geometry>
        <mesh filename="package://dexforce_w1_description/meshes/Collision/Common/Head/head2.obj"/>
      </geometry>
    </collision>
  </link>
  <link name="eyes"/>
  <joint name="WAIST_TO_NECK_CONNECTOR" type="fixed">
    <origin xyz="0 0 0.308"/>
    <parent link="waist"/>
    <child link="waist_to_neck_connector"/>
  </joint>
  <joint name="NECK_BASE" type="fixed">
    <parent link="waist_to_neck_connector"/>
    <child link="neck_base"/>
  </joint>
  <joint name="head_joint1" type="revolute">
    <parent link="neck_base"/>
    <child link="neck1"/>
    <axis xyz="0 0 1"/>
    <limit effort="50" lower="-1.5707963267948966" upper="1.5707963267948966" velocity="0.8726646259971648"/>
  </joint>
  <joint name="head_joint2" type="revolute">
    <origin rpy="-1.5707963267948966 0 0" xyz="0 0 0.081"/>
    <parent link="neck1"/>
    <child link="neck2"/>
    <axis xyz="0 0 -1"/>
    <limit effort="50" lower="-0.7853981633974483" upper="0.4363323129985824" velocity="0.8726646259971648"/>
  </joint>
  <joint name="EYES" type="fixed">
    <origin rpy="2.879 1.5708 0.0" xyz="0.085 -0.051 0.0"/>
    <parent link="neck2"/>
    <child link="eyes"/>
  </joint>
  <link name="waist_to_left_arm_connector"/>
  <link name="left_arm_base"/>
  <!-- J1 -->
  <link name="left_j1">
    <inertial>
      <origin xyz="-2.2097730e-02  6.8020948e-03  7.8858121e-02"/>
      <mass value="1.3497532"/>
      <inertia ixx="1.4265178e-03" ixy="6.7924025e-05" ixz="2.0743078e-04" iyy="1.7452314e-03" iyz="-2.5645235e-04" izz="1.0432941e-03"/>
    </inertial>
    <visual>
      <geometry>
        <mesh filename="package://dexforce_w1_description/meshes/Visual/Common/Arm/link1.glb"/>
      </geometry>
    </visual>
    <collision>
      <geometry>
        <mesh filename="package://dexforce_w1_description/meshes/Collision/Common/Arm/link1.obj"/>
      </geometry>
    </collision>
  </link>
  <!-- J2 -->
  <link name="left_j2">
    <inertial>
      <origin xyz="7.4493179e-02  5.4776062e-03  1.1269136e-02"/>
      <mass value="1.4928861"/>
      <inertia ixx="1.2788191e-03" ixy="1.0008039e-04" ixz="2.8099405e-04" iyy="1.7498196e-03" iyz="1.3220976e-04" izz="2.0259514e-03"/>
    </inertial>
    <visual>
      <geometry>
        <mesh filename="package://dexforce_w1_description/meshes/Visual/Common/Arm/link2.glb"/>
      </geometry>
    </visual>
    <collision>
      <geometry>
        <mesh filename="package://dexforce_w1_description/meshes/Collision/Common/Arm/link2.obj"/>
      </geometry>
    </collision>
  </link>
  <!-- J3 -->
  <link name="left_j3">
    <inertial>
      <origin xyz="-3.0779128e-02  2.3551922e-02  9.5698192e-02 "/>
      <mass value="1.4997301"/>
      <inertia ixx="2.9132663e-03" ixy="1.1962671e-04" ixz="9.9797977e-05" iyy="2.7529670e-03" iyz="-6.5635889e-04" izz="1.7005461e-03"/>
    </inertial>
    <visual>
      <geometry>
        <mesh filename="package://dexforce_w1_description/meshes/Visual/Common/Arm/link3.glb" scale="1 1 1"/>
      </geometry>
    </visual>
    <collision>
      <geometry>
        <mesh filename="package://dexforce_w1_description/meshes/Collision/Common/Arm/link3.obj" scale="1 1 1"/>
      </geometry>
    </collision>
  </link>
  <!-- J4 -->
  <link name="left_j4">
    <inertial>
      <origin xyz="7.9139301e-02  9.0218591e-05  4.6401369e-03 "/>
      <mass value="1.1318974"/>
      <inertia ixx="8.5909310e-04" ixy="2.6724360e-06" ixz="2.3395344e-04" iyy="1.5127053e-03" iyz="6.2885682e-07" izz="1.4507260e-03"/>
    </inertial>
    <visual>
      <geometry>
        <mesh filename="package://dexforce_w1_description/meshes/Visual/Common/Arm/link4.glb" scale="1 1 1"/>
      </geometry>
    </visual>
    <collision>
      <geometry>
        <mesh filename="package://dexforce_w1_description/meshes/Collision/Common/Arm/link4.obj" scale="1 1 1"/>
      </geometry>
    </collision>
  </link>
  <!-- J5 -->
  <link name="left_j5">
    <inertial>
      <origin xyz="-6.8452097e-05 -1.6339752e-02  4.7773028e-02"/>
      <mass value="1.1865221"/>
      <inertia ixx="1.7309858e-03" ixy=" 3.3947403e-06" ixz="-4.1732012e-07" iyy="1.5458309e-03" iyz="3.0462375e-04" izz="9.8698385e-04"/>
    </inertial>
    <visual>
      <geometry>
        <mesh filename="package://dexforce_w1_description/meshes/Visual/Common/Arm/link5.glb" scale="1 1 1"/>
      </geometry>
    </visual>
    <collision>
      <geometry>
        <mesh filename="package://dexforce_w1_description/meshes/Collision/Common/Arm/link5.obj" scale="1 1 1"/>
      </geometry>
    </collision>
  </link>
  <!-- J6 -->
  <link name="left_j6">
    <inertial>
      <origin xyz="-1.8e-05 -0.004847 1.840867e-03"/>
      <mass value="0.98636414"/>
      <inertia ixx="7.01699e-04" ixy="2.22e-06" ixz="-1.99e-07" iyy="6.73097e-04" iyz="1e-06" izz="6.22094e-04"/>
    </inertial>
    <visual>
      <geometry>
        <mesh filename="package://dexforce_w1_description/meshes/Visual/Anthropomorphic/link6.glb" scale="1 1 1"/>
      </geometry>
    </visual>
    <collision>
      <geometry>
        <mesh filename="package://dexforce_w1_description/meshes/Collision/Anthropomorphic/link6.obj" scale="1 1 1"/>
      </geometry>
    </collision>
  </link>
  <!-- J7 -->
  <link name="left_j7">
    <inertial>
      <origin xyz="3.53912e-02 -1.19e-06 3.2097365e-02"/>
      <mass value="0.059937603"/>
      <inertia ixx="2.9853294e-05" ixy="-3.2e-09" ixz="2.0599320e-05" iyy="6.9425737e-05" iyz="1.68e-09" izz="5.84999e-05"/>
    </inertial>
    <visual>
      <geometry>
        <mesh filename="package://dexforce_w1_description/meshes/Visual/Anthropomorphic/link7.glb"/>
      </geometry>
    </visual>
    <collision>
      <geometry>
        <mesh filename="package://dexforce_w1_description/meshes/Collision/Anthropomorphic/link7.obj"/>
      </geometry>
    </collision>
  </link>
  <link name="left_tcp">
    <inertial>
      <origin xyz="0 0 0.048"/>
      <mass value="0.05"/>
      <inertia ixx="1E-05" ixy="1E-11" ixz="1E-06" iyy="1E-05" iyz="1E-08" izz="1E-05"/>
    </inertial>
  </link>
  <!-- Joints -->
  <joint name="left_arm_connector_joint" type="fixed">
    <origin rpy="-1.5707963267948966 -1.5707963267948966 0" xyz="0 0.0985 0.235"/>
    <parent link="waist"/>
    <child link="waist_to_left_arm_connector"/>
  </joint>
  <joint name="left_arm_base_joint" type="fixed">
    <parent link="waist_to_left_arm_connector"/>
    <child link="left_arm_base"/>
  </joint>
  <joint name="left_joint1" type="revolute">
    <parent link="left_arm_base"/>
    <child link="left_j1"/>
    <axis xyz="0 0 1"/>
    <limit effort="100" lower="-2.9670597283903604" upper="2.9670597283903604" velocity="0.8726646259971648"/>
  </joint>
  <joint name="left_joint2" type="revolute">
    <origin rpy="1.5707963267948966 0 3.141592653589793" xyz="0 0 0.1025"/>
    <parent link="left_j1"/>
    <child link="left_j2"/>
    <axis xyz="0 0 1"/>
    <limit effort="100" lower="-2.0943951023931953" upper="1.5707963267948966" velocity="0.8726646259971648"/>
  </joint>
  <joint name="left_joint3" type="revolute">
    <origin rpy="1.5707963267948966 -1.5707963267948966 3.141592653589793" xyz="0 0.260 0.0"/>
    <parent link="left_j2"/>
    <child link="left_j3"/>
    <axis xyz="0 0 1"/>
    <limit effort="100" lower="-2.9670597283903604" upper="2.9670597283903604" velocity="0.8726646259971648"/>
  </joint>
  <joint name="left_joint4" type="revolute">
    <origin rpy="1.5707963267948966 0 0" xyz="0 0 0"/>
    <parent link="left_j3"/>
    <child link="left_j4"/>
    <axis xyz="0 0 1"/>
    <limit effort="50" lower="-2.356194490192345" upper="1.5707963267948966" velocity="0.8726646259971648"/>
  </joint>
  <joint name="left_joint5" type="revolute">
    <origin rpy="-1.5707963267948966 3.141592653589793 0" xyz="0 0.166 0.0"/>
    <parent link="left_j4"/>
    <child link="left_j5"/>
    <axis xyz="0 0 1"/>
    <limit effort="50" lower="-2.9670597283903604" upper="2.9670597283903604" velocity="0.8726646259971648"/>
  </joint>
  <joint name="left_joint6" type="revolute">
    <origin rpy="1.5707963267948966 0 0" xyz="0 0 0.098"/>
    <parent link="left_j5"/>
    <child link="left_j6"/>
    <axis xyz="0 0 -1"/>
    <limit effort="50" lower="-0.7853981633974483" upper="0.7853981633974483" velocity="0.8726646259971648"/>
  </joint>
  <joint name="left_joint7" type="revolute">
    <origin rpy="-1.5707963267948966 3.141592653589793 1.5707963267948966" xyz="0 0 0"/>
    <limit effort="50" lower="-1.5707963267948966" upper="1.0471975511965976" velocity="0.8726646259971648"/>
    <parent link="left_j6"/>
    <child link="left_j7"/>
    <axis xyz="0 0 1"/>
  </joint>
  <joint name="left_tcp_joint" type="fixed">
    <origin rpy="0 -1.5707963267948966 0" xyz="-0.066 0 0"/>
    <parent link="left_j7"/>
    <child link="left_tcp"/>
  </joint>
  <link name="waist_to_right_arm_connector"/>
  <link name="right_arm_base"/>
  <!-- J1 -->
  <link name="right_j1">
    <inertial>
      <origin xyz="-2.2097730e-02  6.8020948e-03  7.8858121e-02"/>
      <mass value="1.3497532"/>
      <inertia ixx="1.4265178e-03" ixy="6.7924025e-05" ixz="2.0743078e-04" iyy="1.7452314e-03" iyz="-2.5645235e-04" izz="1.0432941e-03"/>
    </inertial>
    <visual>
      <geometry>
        <mesh filename="package://dexforce_w1_description/meshes/Visual/Common/Arm/link1.glb"/>
      </geometry>
    </visual>
    <collision>
      <geometry>
        <mesh filename="package://dexforce_w1_description/meshes/Collision/Common/Arm/link1.obj"/>
      </geometry>
    </collision>
  </link>
  <!-- J2 -->
  <link name="right_j2">
    <inertial>
      <origin xyz="7.4503421e-02  8.6398496e-03  7.3875448e-03"/>
      <mass value="1.4928861"/>
      <inertia ixx="1.3168555e-03" ixy="6.4048285e-05" ixz="2.3637923e-05" iyy="1.9564386e-03" iyz="2.2964738e-04" izz="1.8585844e-03"/>
    </inertial>
    <visual>
      <geometry>
        <mesh filename="package://dexforce_w1_description/meshes/Visual/Common/Arm/link2.glb"/>
      </geometry>
    </visual>
    <collision>
      <geometry>
        <mesh filename="package://dexforce_w1_description/meshes/Collision/Common/Arm/link2.obj"/>
      </geometry>
    </collision>
  </link>
  <!-- J3 -->
  <link name="right_j3">
    <inertial>
      <origin xyz="9.4849212e-03 -2.3561648e-02  1.0295135e-01"/>
      <mass value="1.4997301"/>
      <inertia ixx="3.6145187e-03" ixy="2.3474607e-04" ixz="-4.2307811e-04" iyy="3.1581989e-03" iyz="8.5973311e-04" izz="1.4009665e-03"/>
    </inertial>
    <visual>
      <geometry>
        <mesh filename="package://dexforce_w1_description/meshes/Visual/Common/Arm/link3.glb" scale="1 -1 1"/>
      </geometry>
    </visual>
    <collision>
      <geometry>
        <mesh filename="package://dexforce_w1_description/meshes/Collision/Common/Arm/link3.obj" scale="1 -1 1"/>
      </geometry>
    </collision>
  </link>
  <!-- J4 -->
  <link name="right_j4">
    <inertial>
      <origin xyz="-4.8716687e-05 -7.9139305e-02  4.5417266e-03"/>
      <mass value="1.1318974"/>
      <inertia ixx="1.5137272e-03" ixy="1.5021396e-06" ixz="-3.2891726e-07" iyy="8.6021305e-04" iyz="-2.3129546e-04" izz="1.4508237e-03"/>
    </inertial>
    <visual>
      <geometry>
        <mesh filename="package://dexforce_w1_description/meshes/Visual/Common/Arm/link4.glb" scale="1 1 -1"/>
      </geometry>
    </visual>
    <collision>
      <geometry>
        <mesh filename="package://dexforce_w1_description/meshes/Collision/Common/Arm/link4.obj" scale="1 1 -1"/>
      </geometry>
    </collision>
  </link>
  <!-- J5 -->
  <link name="right_j5">
    <inertial>
      <origin xyz="-7.2715831e-05  1.6196953e-02  4.7799231e-02"/>
      <mass value="1.1842602"/>
      <inertia ixx="1.7197116e-03" ixy="-3.6654609e-06" ixz="-9.7904563e-07" iyy="1.5409585e-03" iyz="-2.9712912e-04" izz="9.8002806e-04"/>
    </inertial>
    <visual>
      <geometry>
        <mesh filename="package://dexforce_w1_description/meshes/Visual/Common/Arm/link5.glb" scale="1 -1 1"/>
      </geometry>
    </visual>
    <collision>
      <geometry>
        <mesh filename="package://dexforce_w1_description/meshes/Collision/Common/Arm/link5.obj" scale="1 -1 1"/>
      </geometry>
    </collision>
  </link>
  <!-- J6 -->
  <link name="right_j6">
    <inertial>
      <origin xyz="1.8e-05 0.004847 1.840867e-03"/>
      <mass value="0.98636414"/>
      <inertia ixx="7.01699e-04" ixy="-2.22e-06" ixz="1.99e-07" iyy="6.73097e-04" iyz="-1e-06" izz="6.22094e-04"/>
    </inertial>
    <visual>
      <geometry>
        <mesh filename="package://dexforce_w1_description/meshes/Visual/Anthropomorphic/link6.glb" scale="1 1 -1"/>
      </geometry>
    </visual>
    <collision>
      <geometry>
        <mesh filename="package://dexforce_w1_description/meshes/Collision/Anthropomorphic/link6.obj" scale="1 1 -1"/>
      </geometry>
    </collision>
  </link>
  <!-- J7 -->
  <link name="right_j7">
    <inertial>
      <origin xyz="3.53912e-02 1.19e-06 3.2097365e-02"/>
      <mass value="0.059937603"/>
      <inertia ixx="2.9853294e-05" ixy="3.2e-09" ixz="2.0599320e-05" iyy="6.9425737e-05" iyz="-1.68e-09" izz="5.84999e-05"/>
    </inertial>
    <visual>
      <geometry>
        <mesh filename="package://dexforce_w1_description/meshes/Visual/Anthropomorphic/link7.glb"/>
      </geometry>
    </visual>
    <collision>
      <geometry>
        <mesh filename="package://dexforce_w1_description/meshes/Collision/Anthropomorphic/link7.obj"/>
      </geometry>
    </collision>
  </link>
  <link name="right_tcp">
    <inertial>
      <origin xyz="0 0 0.048"/>
      <mass value="0.05"/>
      <inertia ixx="1E-05" ixy="1E-11" ixz="1E-06" iyy="1E-05" iyz="1E-08" izz="1E-05"/>
    </inertial>
  </link>
  <!-- Joints -->
  <joint name="right_arm_connector_joint" type="fixed">
    <origin rpy="1.5707963267948966 1.5707963267948966 0" xyz="0 -0.0985 0.235"/>
    <parent link="waist"/>
    <child link="waist_to_right_arm_connector"/>
  </joint>
  <joint name="right_arm_base_joint" type="fixed">
    <parent link="waist_to_right_arm_connector"/>
    <child link="right_arm_base"/>
  </joint>
  <joint name="right_joint1" type="revolute">
    <parent link="right_arm_base"/>
    <child link="right_j1"/>
    <axis xyz="0 0 1"/>
    <limit effort="100" lower="-2.9670597283903604" upper="2.9670597283903604" velocity="0.8726646259971648"/>
  </joint>
  <joint name="right_joint2" type="revolute">
    <origin rpy="1.5707963267948966 0 3.141592653589793" xyz="0 0 0.1025"/>
    <parent link="right_j1"/>
    <child link="right_j2"/>
    <axis xyz="0 0 1"/>
    <limit effort="100" lower="-1.5707963267948966" upper="2.0943951023931953" velocity="0.8726646259971648"/>
  </joint>
  <joint name="right_joint3" type="revolute">
    <origin rpy="1.5707963267948966 -1.5707963267948966 3.141592653589793" xyz="0 0.260 0.0"/>
    <parent link="right_j2"/>
    <child link="right_j3"/>
    <axis xyz="0 0 1"/>
    <limit effort="100" lower="-2.9670597283903604" upper="2.9670597283903604" velocity="0.8726646259971648"/>
  </joint>
  <joint name="right_joint4" type="revolute">
    <origin rpy="1.5707963267948966 0 0" xyz="0 0 0"/>
    <parent link="right_j3"/>
    <child link="right_j4"/>
    <axis xyz="0 0 -1"/>
    <limit effort="50" lower="-1.5707963267948966" upper="2.356194490192345" velocity="0.8726646259971648"/>
  </joint>
  <joint name="right_joint5" type="revolute">
    <origin rpy="-1.5707963267948966 3.141592653589793 0" xyz="0 0.166 0.0"/>
    <parent link="right_j4"/>
    <child link="right_j5"/>
    <axis xyz="0 0 1"/>
    <limit effort="50" lower="-2.9670597283903604" upper="2.9670597283903604" velocity="0.8726646259971648"/>
  </joint>
  <joint name="right_joint6" type="revolute">
    <origin rpy="1.5707963267948966 0 0" xyz="0 0 0.098"/>
    <parent link="right_j5"/>
    <child link="right_j6"/>
    <axis xyz="0 0 1"/>
    <limit effort="50" lower="-0.7853981633974483" upper="0.7853981633974483" velocity="0.8726646259971648"/>
  </joint>
  <joint name="right_joint7" type="revolute">
    <origin rpy="-1.5707963267948966 3.141592653589793 1.5707963267948966" xyz="0 0 0"/>
    <limit effort="50" lower="-1.0471975511965976" upper="1.5707963267948966" velocity="0.8726646259971648"/>
    <parent link="right_j6"/>
    <child link="right_j7"/>
    <axis xyz="0 0 1"/>
  </joint>
  <joint name="right_tcp_joint" type="fixed">
    <origin rpy="0 -1.5707963267948966 0" xyz="-0.066 0 0"/>
    <parent link="right_j7"/>
    <child link="right_tcp"/>
  </joint>
  <!-- Note: gripper_type 不为空时表示使用夹爪 -->
  <link name="left_eef"/>
  <link name="right_eef"/>
  <joint name="left_eef_joint" type="fixed">
    <parent link="left_tcp"/>
    <child link="left_eef"/>
  </joint>
  <joint name="right_eef_joint" type="fixed">
    <parent link="right_tcp"/>
    <child link="right_eef"/>
  </joint>
</robot>
