<?xml version="1.0" ?>
<!-- =================================================================================== -->
<!-- |    This document was autogenerated by xacro from xacro/robot.xacro              | -->
<!-- |    EDITING THIS FILE BY HAND IS NOT RECOMMENDED                                 | -->
<!-- =================================================================================== -->
<!-- This URDF was automatically created by SolidWorks to URDF Exporter! Originally created by Stephen Brawner (brawner@gmail.com)
     Commit Version: 1.6.0-4-g7f85cfe  Build Version: 1.6.7995.38578
     For more information, please see http://wiki.ros.org/sw_urdf_exporter -->
<robot name="atom">
  <link name="base_link"/>
  <!-- Without Left Leg -->
  <!-- xacro:include filename="$(find dobot_atom_description)/xacro/leg.xacro"/>
	<! xacro:AtomLeg name="" direction="1" parent_link="pelvis"/-->
  <!-- Without Right Leg -->
  <!-- xacro:AtomLeg name="" direction="-1" parent_link="pelvis"/-->
  <link name="torso_link">
    <inertial>
      <origin xyz="-0.0155931 0 0.2199051"/>
      <mass value="14.0858"/>
      <inertia ixx="0.1671325" ixy="0.0000" ixz="-0.0005474" iyy="0.1806563" iyz="0.0000" izz="0.0672070"/>
    </inertial>
    <visual>
      <geometry>
        <mesh filename="file:///home/ly/ros2_ws/install/dobot_atom_description/share/dobot_atom_description/meshes/body/torso.obj"/>
      </geometry>
    </visual>
    <collision>
      <origin xyz="0 0 0.2"/>
      <geometry>
        <box size="0.26 0.24 0.4"/>
      </geometry>
    </collision>
  </link>
  <!-- upper 模式锁死躯干 -->
  <joint name="torso_joint" type="fixed">
    <parent link="base_link"/>
    <child link="torso_link"/>
  </joint>
  <link name="head_yaw_link">
    <inertial>
      <origin xyz="0.0000 -0.0027 0.0383"/>
      <mass value="0.4387"/>
      <inertia ixx="0.0003" ixy="0.0000" ixz="0.0000" iyy="0.0002" iyz="0.0000" izz="0.0002"/>
    </inertial>
    <visual>
      <geometry>
        <mesh filename="file:///home/ly/ros2_ws/install/dobot_atom_description/share/dobot_atom_description/meshes/body/head_yaw.obj"/>
      </geometry>
    </visual>
  </link>
  <joint name="head_yaw_joint" type="revolute">
    <origin xyz="0 0 0.4177"/>
    <parent link="torso_link"/>
    <child link="head_yaw_link"/>
    <axis xyz="0 0 1"/>
    <limit effort="12" lower="-1.57" upper="1.57" velocity="6.28"/>
  </joint>
  <link name="head_pitch_link">
    <inertial>
      <origin xyz="0.0337 0.0004 0.1204"/>
      <mass value="1.3341"/>
      <inertia ixx="0.0042" ixy="0.0000" ixz="0.0001" iyy="0.0070" iyz="0.0000" izz="0.0067"/>
    </inertial>
    <visual>
      <geometry>
        <mesh filename="file:///home/ly/ros2_ws/install/dobot_atom_description/share/dobot_atom_description/meshes/body/head_pitch.obj"/>
      </geometry>
    </visual>
    <collision>
      <origin xyz="0.05 0 0.1"/>
      <geometry>
        <box size="0.16 0.14 0.14"/>
      </geometry>
    </collision>
  </link>
  <joint name="head_pitch_joint" type="revolute">
    <origin xyz="0 0 0.041"/>
    <parent link="head_yaw_link"/>
    <child link="head_pitch_link"/>
    <axis xyz="0 1 0"/>
    <limit effort="12" lower="-1.57" upper="0.6981" velocity="6.28"/>
  </joint>
  <!-- imu -->
  <link name="imu_link">
		</link>
  <joint name="imu_joint" type="fixed">
    <origin xyz="0 0 -0.18"/>
    <parent link="torso_link"/>
    <child link="imu_link"/>
  </joint>
  <!-- Shoulder Pitch Link -->
  <link name="left_shoulder_pitch_link">
    <inertial>
      <origin xyz="0.0044 0.0368 0.0000"/>
      <mass value="0.4473"/>
      <inertia ixx="0.0007" ixy="0.0001" ixz="-0.0001" iyy="0.0008" iyz="0.0000" izz="0.0010"/>
    </inertial>
    <visual>
      <geometry>
        <mesh filename="file:///home/ly/ros2_ws/install/dobot_atom_description/share/dobot_atom_description/meshes/arm/link1.obj" scale="1 1 1"/>
      </geometry>
    </visual>
  </link>
  <joint name="left_shoulder_pitch_joint" type="revolute">
    <origin xyz="0 0.128 0.333"/>
    <parent link="torso_link"/>
    <child link="left_shoulder_pitch_link"/>
    <axis xyz="0 1 0"/>
    <limit effort="56" lower="-2.97" upper="2.97" velocity="2.62"/>
  </joint>
  <!-- Shoulder Roll Link -->
  <link name="left_shoulder_roll_link">
    <inertial>
      <origin xyz="0.0124 0.0009 -0.0545"/>
      <mass value="1.7940"/>
      <inertia ixx="0.0066" ixy="0.0000" ixz="0.0004" iyy="0.0067" iyz="0.0000" izz="0.0013"/>
    </inertial>
    <visual>
      <geometry>
        <mesh filename="file:///home/ly/ros2_ws/install/dobot_atom_description/share/dobot_atom_description/meshes/arm/link2.obj" scale="1 1 1"/>
      </geometry>
    </visual>
  </link>
  <joint name="left_shoulder_roll_joint" type="revolute">
    <origin rpy="0.18 0 0" xyz="0 0.078 0"/>
    <parent link="left_shoulder_pitch_link"/>
    <child link="left_shoulder_roll_link"/>
    <axis xyz="1 0 0"/>
    <limit effort="36" lower="-0.43" upper="3.14" velocity="2.62"/>
  </joint>
  <!-- Shoulder Yaw Link -->
  <link name="left_shoulder_yaw_link">
    <inertial>
      <origin xyz="-0.0014 0.0066 -0.1179"/>
      <mass value="0.9798"/>
      <inertia ixx="0.0018" ixy="0.0000" ixz="-0.0001" iyy="0.0016" iyz="-0.0001" izz="0.0008"/>
    </inertial>
    <visual>
      <geometry>
        <mesh filename="file:///home/ly/ros2_ws/install/dobot_atom_description/share/dobot_atom_description/meshes/arm/link3.obj"/>
      </geometry>
    </visual>
    <collision>
      <origin xyz="0 0 0"/>
      <geometry>
        <cylinder length="0.20" radius="0.04"/>
      </geometry>
    </collision>
  </link>
  <joint name="left_shoulder_yaw_joint" type="revolute">
    <origin xyz="0 0 -0.135"/>
    <parent link="left_shoulder_roll_link"/>
    <child link="left_shoulder_yaw_link"/>
    <axis xyz="0 0 1"/>
    <limit effort="36" lower="-2.97" upper="2.97" velocity="2.62"/>
  </joint>
  <!-- Elbow Pitch Link -->
  <link name="left_elbow_pitch_link">
    <inertial>
      <origin xyz="0.0903 0.0016 -0.0003"/>
      <mass value="0.8548"/>
      <inertia ixx="0.0008" ixy="-0.0001" ixz="0.0000" iyy="0.0025" iyz="-0.0" izz="0.0028"/>
    </inertial>
    <visual>
      <geometry>
        <mesh filename="file:///home/ly/ros2_ws/install/dobot_atom_description/share/dobot_atom_description/meshes/arm/link4.obj"/>
      </geometry>
    </visual>
    <collision>
      <origin rpy="1.57079632679 0 0"/>
      <geometry>
        <cylinder length="0.11" radius="0.04"/>
      </geometry>
    </collision>
  </link>
  <joint name="left_elbow_pitch_joint" type="revolute">
    <origin xyz="0.00044198773719138 0 -0.130000000000198"/>
    <parent link="left_shoulder_yaw_link"/>
    <child link="left_elbow_pitch_link"/>
    <axis xyz="0 1 0"/>
    <limit effort="36" lower="-1.57" upper="2" velocity="2.62"/>
  </joint>
  <!-- Elbow Roll Link -->
  <link name="left_elbow_roll_link">
    <inertial>
      <origin xyz="0.0270 0.0018 -0.0002"/>
      <mass value="0.2126"/>
      <inertia ixx="0.0003" ixy="0.0000" ixz="0.0000" iyy="0.0002" iyz="0.0000" izz="0.0003"/>
    </inertial>
    <visual>
      <geometry>
        <mesh filename="file:///home/ly/ros2_ws/install/dobot_atom_description/share/dobot_atom_description/meshes/arm/link5.obj"/>
      </geometry>
    </visual>
    <collision>
      <origin rpy="0 1.57079632679 0" xyz="-0.04 0 0"/>
      <geometry>
        <cylinder length="0.15" radius="0.045"/>
      </geometry>
    </collision>
  </link>
  <joint name="left_elbow_roll_joint" type="revolute">
    <origin xyz="0.1453 0 0"/>
    <parent link="left_elbow_pitch_link"/>
    <child link="left_elbow_roll_link"/>
    <axis xyz="1 0 0"/>
    <limit effort="18.6" lower="-2.97" upper="2.97" velocity="2.62"/>
  </joint>
  <!-- Wrist Pitch Link -->
  <link name="left_wrist_pitch_link">
    <inertial>
      <origin xyz="0.0421 -0.0042 -0.0038"/>
      <mass value="1.2573"/>
      <inertia ixx="0.0008" ixy="0.0002" ixz="-0.0002" iyy="0.0029" iyz="0.0000" izz="0.0029"/>
    </inertial>
    <visual>
      <geometry>
        <mesh filename="file:///home/ly/ros2_ws/install/dobot_atom_description/share/dobot_atom_description/meshes/arm/link6.obj" scale="1 1 1"/>
      </geometry>
    </visual>
    <collision>
      <origin rpy="1.57079632679 0 0"/>
      <geometry>
        <cylinder length="0.09" radius="0.035"/>
      </geometry>
    </collision>
  </link>
  <joint name="left_wrist_pitch_joint" type="revolute">
    <origin xyz="0.05345 0 0"/>
    <parent link="left_elbow_roll_link"/>
    <child link="left_wrist_pitch_link"/>
    <axis xyz="0 1 0"/>
    <limit effort="18.6" lower="-1.57" upper="1.57" velocity="2.62"/>
  </joint>
  <!-- Wrist Yaw Link -->
  <link name="left_wrist_yaw_link">
    <inertial>
      <origin xyz="0.0290 0.0004 0.0010"/>
      <mass value="0.3340"/>
      <inertia ixx="0.0003" ixy="0.0000" ixz="0.0000" iyy="0.0004" iyz="-0.0" izz="0.0003"/>
    </inertial>
    <visual>
      <geometry>
        <mesh filename="file:///home/ly/ros2_ws/install/dobot_atom_description/share/dobot_atom_description/meshes/arm/link7.obj" scale="1 1 1"/>
      </geometry>
    </visual>
    <collision>
      <origin rpy="0 0 0"/>
      <geometry>
        <cylinder length="0.09" radius="0.035"/>
      </geometry>
    </collision>
  </link>
  <joint name="left_wrist_yaw_joint" type="revolute">
    <origin xyz="0.085 0 0"/>
    <parent link="left_wrist_pitch_link"/>
    <child link="left_wrist_yaw_link"/>
    <axis xyz="0 0 1"/>
    <limit effort="18.6" lower="-1.57" upper="1.57" velocity="2.62"/>
  </joint>
  <!-- Shoulder Pitch Link -->
  <link name="right_shoulder_pitch_link">
    <inertial>
      <origin xyz="0.0044 -0.0368 0.0000"/>
      <mass value="0.4473"/>
      <inertia ixx="0.0007" ixy="-0.0001" ixz="-0.0001" iyy="0.0008" iyz="0.0000" izz="0.0010"/>
    </inertial>
    <visual>
      <geometry>
        <mesh filename="file:///home/ly/ros2_ws/install/dobot_atom_description/share/dobot_atom_description/meshes/arm/link1.obj" scale="1 -1 1"/>
      </geometry>
    </visual>
  </link>
  <joint name="right_shoulder_pitch_joint" type="revolute">
    <origin xyz="0 -0.128 0.333"/>
    <parent link="torso_link"/>
    <child link="right_shoulder_pitch_link"/>
    <axis xyz="0 1 0"/>
    <limit effort="56" lower="-2.97" upper="2.97" velocity="2.62"/>
  </joint>
  <!-- Shoulder Roll Link -->
  <link name="right_shoulder_roll_link">
    <inertial>
      <origin xyz="0.0124 -0.0009 -0.0545"/>
      <mass value="1.7940"/>
      <inertia ixx="0.0066" ixy="0.0000" ixz="0.0004" iyy="0.0067" iyz="0.0000" izz="0.0013"/>
    </inertial>
    <visual>
      <geometry>
        <mesh filename="file:///home/ly/ros2_ws/install/dobot_atom_description/share/dobot_atom_description/meshes/arm/link2.obj" scale="1 -1 1"/>
      </geometry>
    </visual>
  </link>
  <joint name="right_shoulder_roll_joint" type="revolute">
    <origin rpy="-0.18 0 0" xyz="0 -0.078 0"/>
    <parent link="right_shoulder_pitch_link"/>
    <child link="right_shoulder_roll_link"/>
    <axis xyz="1 0 0"/>
    <limit effort="36" lower="-3.14" upper="0.43" velocity="2.62"/>
  </joint>
  <!-- Shoulder Yaw Link -->
  <link name="right_shoulder_yaw_link">
    <inertial>
      <origin xyz="-0.0014 -0.0066 -0.1179"/>
      <mass value="0.9798"/>
      <inertia ixx="0.0018" ixy="0.0000" ixz="-0.0001" iyy="0.0016" iyz="0.0001" izz="0.0008"/>
    </inertial>
    <visual>
      <geometry>
        <mesh filename="file:///home/ly/ros2_ws/install/dobot_atom_description/share/dobot_atom_description/meshes/arm/link3.obj"/>
      </geometry>
    </visual>
    <collision>
      <origin xyz="0 0 0"/>
      <geometry>
        <cylinder length="0.20" radius="0.04"/>
      </geometry>
    </collision>
  </link>
  <joint name="right_shoulder_yaw_joint" type="revolute">
    <origin xyz="0 0 -0.135"/>
    <parent link="right_shoulder_roll_link"/>
    <child link="right_shoulder_yaw_link"/>
    <axis xyz="0 0 1"/>
    <limit effort="36" lower="-2.97" upper="2.97" velocity="2.62"/>
  </joint>
  <!-- Elbow Pitch Link -->
  <link name="right_elbow_pitch_link">
    <inertial>
      <origin xyz="0.0903 -0.0016 -0.0003"/>
      <mass value="0.8548"/>
      <inertia ixx="0.0008" ixy="0.0001" ixz="0.0000" iyy="0.0025" iyz="0.0" izz="0.0028"/>
    </inertial>
    <visual>
      <geometry>
        <mesh filename="file:///home/ly/ros2_ws/install/dobot_atom_description/share/dobot_atom_description/meshes/arm/link4.obj"/>
      </geometry>
    </visual>
    <collision>
      <origin rpy="1.57079632679 0 0"/>
      <geometry>
        <cylinder length="0.11" radius="0.04"/>
      </geometry>
    </collision>
  </link>
  <joint name="right_elbow_pitch_joint" type="revolute">
    <origin xyz="0.00044198773719138 0 -0.130000000000198"/>
    <parent link="right_shoulder_yaw_link"/>
    <child link="right_elbow_pitch_link"/>
    <axis xyz="0 1 0"/>
    <limit effort="36" lower="-1.57" upper="2" velocity="2.62"/>
  </joint>
  <!-- Elbow Roll Link -->
  <link name="right_elbow_roll_link">
    <inertial>
      <origin xyz="0.0270 -0.0018 -0.0002"/>
      <mass value="0.2126"/>
      <inertia ixx="0.0003" ixy="0.0000" ixz="0.0000" iyy="0.0002" iyz="0.0000" izz="0.0003"/>
    </inertial>
    <visual>
      <geometry>
        <mesh filename="file:///home/ly/ros2_ws/install/dobot_atom_description/share/dobot_atom_description/meshes/arm/link5.obj"/>
      </geometry>
    </visual>
    <collision>
      <origin rpy="0 1.57079632679 0" xyz="-0.04 0 0"/>
      <geometry>
        <cylinder length="0.15" radius="0.045"/>
      </geometry>
    </collision>
  </link>
  <joint name="right_elbow_roll_joint" type="revolute">
    <origin xyz="0.1453 0 0"/>
    <parent link="right_elbow_pitch_link"/>
    <child link="right_elbow_roll_link"/>
    <axis xyz="1 0 0"/>
    <limit effort="18.6" lower="-2.97" upper="2.97" velocity="2.62"/>
  </joint>
  <!-- Wrist Pitch Link -->
  <link name="right_wrist_pitch_link">
    <inertial>
      <origin xyz="0.0421 0.0042 -0.0038"/>
      <mass value="1.2573"/>
      <inertia ixx="0.0008" ixy="-0.0002" ixz="-0.0002" iyy="0.0029" iyz="0.0000" izz="0.0029"/>
    </inertial>
    <visual>
      <geometry>
        <mesh filename="file:///home/ly/ros2_ws/install/dobot_atom_description/share/dobot_atom_description/meshes/arm/link6.obj" scale="1 -1 1"/>
      </geometry>
    </visual>
    <collision>
      <origin rpy="1.57079632679 0 0"/>
      <geometry>
        <cylinder length="0.09" radius="0.035"/>
      </geometry>
    </collision>
  </link>
  <joint name="right_wrist_pitch_joint" type="revolute">
    <origin xyz="0.05345 0 0"/>
    <parent link="right_elbow_roll_link"/>
    <child link="right_wrist_pitch_link"/>
    <axis xyz="0 1 0"/>
    <limit effort="18.6" lower="-1.57" upper="1.57" velocity="2.62"/>
  </joint>
  <!-- Wrist Yaw Link -->
  <link name="right_wrist_yaw_link">
    <inertial>
      <origin xyz="0.0290 -0.0004 0.0010"/>
      <mass value="0.3340"/>
      <inertia ixx="0.0003" ixy="0.0000" ixz="0.0000" iyy="0.0004" iyz="0.0" izz="0.0003"/>
    </inertial>
    <visual>
      <geometry>
        <mesh filename="file:///home/ly/ros2_ws/install/dobot_atom_description/share/dobot_atom_description/meshes/arm/link7.obj" scale="1 -1 1"/>
      </geometry>
    </visual>
    <collision>
      <origin rpy="0 0 0"/>
      <geometry>
        <cylinder length="0.09" radius="0.035"/>
      </geometry>
    </collision>
  </link>
  <joint name="right_wrist_yaw_joint" type="revolute">
    <origin xyz="0.085 0 0"/>
    <parent link="right_wrist_pitch_link"/>
    <child link="right_wrist_yaw_link"/>
    <axis xyz="0 0 1"/>
    <limit effort="18.6" lower="-1.57" upper="1.57" velocity="2.62"/>
  </joint>
  <!--xacro:include filename="$(find dobot_atom_description)/xacro/full_body.xacro"/-->
</robot>
