<?xml version="1.0" ?>
<!-- =================================================================================== -->
<!-- |    This document was autogenerated by xacro from robot.xacro                    | -->
<!-- |    EDITING THIS FILE BY HAND IS NOT RECOMMENDED                                 | -->
<!-- =================================================================================== -->
<!-- This URDF was automatically created by SolidWorks to URDF Exporter! Originally created by Stephen Brawner (brawner@gmail.com) 
     Commit Version: 1.6.0-4-g7f85cfe  Build Version: 1.6.7995.38578
     For more information, please see http://wiki.ros.org/sw_urdf_exporter -->
<robot name="A1Lite">
  <link name="base_link">
    <inertial>
      <origin xyz="0.0718033657159837 -0.0016279349766449 0.128750850965126"/>
      <mass value="25.114"/>
      <inertia ixx="0.190993086908409" ixy="7.01153963312701E-05" ixz="-0.00785937977791519" iyy="0.152035922355254" iyz="-0.000494758898409346" izz="0.29121889848538"/>
    </inertial>
    <visual>
      <geometry>
        <mesh filename="package://galaxea_r1lite_description/meshes/visual/base.obj"/>
      </geometry>
    </visual>
    <collision>
      <geometry>
        <mesh filename="package://galaxea_r1lite_description/meshes/collision/base.stl"/>
      </geometry>
    </collision>
  </link>
  <link name="steer_motor_link1">
    <inertial>
      <origin xyz="-1.76196610579549E-07 -7.75116053202478E-05 -0.0852489956386505"/>
      <mass value="1.5"/>
      <inertia ixx="0.000338657650556839" ixy="6.14197589167664E-09" ixz="6.6056392682533E-09" iyy="0.000503900951850049" iyz="3.6051622873431E-08" izz="0.000211486748436409"/>
    </inertial>
    <visual>
      <geometry>
        <mesh filename="package://galaxea_r1lite_description/meshes/visual/steer_motor.obj"/>
      </geometry>
    </visual>
  </link>
  <joint name="steer_motor_joint1" type="fixed">
    <origin xyz="0.29183 -0.0014897 0.18165"/>
    <parent link="base_link"/>
    <child link="steer_motor_link1"/>
    <axis xyz="0 0 1"/>
    <limit effort="20" lower="-3.141592653589793" upper="3.141592653589793" velocity="20"/>
  </joint>
  <link name="wheel_motor_link1">
    <inertial>
      <origin xyz="0 -9.99250577455509E-13 -2.34534613952064E-15"/>
      <mass value="1.5"/>
      <inertia ixx="0.00104702497304016" ixy="2.02186210571336E-18" ixz="-8.67361737988254E-20" iyy="0.00181031135070458" iyz="3.54126040189266E-17" izz="0.00104702497304016"/>
    </inertial>
    <visual>
      <geometry>
        <mesh filename="package://galaxea_r1lite_description/meshes/visual/wheel.obj"/>
      </geometry>
    </visual>
    <collision>
      <geometry>
        <mesh filename="package://galaxea_r1lite_description/meshes/visual/wheel.obj"/>
      </geometry>
    </collision>
  </link>
  <joint name="wheel_motor_joint1" type="fixed">
    <origin xyz="0 0 -0.11165"/>
    <parent link="steer_motor_link1"/>
    <child link="wheel_motor_link1"/>
    <axis xyz="0 1 0"/>
  </joint>
  <link name="steer_motor_link2">
    <inertial>
      <origin xyz="1.76196610607304E-07 7.75116053202962E-05 -0.0852489956386505"/>
      <mass value="1.5"/>
      <inertia ixx="0.000338657650556839" ixy="6.1419758916829E-09" ixz="-6.6056392682485E-09" iyy="0.000503900951850049" iyz="-3.60516228734399E-08" izz="0.000211486748436408"/>
    </inertial>
    <visual>
      <geometry>
        <mesh filename="package://galaxea_r1lite_description/meshes/visual/steer_motor.obj"/>
      </geometry>
    </visual>
  </link>
  <joint name="steer_motor_joint2" type="fixed">
    <origin xyz="-0.16817 0.23851 0.18165"/>
    <parent link="base_link"/>
    <child link="steer_motor_link2"/>
    <axis xyz="0 0 1"/>
    <limit effort="20" lower="-3.141592653589793" upper="3.141592653589793" velocity="20"/>
  </joint>
  <link name="wheel_motor_link2">
    <inertial>
      <origin xyz="2.77555756156289E-17 -1.94289029309402E-16 -2.34621350125863E-15"/>
      <mass value="1.5"/>
      <inertia ixx="0.00104702497304016" ixy="2.01102008398851E-18" ixz="-8.67361737988254E-20" iyy="0.00181031135070458" iyz="3.54092952964764E-17" izz="0.00104702497304016"/>
    </inertial>
    <visual>
      <geometry>
        <mesh filename="package://galaxea_r1lite_description/meshes/visual/wheel.obj"/>
      </geometry>
    </visual>
    <collision>
      <geometry>
        <mesh filename="package://galaxea_r1lite_description/meshes/visual/wheel.obj"/>
      </geometry>
    </collision>
  </link>
  <joint name="wheel_motor_joint2" type="fixed">
    <origin xyz="0 0 -0.11165"/>
    <parent link="steer_motor_link2"/>
    <child link="wheel_motor_link2"/>
    <axis xyz="0 1 0"/>
  </joint>
  <link name="steer_motor_link3">
    <inertial>
      <origin xyz="1.76196610579549E-07 7.75116053202407E-05 -0.0852489956386505"/>
      <mass value="1.5"/>
      <inertia ixx="0.000338657650556839" ixy="6.14197589167356E-09" ixz="-6.60563926825079E-09" iyy="0.000503900951850049" iyz="-3.60516228734413E-08" izz="0.000211486748436408"/>
    </inertial>
    <visual>
      <geometry>
        <mesh filename="package://galaxea_r1lite_description/meshes/visual/steer_motor.obj"/>
      </geometry>
    </visual>
  </link>
  <joint name="steer_motor_joint3" type="fixed">
    <origin xyz="-0.16817 -0.24149 0.18165"/>
    <parent link="base_link"/>
    <child link="steer_motor_link3"/>
    <axis xyz="0 0 1"/>
    <limit effort="20" lower="-3.141592653589793" upper="3.141592653589793" velocity="20"/>
  </joint>
  <link name="wheel_motor_link3">
    <inertial>
      <origin xyz="0 -1.94289029309402E-16 -2.34274405430668E-15"/>
      <mass value="1.5"/>
      <inertia ixx="0.00104702497304016" ixy="2.00017806226365E-18" ixz="-8.67361737988255E-20" iyy="0.00181031135070458" iyz="3.53868224535946E-17" izz="0.00104702497304016"/>
    </inertial>
    <visual>
      <geometry>
        <mesh filename="package://galaxea_r1lite_description/meshes/visual/wheel.obj"/>
      </geometry>
    </visual>
    <collision>
      <geometry>
        <mesh filename="package://galaxea_r1lite_description/meshes/visual/wheel.obj"/>
      </geometry>
    </collision>
  </link>
  <joint name="wheel_motor_joint3" type="fixed">
    <origin xyz="0 0 -0.11165"/>
    <parent link="steer_motor_link3"/>
    <child link="wheel_motor_link3"/>
    <axis xyz="0 1 0"/>
  </joint>
  <link name="torso_link1">
    <inertial>
      <origin xyz="0.00321196798398059 0.0116566745256909 0.100697975240297"/>
      <mass value="4.807"/>
      <inertia ixx="0.00310511493924453" ixy="3.89455548949465E-06" ixz="-0.000112029811012738" iyy="0.00326868759782864" iyz="4.14882596510336E-05" izz="0.000354993987137864"/>
    </inertial>
    <visual>
      <geometry>
        <mesh filename="package://galaxea_r1lite_description/meshes/visual/torso1.obj"/>
      </geometry>
    </visual>
    <collision>
      <geometry>
        <mesh filename="package://galaxea_r1lite_description/meshes/collision/torso1.stl"/>
      </geometry>
    </collision>
  </link>
  <joint name="torso_joint1" type="revolute">
    <origin xyz="0.091831 0.00036033 0.14865"/>
    <parent link="base_link"/>
    <child link="torso_link1"/>
    <axis xyz="0 1 0"/>
    <limit effort="100" lower="-1.5707963267948966" upper="0.436333" velocity="2.5"/>
  </joint>
  <link name="torso_link2">
    <inertial>
      <origin xyz="0.00627300956924463 0.00536087570300695 0.184118796618929"/>
      <mass value="2.779"/>
      <inertia ixx="0.0309540761907757" ixy="-5.57959685881806E-07" ixz="0.000297952176364751" iyy="0.032517017639908" iyz="9.00096610164517E-07" izz="0.00185256464591929"/>
    </inertial>
    <visual>
      <geometry>
        <mesh filename="package://galaxea_r1lite_description/meshes/visual/torso2.obj"/>
      </geometry>
    </visual>
    <collision>
      <geometry>
        <mesh filename="package://galaxea_r1lite_description/meshes/collision/torso2.stl"/>
      </geometry>
    </collision>
  </link>
  <joint name="torso_joint2" type="revolute">
    <origin xyz="0 -0.00185 0.35"/>
    <parent link="torso_link1"/>
    <child link="torso_link2"/>
    <axis xyz="0 1 0"/>
    <limit effort="100" lower="-2.705262" upper="2.705262" velocity="2.5"/>
  </joint>
  <link name="torso_link3">
    <inertial>
      <origin xyz="-0.0416383086406449 0.000484599582373232 0.051111008977659"/>
      <mass value="5.833"/>
      <inertia ixx="0.00647219350010978" ixy="-4.51460802718021E-07" ixz="-1.28687447342324E-05" iyy="0.0054231706909373" iyz="-1.67510995383755E-07" izz="0.00845061936347779"/>
    </inertial>
    <visual>
      <geometry>
        <mesh filename="package://galaxea_r1lite_description/meshes/visual/torso3.obj"/>
      </geometry>
    </visual>
    <collision>
      <geometry>
        <mesh filename="package://galaxea_r1lite_description/meshes/collision/torso3.stl"/>
      </geometry>
    </collision>
  </link>
  <joint name="torso_joint3" type="revolute">
    <origin xyz="9.6485E-05 0 0.35"/>
    <parent link="torso_link2"/>
    <child link="torso_link3"/>
    <axis xyz="0 -1 0"/>
    <limit effort="100" lower="-1.5707963267948966" upper="1.5707963267948966" velocity="2.5"/>
  </joint>
  <link name="camera_head_left_link"/>
  <joint name="camera_head_left_joint" type="fixed">
    <origin rpy="-2.0943951023931953 4.1972E-05 -1.5707963267948966" xyz="0.054947 0.03149 0.63214"/>
    <parent link="torso_link3"/>
    <child link="camera_head_left_link"/>
  </joint>
  <link name="camera_head_right_link"/>
  <joint name="camera_head_right_joint" type="fixed">
    <origin rpy="-2.0943951023931953 4.1972E-05 -1.5707963267948966" xyz="0.054943 -0.03351 0.63214"/>
    <parent link="torso_link3"/>
    <child link="camera_head_right_link"/>
  </joint>
  <joint name="left_arm_base_joint" type="fixed">
    <origin xyz="0 0.335 0.12306"/>
    <parent link="torso_link3"/>
    <child link="left_base_link"/>
  </joint>
  <joint name="right_arm_base_joint" type="fixed">
    <origin xyz="0 -0.335 0.12306"/>
    <parent link="torso_link3"/>
    <child link="right_base_link"/>
  </joint>
  <!-- Base Link -->
  <link name="left_base_link">
    <inertial>
      <origin xyz="0.00303246421307354 -0.000695340443194854 0.0297996781638517"/>
      <mass value="0.786"/>
      <inertia ixx="0.000209631286775999" ixy="1.3987766340865E-06" ixz="5.68764766805313E-06" iyy="0.000199785107628426" iyz="-3.65982104907021E-06" izz="0.000237444184695321"/>
    </inertial>
    <visual>
      <geometry>
        <mesh filename="package://galaxea_a1_description/meshes/a1_xy/base_link.obj"/>
      </geometry>
    </visual>
    <collision>
      <geometry>
        <mesh filename="package://galaxea_a1_description/meshes/a1_xy/base_link.obj"/>
      </geometry>
    </collision>
  </link>
  <!-- Link 1 -->
  <link name="left_link1">
    <inertial>
      <origin xyz="4.1065175135883E-07 -0.00198628171247454 0.0468863413356551"/>
      <mass value="0.839"/>
      <inertia ixx="0.000224135392915726" ixy="-1.28206810172038E-09" ixz="7.50235402650185E-09" iyy="0.00026979982869931" iyz="7.49527197322758E-09" izz="0.000218724360467532"/>
    </inertial>
    <visual>
      <geometry>
        <mesh filename="package://galaxea_a1_description/meshes/a1_xy/link1.obj"/>
      </geometry>
    </visual>
    <collision>
      <geometry>
        <mesh filename="package://galaxea_a1_description/meshes/a1_xy/link1.obj"/>
      </geometry>
    </collision>
  </link>
  <!-- Joint 1: Base to Link1 -->
  <joint name="left_joint1" type="revolute">
    <origin xyz="0 0 0.08605"/>
    <parent link="left_base_link"/>
    <child link="left_link1"/>
    <axis xyz="0 0 1"/>
    <limit effort="27" lower="-2.879795" upper="2.879795" velocity="10.4720"/>
  </joint>
  <!-- Link 2 -->
  <link name="left_link2">
    <inertial>
      <origin xyz="-0.122673818397923 -0.0295401461831619 0.00364838977156251"/>
      <mass value="1.09"/>
      <inertia ixx="0.000388311522528777" ixy="-2.18086613093501E-05" ixz="8.77434895649448E-06" iyy="0.00274683151904258" iyz="1.19756607314247E-06" izz="0.00278055331308976"/>
    </inertial>
    <visual>
      <geometry>
        <mesh filename="package://galaxea_a1_description/meshes/a1_xy/link2.obj"/>
      </geometry>
    </visual>
    <collision>
      <geometry>
        <mesh filename="package://galaxea_a1_description/meshes/a1_xy/link2.obj"/>
      </geometry>
    </collision>
  </link>
  <!-- Joint 2: Link1 to Link2 -->
  <joint name="left_joint2" type="revolute">
    <origin xyz="0 0.03075 0.04925"/>
    <parent link="left_link1"/>
    <child link="left_link2"/>
    <axis xyz="0 1 0"/>
    <limit effort="50" lower="0" upper="3.141592653589793" velocity="12.5664"/>
  </joint>
  <link name="left_link3">
    <inertial>
      <origin xyz="0.0795681449160072 -0.0327357454565678 0.065177920553168"/>
      <mass value="0.762"/>
      <inertia ixx="0.000282703505875711" ixy="-4.06256349285171E-06" ixz="-7.63228373259732E-05" iyy="0.000329835410245831" iyz="-1.03493005263955E-05" izz="0.000237652038430906"/>
    </inertial>
    <visual>
      <geometry>
        <mesh filename="package://galaxea_a1_description/meshes/a1_xy/a1_y/link3.obj"/>
      </geometry>
    </visual>
    <collision>
      <geometry>
        <mesh filename="package://galaxea_a1_description/meshes/a1_xy/a1_y/link3.obj"/>
      </geometry>
    </collision>
  </link>
  <joint name="left_joint3" type="revolute">
    <origin xyz="-0.3 0.00024449 0"/>
    <parent link="left_link2"/>
    <child link="left_link3"/>
    <axis xyz="0 1 0"/>
    <limit effort="27" lower="-3.316127" upper="0" velocity="10.4720"/>
  </joint>
  <link name="left_link4">
    <inertial>
      <origin xyz="0.0388578803222686 0.000937806543809841 -1.15721572034322E-05"/>
      <mass value="0.353"/>
      <inertia ixx="5.97701758868814E-05" ixy="-6.87774799668449E-10" ixz="-2.14372946639157E-10" iyy="6.0587917049985E-05" iyz="-5.98401601618766E-11" izz="5.98342278178533E-05"/>
    </inertial>
    <visual>
      <geometry>
        <mesh filename="package://galaxea_a1_description/meshes/a1_xy/a1_y/link4.obj"/>
      </geometry>
    </visual>
    <collision>
      <geometry>
        <mesh filename="package://galaxea_a1_description/meshes/a1_xy/a1_y/link4.obj"/>
      </geometry>
    </collision>
  </link>
  <joint name="left_joint4" type="revolute">
    <origin xyz="0.1544 -0.030998 0.075485"/>
    <parent link="left_link3"/>
    <child link="left_link4"/>
    <axis xyz="1 0 0"/>
    <limit effort="14" lower="-2.879795" upper="2.879795" velocity="32.9867"/>
  </joint>
  <link name="left_link5">
    <inertial>
      <origin xyz="0.0526293728146609 -0.0197387756630963 7.38547745043894E-06"/>
      <mass value="0.366"/>
      <inertia ixx="5.87226827172217E-05" ixy="3.94835644387525E-09" ixz="-1.57113932950695E-12" iyy="6.96559934519655E-05" iyz="7.55674102061766E-09" izz="6.85055623583414E-05"/>
    </inertial>
    <visual>
      <geometry>
        <mesh filename="package://galaxea_a1_description/meshes/a1_xy/a1_y/link5.obj"/>
      </geometry>
    </visual>
    <collision>
      <geometry>
        <mesh filename="package://galaxea_a1_description/meshes/a1_xy/a1_y/link5.obj"/>
      </geometry>
    </collision>
  </link>
  <joint name="left_joint5" type="revolute">
    <origin xyz="0.0418 0.023501 0"/>
    <parent link="left_link4"/>
    <child link="left_link5"/>
    <axis xyz="0 1 0"/>
    <limit effort="14" lower="-1.832597" upper="1.832597" velocity="32.9867"/>
  </joint>
  <link name="left_link6">
    <inertial>
      <origin xyz="0.00709944781467154 1.26586535489642E-07 -3.8262881471296E-05"/>
      <mass value="0.031"/>
      <inertia ixx="3.44528457425794E-06" ixy="2.98138934982256E-11" ixz="-1.26128084918303E-09" iyy="1.82573408455416E-06" iyz="1.17092872453752E-14" izz="1.8173151968758E-06"/>
    </inertial>
    <visual>
      <geometry>
        <mesh filename="package://galaxea_a1_description/meshes/a1_xy/link6.obj"/>
      </geometry>
    </visual>
    <collision>
      <geometry>
        <mesh filename="package://galaxea_a1_description/meshes/a1_xy/link6.obj"/>
      </geometry>
    </collision>
  </link>
  <joint name="left_joint6" type="revolute">
    <origin xyz="0.081 -0.023499 0"/>
    <parent link="left_link5"/>
    <child link="left_link6"/>
    <axis xyz="1 0 0"/>
    <limit effort="14" lower="-2.879795" upper="2.879795" velocity="32.9867"/>
  </joint>
  <link name="left_gripper_base">
    <inertial>
      <origin xyz="-0.0311072323899603 1.17979991887118E-08 7.93394685505433E-08"/>
      <mass value="0.604"/>
      <inertia ixx="0.000175881544189539" ixy="-6.06026450851008E-11" ixz="5.30643405624365E-10" iyy="9.86379407701341E-05" iyz="-8.18686692495892E-08" izz="0.000165121280580029"/>
    </inertial>
    <visual>
      <geometry>
        <mesh filename="package://galaxea_a1_description/meshes/gripper/gripper_link.obj"/>
      </geometry>
    </visual>
    <collision>
      <geometry>
        <mesh filename="package://galaxea_a1_description/meshes/gripper/gripper_link.obj"/>
      </geometry>
    </collision>
  </link>
  <link name="left_finger1">
    <inertial>
      <origin xyz="-0.0195895895552112 -0.0151136845490034 0.00542254359093075"/>
      <mass value="0.027"/>
      <inertia ixx="2.40569358477209E-06" ixy="3.9898459609048E-07" ixz="5.12152762183641E-08" iyy="5.71079298307516E-06" iyz="6.19467902008363E-08" izz="6.48482183930358E-06"/>
    </inertial>
    <visual>
      <geometry>
        <mesh filename="package://galaxea_a1_description/meshes/gripper/finger.obj"/>
      </geometry>
    </visual>
    <collision>
      <geometry>
        <mesh filename="package://galaxea_a1_description/meshes/gripper/finger.obj"/>
      </geometry>
    </collision>
  </link>
  <joint name="left_gripper_joint" type="prismatic">
    <origin xyz="0.03689 0.013453 0.00012059"/>
    <parent link="left_gripper_base"/>
    <child link="left_finger1"/>
    <axis xyz="0 1 0"/>
    <limit effort="10" lower="0" upper="0.05" velocity="0.25"/>
  </joint>
  <link name="left_finger2">
    <inertial>
      <origin xyz="-0.0195895857999098 0.0151136893508115 -0.00542254357246619"/>
      <mass value="0.027"/>
      <inertia ixx="2.40569340151687E-06" ixy="-3.98983784827124E-07" ixz="-5.12152683073981E-08" iyy="5.71079321589929E-06" iyz="6.19467953006536E-08" izz="6.48482187274222E-06"/>
    </inertial>
    <visual>
      <geometry>
        <mesh filename="package://galaxea_a1_description/meshes/gripper/finger.obj" scale="1 -1 -1"/>
      </geometry>
    </visual>
    <collision>
      <geometry>
        <mesh filename="package://galaxea_a1_description/meshes/gripper/finger.obj" scale="1 -1 -1"/>
      </geometry>
    </collision>
  </link>
  <joint name="left_gripper_joint2" type="prismatic">
    <origin xyz="0.03689 -0.013453 -0.00012059"/>
    <parent link="left_gripper_base"/>
    <child link="left_finger2"/>
    <axis xyz="0 -1 0"/>
    <limit effort="10" lower="0" upper="0.05" velocity="0.25"/>
    <mimic joint="left_gripper_joint" multiplier="1" offset="0"/>
  </joint>
  <link name="left_gripper_center"/>
  <joint name="left_gripper_center_joint" type="fixed">
    <origin xyz="0.03689 0 -0.00012059"/>
    <parent link="left_gripper_base"/>
    <child link="left_gripper_center"/>
  </joint>
  <joint name="left_gripper_base_joint" type="fixed">
    <origin xyz="0.08165 0 0"/>
    <parent link="left_link6"/>
    <child link="left_gripper_base"/>
  </joint>
  <link name="left_camera_stand">
    <inertial>
      <origin xyz="0.00904707172594749 0.0155186578138565 -0.00819594831521042"/>
      <mass value="0.1"/>
      <inertia ixx="2.78082944930657E-05" ixy="-4.06196131154851E-10" ixz="1.50543456329152E-08" iyy="2.18951425070333E-05" iyz="-3.73269688187078E-06" izz="2.07706210423581E-05"/>
    </inertial>
    <visual>
      <geometry>
        <mesh filename="package://galaxea_r1lite_description/meshes/visual/camera_stand.obj"/>
      </geometry>
    </visual>
    <visual>
      <origin rpy="0 -1.5707963267948966 1.5707963267948966" xyz="0.008996 0 0"/>
      <geometry>
        <mesh filename="package://share/sensor_models/meshes/d405/d405.obj"/>
      </geometry>
    </visual>
    <collision>
      <geometry>
        <mesh filename="package://galaxea_r1lite_description/meshes/collision/camera.stl"/>
      </geometry>
    </collision>
  </link>
  <joint name="left_camera_stand_joint" type="fixed">
    <origin rpy="-2.268 0 -1.5707963267948966" xyz="-0.019206 0.009 0.074757"/>
    <parent link="left_gripper_base"/>
    <child link="left_camera_stand"/>
  </joint>
  <!-- Base Link -->
  <link name="right_base_link">
    <inertial>
      <origin xyz="0.00303246421307354 -0.000695340443194854 0.0297996781638517"/>
      <mass value="0.786"/>
      <inertia ixx="0.000209631286775999" ixy="1.3987766340865E-06" ixz="5.68764766805313E-06" iyy="0.000199785107628426" iyz="-3.65982104907021E-06" izz="0.000237444184695321"/>
    </inertial>
    <visual>
      <geometry>
        <mesh filename="package://galaxea_a1_description/meshes/a1_xy/base_link.obj"/>
      </geometry>
    </visual>
    <collision>
      <geometry>
        <mesh filename="package://galaxea_a1_description/meshes/a1_xy/base_link.obj"/>
      </geometry>
    </collision>
  </link>
  <!-- Link 1 -->
  <link name="right_link1">
    <inertial>
      <origin xyz="4.1065175135883E-07 -0.00198628171247454 0.0468863413356551"/>
      <mass value="0.839"/>
      <inertia ixx="0.000224135392915726" ixy="-1.28206810172038E-09" ixz="7.50235402650185E-09" iyy="0.00026979982869931" iyz="7.49527197322758E-09" izz="0.000218724360467532"/>
    </inertial>
    <visual>
      <geometry>
        <mesh filename="package://galaxea_a1_description/meshes/a1_xy/link1.obj"/>
      </geometry>
    </visual>
    <collision>
      <geometry>
        <mesh filename="package://galaxea_a1_description/meshes/a1_xy/link1.obj"/>
      </geometry>
    </collision>
  </link>
  <!-- Joint 1: Base to Link1 -->
  <joint name="right_joint1" type="revolute">
    <origin xyz="0 0 0.08605"/>
    <parent link="right_base_link"/>
    <child link="right_link1"/>
    <axis xyz="0 0 1"/>
    <limit effort="27" lower="-2.879795" upper="2.879795" velocity="10.4720"/>
  </joint>
  <!-- Link 2 -->
  <link name="right_link2">
    <inertial>
      <origin xyz="-0.122673818397923 -0.0295401461831619 0.00364838977156251"/>
      <mass value="1.09"/>
      <inertia ixx="0.000388311522528777" ixy="-2.18086613093501E-05" ixz="8.77434895649448E-06" iyy="0.00274683151904258" iyz="1.19756607314247E-06" izz="0.00278055331308976"/>
    </inertial>
    <visual>
      <geometry>
        <mesh filename="package://galaxea_a1_description/meshes/a1_xy/link2.obj"/>
      </geometry>
    </visual>
    <collision>
      <geometry>
        <mesh filename="package://galaxea_a1_description/meshes/a1_xy/link2.obj"/>
      </geometry>
    </collision>
  </link>
  <!-- Joint 2: Link1 to Link2 -->
  <joint name="right_joint2" type="revolute">
    <origin xyz="0 0.03075 0.04925"/>
    <parent link="right_link1"/>
    <child link="right_link2"/>
    <axis xyz="0 1 0"/>
    <limit effort="50" lower="0" upper="3.141592653589793" velocity="12.5664"/>
  </joint>
  <link name="right_link3">
    <inertial>
      <origin xyz="0.0795681449160072 -0.0327357454565678 0.065177920553168"/>
      <mass value="0.762"/>
      <inertia ixx="0.000282703505875711" ixy="-4.06256349285171E-06" ixz="-7.63228373259732E-05" iyy="0.000329835410245831" iyz="-1.03493005263955E-05" izz="0.000237652038430906"/>
    </inertial>
    <visual>
      <geometry>
        <mesh filename="package://galaxea_a1_description/meshes/a1_xy/a1_y/link3.obj"/>
      </geometry>
    </visual>
    <collision>
      <geometry>
        <mesh filename="package://galaxea_a1_description/meshes/a1_xy/a1_y/link3.obj"/>
      </geometry>
    </collision>
  </link>
  <joint name="right_joint3" type="revolute">
    <origin xyz="-0.3 0.00024449 0"/>
    <parent link="right_link2"/>
    <child link="right_link3"/>
    <axis xyz="0 1 0"/>
    <limit effort="27" lower="-3.316127" upper="0" velocity="10.4720"/>
  </joint>
  <link name="right_link4">
    <inertial>
      <origin xyz="0.0388578803222686 0.000937806543809841 -1.15721572034322E-05"/>
      <mass value="0.353"/>
      <inertia ixx="5.97701758868814E-05" ixy="-6.87774799668449E-10" ixz="-2.14372946639157E-10" iyy="6.0587917049985E-05" iyz="-5.98401601618766E-11" izz="5.98342278178533E-05"/>
    </inertial>
    <visual>
      <geometry>
        <mesh filename="package://galaxea_a1_description/meshes/a1_xy/a1_y/link4.obj"/>
      </geometry>
    </visual>
    <collision>
      <geometry>
        <mesh filename="package://galaxea_a1_description/meshes/a1_xy/a1_y/link4.obj"/>
      </geometry>
    </collision>
  </link>
  <joint name="right_joint4" type="revolute">
    <origin xyz="0.1544 -0.030998 0.075485"/>
    <parent link="right_link3"/>
    <child link="right_link4"/>
    <axis xyz="1 0 0"/>
    <limit effort="14" lower="-2.879795" upper="2.879795" velocity="32.9867"/>
  </joint>
  <link name="right_link5">
    <inertial>
      <origin xyz="0.0526293728146609 -0.0197387756630963 7.38547745043894E-06"/>
      <mass value="0.366"/>
      <inertia ixx="5.87226827172217E-05" ixy="3.94835644387525E-09" ixz="-1.57113932950695E-12" iyy="6.96559934519655E-05" iyz="7.55674102061766E-09" izz="6.85055623583414E-05"/>
    </inertial>
    <visual>
      <geometry>
        <mesh filename="package://galaxea_a1_description/meshes/a1_xy/a1_y/link5.obj"/>
      </geometry>
    </visual>
    <collision>
      <geometry>
        <mesh filename="package://galaxea_a1_description/meshes/a1_xy/a1_y/link5.obj"/>
      </geometry>
    </collision>
  </link>
  <joint name="right_joint5" type="revolute">
    <origin xyz="0.0418 0.023501 0"/>
    <parent link="right_link4"/>
    <child link="right_link5"/>
    <axis xyz="0 1 0"/>
    <limit effort="14" lower="-1.832597" upper="1.832597" velocity="32.9867"/>
  </joint>
  <link name="right_link6">
    <inertial>
      <origin xyz="0.00709944781467154 1.26586535489642E-07 -3.8262881471296E-05"/>
      <mass value="0.031"/>
      <inertia ixx="3.44528457425794E-06" ixy="2.98138934982256E-11" ixz="-1.26128084918303E-09" iyy="1.82573408455416E-06" iyz="1.17092872453752E-14" izz="1.8173151968758E-06"/>
    </inertial>
    <visual>
      <geometry>
        <mesh filename="package://galaxea_a1_description/meshes/a1_xy/link6.obj"/>
      </geometry>
    </visual>
    <collision>
      <geometry>
        <mesh filename="package://galaxea_a1_description/meshes/a1_xy/link6.obj"/>
      </geometry>
    </collision>
  </link>
  <joint name="right_joint6" type="revolute">
    <origin xyz="0.081 -0.023499 0"/>
    <parent link="right_link5"/>
    <child link="right_link6"/>
    <axis xyz="1 0 0"/>
    <limit effort="14" lower="-2.879795" upper="2.879795" velocity="32.9867"/>
  </joint>
  <link name="right_gripper_base">
    <inertial>
      <origin xyz="-0.0311072323899603 1.17979991887118E-08 7.93394685505433E-08"/>
      <mass value="0.604"/>
      <inertia ixx="0.000175881544189539" ixy="-6.06026450851008E-11" ixz="5.30643405624365E-10" iyy="9.86379407701341E-05" iyz="-8.18686692495892E-08" izz="0.000165121280580029"/>
    </inertial>
    <visual>
      <geometry>
        <mesh filename="package://galaxea_a1_description/meshes/gripper/gripper_link.obj"/>
      </geometry>
    </visual>
    <collision>
      <geometry>
        <mesh filename="package://galaxea_a1_description/meshes/gripper/gripper_link.obj"/>
      </geometry>
    </collision>
  </link>
  <link name="right_finger1">
    <inertial>
      <origin xyz="-0.0195895895552112 -0.0151136845490034 0.00542254359093075"/>
      <mass value="0.027"/>
      <inertia ixx="2.40569358477209E-06" ixy="3.9898459609048E-07" ixz="5.12152762183641E-08" iyy="5.71079298307516E-06" iyz="6.19467902008363E-08" izz="6.48482183930358E-06"/>
    </inertial>
    <visual>
      <geometry>
        <mesh filename="package://galaxea_a1_description/meshes/gripper/finger.obj"/>
      </geometry>
    </visual>
    <collision>
      <geometry>
        <mesh filename="package://galaxea_a1_description/meshes/gripper/finger.obj"/>
      </geometry>
    </collision>
  </link>
  <joint name="right_gripper_joint" type="prismatic">
    <origin xyz="0.03689 0.013453 0.00012059"/>
    <parent link="right_gripper_base"/>
    <child link="right_finger1"/>
    <axis xyz="0 1 0"/>
    <limit effort="10" lower="0" upper="0.05" velocity="0.25"/>
  </joint>
  <link name="right_finger2">
    <inertial>
      <origin xyz="-0.0195895857999098 0.0151136893508115 -0.00542254357246619"/>
      <mass value="0.027"/>
      <inertia ixx="2.40569340151687E-06" ixy="-3.98983784827124E-07" ixz="-5.12152683073981E-08" iyy="5.71079321589929E-06" iyz="6.19467953006536E-08" izz="6.48482187274222E-06"/>
    </inertial>
    <visual>
      <geometry>
        <mesh filename="package://galaxea_a1_description/meshes/gripper/finger.obj" scale="1 -1 -1"/>
      </geometry>
    </visual>
    <collision>
      <geometry>
        <mesh filename="package://galaxea_a1_description/meshes/gripper/finger.obj" scale="1 -1 -1"/>
      </geometry>
    </collision>
  </link>
  <joint name="right_gripper_joint2" type="prismatic">
    <origin xyz="0.03689 -0.013453 -0.00012059"/>
    <parent link="right_gripper_base"/>
    <child link="right_finger2"/>
    <axis xyz="0 -1 0"/>
    <limit effort="10" lower="0" upper="0.05" velocity="0.25"/>
    <mimic joint="right_gripper_joint" multiplier="1" offset="0"/>
  </joint>
  <link name="right_gripper_center"/>
  <joint name="right_gripper_center_joint" type="fixed">
    <origin xyz="0.03689 0 -0.00012059"/>
    <parent link="right_gripper_base"/>
    <child link="right_gripper_center"/>
  </joint>
  <joint name="right_gripper_base_joint" type="fixed">
    <origin xyz="0.08165 0 0"/>
    <parent link="right_link6"/>
    <child link="right_gripper_base"/>
  </joint>
  <link name="right_camera_stand">
    <inertial>
      <origin xyz="0.00904707172594749 0.0155186578138565 -0.00819594831521042"/>
      <mass value="0.1"/>
      <inertia ixx="2.78082944930657E-05" ixy="-4.06196131154851E-10" ixz="1.50543456329152E-08" iyy="2.18951425070333E-05" iyz="-3.73269688187078E-06" izz="2.07706210423581E-05"/>
    </inertial>
    <visual>
      <geometry>
        <mesh filename="package://galaxea_r1lite_description/meshes/visual/camera_stand.obj"/>
      </geometry>
    </visual>
    <visual>
      <origin rpy="0 -1.5707963267948966 1.5707963267948966" xyz="0.008996 0 0"/>
      <geometry>
        <mesh filename="package://share/sensor_models/meshes/d405/d405.obj"/>
      </geometry>
    </visual>
    <collision>
      <geometry>
        <mesh filename="package://galaxea_r1lite_description/meshes/collision/camera.stl"/>
      </geometry>
    </collision>
  </link>
  <joint name="right_camera_stand_joint" type="fixed">
    <origin rpy="-2.268 0 -1.5707963267948966" xyz="-0.019206 0.009 0.074757"/>
    <parent link="right_gripper_base"/>
    <child link="right_camera_stand"/>
  </joint>
</robot>
