<?xml version="1.0" ?>
<!-- =================================================================================== -->
<!-- |    This document was autogenerated by xacro from xacro/robot.xacro              | -->
<!-- |    EDITING THIS FILE BY HAND IS NOT RECOMMENDED                                 | -->
<!-- =================================================================================== -->
<!-- =================================================================================== -->
<!-- |    Ai2 Bot2 Full Robot (visualization)                                           | -->
<!-- |    Used by robot_common_launch manipulator.launch.py (xacro_filename=robot.xacro)| -->
<!-- |    Structure : base_link (chassis) -> body ->                                    | -->
<!-- |    body_link4; ego and arms both attach to body_link4.                           | -->
<!-- =================================================================================== -->
<robot name="Ai2_Bot2">
  <!--
		Ai2-Bot2 chassis: base_link + driven wheels (fl/rl/fr/rr) + driving wheels (left/right).
		Use <xacro:Ai2Bot2Chassis/> then attach body to base_link.
	-->
  <!--
    Ai2-Bot2 body: lower-body chain (body_link1..3, body_joint1..3) + torso (waist_yaw_torso_link, body_joint4).
    Chain: parent_link -> body_link1 -> body_link2 -> body_link3 -> waist_yaw_torso_link.
    Use <xacro:Ai2Bot2Body parent_link="base_link"/> then attach head/arms to waist_yaw_torso_link.
  -->
  <!--
      Ai2-Bot2 arm: single parametric macro for left/right arms.
      Usage: <xacro:Ai2Bot2Arm name="left" parent_link="..." direction="1"/>
             <xacro:Ai2Bot2Arm name="right" parent_link="..." direction="-1"/>
      Links/joints use ${prefix}base_link, ${prefix}link1..8, ${prefix}joint0..8.
      Meshes use ZPF_left_* glb with scale="1 ${direction} 1"; set direction to -1 for mirror.
    -->
  <link name="base_footprint"/>
  <joint name="base_footprint_joint" type="fixed">
    <parent link="base_footprint"/>
    <child link="base_link"/>
  </joint>
  <link name="base_link">
    <inertial>
      <origin xyz="-0.026689 -0.0065193 0.14154"/>
      <mass value="64.788"/>
      <inertia ixx="0.346" ixy="0.00079709" ixz="-0.022691" iyy="0.65327" iyz="-6.4191E-05" izz="0.70449"/>
    </inertial>
    <visual>
      <geometry>
        <mesh filename="package://ai2_bot2_description/meshes/Visual/chassis/chassis.glb"/>
      </geometry>
    </visual>
    <collision>
      <origin xyz="0 0 0.1"/>
      <geometry>
        <box size="0.6 0.46 0.15"/>
      </geometry>
    </collision>
  </link>
  <!-- driven wheels: fl=front_left, rl=rear_left, fr=front_right, rr=rear_right; _v/_h = vertical/horizontal joint -->
  <link name="driven_fl_link_v">
    <visual>
      <geometry>
        <mesh filename="package://ai2_bot2_description/meshes/Visual/chassis/driven_v.glb"/>
      </geometry>
    </visual>
  </link>
  <joint name="driven_fl_joint_v" type="fixed">
    <origin xyz="0.215 0.15 0.085704"/>
    <parent link="base_link"/>
    <child link="driven_fl_link_v"/>
    <axis xyz="0 0 1"/>
    <limit effort="2000" velocity="10"/>
  </joint>
  <link name="driven_fl_link_h">
    <visual>
      <geometry>
        <mesh filename="package://ai2_bot2_description/meshes/Visual/chassis/driven_h.glb"/>
      </geometry>
    </visual>
    <collision>
      <geometry>
        <sphere radius="0.0375"/>
      </geometry>
    </collision>
  </link>
  <joint name="driven_fl_joint_h" type="fixed">
    <origin rpy="-1.5708 0 0" xyz="-0.016001 0 -0.0482"/>
    <parent link="driven_fl_link_v"/>
    <child link="driven_fl_link_h"/>
    <axis xyz="0 0 1"/>
    <limit effort="2000" velocity="10"/>
  </joint>
  <link name="driven_rl_link_v">
    <visual>
      <geometry>
        <mesh filename="package://ai2_bot2_description/meshes/Visual/chassis/driven_v.glb"/>
      </geometry>
    </visual>
  </link>
  <joint name="driven_rl_joint_v" type="fixed">
    <origin xyz="-0.215 0.15 0.085704"/>
    <parent link="base_link"/>
    <child link="driven_rl_link_v"/>
    <axis xyz="0 0 1"/>
    <limit effort="2000" velocity="10"/>
  </joint>
  <link name="driven_rl_link_h">
    <visual>
      <geometry>
        <mesh filename="package://ai2_bot2_description/meshes/Visual/chassis/driven_h.glb"/>
      </geometry>
    </visual>
    <collision>
      <geometry>
        <sphere radius="0.0375"/>
      </geometry>
    </collision>
  </link>
  <joint name="driven_rl_joint_h" type="fixed">
    <origin rpy="-1.5708 0 0" xyz="-0.016001 0 -0.0482"/>
    <parent link="driven_rl_link_v"/>
    <child link="driven_rl_link_h"/>
    <axis xyz="0 0 1"/>
    <limit effort="2000" velocity="10"/>
  </joint>
  <link name="driven_fr_link_v">
    <visual>
      <geometry>
        <mesh filename="package://ai2_bot2_description/meshes/Visual/chassis/driven_v.glb"/>
      </geometry>
    </visual>
  </link>
  <joint name="driven_fr_joint_v" type="fixed">
    <origin xyz="0.215 -0.15 0.085704"/>
    <parent link="base_link"/>
    <child link="driven_fr_link_v"/>
    <axis xyz="0 0 1"/>
    <limit effort="2000" velocity="10"/>
  </joint>
  <link name="driven_fr_link_h">
    <visual>
      <geometry>
        <mesh filename="package://ai2_bot2_description/meshes/Visual/chassis/driven_h.glb"/>
      </geometry>
    </visual>
    <collision>
      <geometry>
        <sphere radius="0.0375"/>
      </geometry>
    </collision>
  </link>
  <joint name="driven_fr_joint_h" type="fixed">
    <origin rpy="-1.5708 0 0" xyz="-0.016001 0 -0.0482"/>
    <parent link="driven_fr_link_v"/>
    <child link="driven_fr_link_h"/>
    <axis xyz="0 0 1"/>
    <limit effort="2000" velocity="10"/>
  </joint>
  <link name="driven_rr_link_v">
    <visual>
      <geometry>
        <mesh filename="package://ai2_bot2_description/meshes/Visual/chassis/driven_v.glb"/>
      </geometry>
    </visual>
  </link>
  <joint name="driven_rr_joint_v" type="fixed">
    <origin xyz="-0.215 -0.15 0.085704"/>
    <parent link="base_link"/>
    <child link="driven_rr_link_v"/>
    <axis xyz="0 0 1"/>
    <limit effort="2000" velocity="10"/>
  </joint>
  <link name="driven_rr_link_h">
    <visual>
      <geometry>
        <mesh filename="package://ai2_bot2_description/meshes/Visual/chassis/driven_h.glb"/>
      </geometry>
    </visual>
    <collision>
      <geometry>
        <sphere radius="0.0375"/>
      </geometry>
    </collision>
  </link>
  <joint name="driven_rr_joint_h" type="fixed">
    <origin rpy="-1.5708 0 0" xyz="-0.016001 0 -0.0482"/>
    <parent link="driven_rr_link_v"/>
    <child link="driven_rr_link_h"/>
    <axis xyz="0 0 1"/>
    <limit effort="2000" velocity="10"/>
  </joint>
  <link name="driving_left_link">
    <visual>
      <geometry>
        <mesh filename="package://aidal_description/meshes/woosh_agv/wheel.glb" scale="1 1 1"/>
      </geometry>
    </visual>
    <collision>
      <origin rpy="0 1.5708 0"/>
      <geometry>
        <cylinder length="0.034" radius="0.085"/>
      </geometry>
    </collision>
  </link>
  <joint name="driving_left_joint" type="fixed">
    <origin rpy="0 0 -1.5708" xyz="0 0.208 0.0845"/>
    <parent link="base_link"/>
    <child link="driving_left_link"/>
    <axis xyz="-1 0 0"/>
    <limit effort="2000" velocity="10"/>
  </joint>
  <link name="driving_right_link">
    <visual>
      <geometry>
        <mesh filename="package://aidal_description/meshes/woosh_agv/wheel.glb" scale="1 1 -1"/>
      </geometry>
    </visual>
    <collision>
      <origin rpy="0 1.5708 0"/>
      <geometry>
        <cylinder length="0.034" radius="0.085"/>
      </geometry>
    </collision>
  </link>
  <joint name="driving_right_joint" type="fixed">
    <origin rpy="0 0 -1.5708" xyz="0 -0.208 0.0845"/>
    <parent link="base_link"/>
    <child link="driving_right_link"/>
    <axis xyz="-1 0 0"/>
    <limit effort="2000" velocity="10"/>
  </joint>
  <link name="chassis_panel">
    <visual>
      <geometry>
        <mesh filename="package://aidal_description/meshes/woosh_agv/panel.glb"/>
      </geometry>
    </visual>
  </link>
  <joint name="chassis_panel_joint" type="fixed">
    <origin rpy="1.5708 -1.5708 0" xyz="-0.0524 0.1771 0.2463"/>
    <parent link="base_link"/>
    <child link="chassis_panel"/>
  </joint>
  <link name="charge_port">
    <visual>
      <geometry>
        <mesh filename="package://ai2_bot2_description/meshes/Visual/chassis/charge_port.glb"/>
      </geometry>
    </visual>
  </link>
  <joint name="charge_port" type="fixed">
    <origin xyz="0.283736 0 0.056555"/>
    <parent link="base_link"/>
    <child link="charge_port"/>
  </joint>
  <link name="lidar_link">
    <visual>
      <geometry>
        <mesh filename="package://sensor_models/meshes/orbbec/ms500.glb"/>
      </geometry>
    </visual>
  </link>
  <joint name="lidar_joint" type="fixed">
    <origin rpy="0 0 1.5708" xyz="0.260985 0 0.126476"/>
    <parent link="base_link"/>
    <child link="lidar_link"/>
  </joint>
  <link name="chassis_camera">
    <visual>
      <geometry>
        <mesh filename="package://sensor_models/meshes/orbbec/Dabai_DW.glb"/>
      </geometry>
    </visual>
  </link>
  <joint name="chassis_camera" type="fixed">
    <origin rpy="1.5708 0 1.5708" xyz="0.315 0 0.104"/>
    <parent link="base_link"/>
    <child link="chassis_camera"/>
  </joint>
  <!-- body_link1 (ankle/calf) -->
  <link name="body_link1">
    <inertial>
      <origin xyz="0.0040321 -0.3007 0.0026114"/>
      <mass value="8.2502"/>
      <inertia ixx="0.093386" ixy="-0.0049619" ixz="-0.00010259" iyy="0.019887" iyz="0.00015883" izz="0.090475"/>
    </inertial>
    <visual>
      <geometry>
        <mesh filename="package://ai2_bot2_description/meshes/Visual/body/link1.glb"/>
      </geometry>
    </visual>
    <collision>
      <geometry>
        <mesh filename="package://ai2_bot2_description/meshes/Visual/body/link1.glb"/>
      </geometry>
    </collision>
  </link>
  <joint name="body_joint1" type="revolute">
    <origin rpy="-1.5708 0 0" xyz="0.19155 0 0.294"/>
    <parent link="base_link"/>
    <child link="body_link1"/>
    <axis xyz="0 0 1"/>
    <limit effort="1000" lower="-1.1868" upper="0" velocity="10"/>
  </joint>
  <!-- body_link2 (knee/thigh) -->
  <link name="body_link2">
    <inertial>
      <origin xyz="-0.0065356 -0.15379 -0.0042654"/>
      <mass value="3.312"/>
      <inertia ixx="0.03805" ixy="-0.00010138" ixz="1.1661E-06" iyy="0.0070468" iyz="6.6081E-06" izz="0.041003"/>
    </inertial>
    <visual>
      <geometry>
        <mesh filename="package://ai2_bot2_description/meshes/Visual/body/link2.glb"/>
      </geometry>
    </visual>
    <collision>
      <geometry>
        <mesh filename="package://ai2_bot2_description/meshes/Visual/body/link2.glb"/>
      </geometry>
    </collision>
  </link>
  <joint name="body_joint2" type="revolute">
    <origin xyz="0 -0.38704 0"/>
    <parent link="body_link1"/>
    <child link="body_link2"/>
    <axis xyz="0 0 1"/>
    <limit effort="1000" lower="-0.38397" upper="2.7576" velocity="10"/>
  </joint>
  <!-- body_link3 (waist) -->
  <link name="body_link3">
    <inertial>
      <origin xyz="0.0057091 -0.043636 0.0033344"/>
      <mass value="5.6895"/>
      <inertia ixx="0.010503" ixy="0.00050418" ixz="1.2455E-05" iyy="0.0080802" iyz="-4.4802E-05" izz="0.011644"/>
    </inertial>
    <visual>
      <geometry>
        <mesh filename="package://ai2_bot2_description/meshes/Visual/body/link3.glb"/>
      </geometry>
    </visual>
    <collision>
      <geometry>
        <mesh filename="package://ai2_bot2_description/meshes/Visual/body/link3.glb"/>
      </geometry>
    </collision>
  </link>
  <joint name="body_joint3" type="revolute">
    <origin xyz="0 -0.27 0"/>
    <parent link="body_link2"/>
    <child link="body_link3"/>
    <axis xyz="0 0 1"/>
    <limit effort="1000" lower="-1.5708" upper="0.5236" velocity="10"/>
  </joint>
  <!-- waist_yaw_torso_link (torso, parent for head/arms) -->
  <link name="body_link4">
    <inertial>
      <origin xyz="-0.014346 4.4158E-06 0.20167"/>
      <mass value="4.6934"/>
      <inertia ixx="0.048256" ixy="-1.0989E-06" ixz="0.0042551" iyy="0.041609" iyz="1.1206E-07" izz="0.017837"/>
    </inertial>
    <visual>
      <geometry>
        <mesh filename="package://ai2_bot2_description/meshes/Visual/body/link4.glb"/>
      </geometry>
    </visual>
    <collision>
      <geometry>
        <mesh filename="package://ai2_bot2_description/meshes/Visual/body/link4.glb"/>
      </geometry>
    </collision>
  </link>
  <joint name="body_joint4" type="revolute">
    <origin rpy="1.5708 0 0" xyz="0 -0.1655 0"/>
    <parent link="body_link3"/>
    <child link="body_link4"/>
    <axis xyz="0 0 1"/>
    <limit effort="1000" lower="-1.5708" upper="1.5708" velocity="10"/>
  </joint>
  <link name="front_camera">
    <visual>
      <geometry>
        <mesh filename="package://sensor_models/meshes/d435/d435.obj"/>
      </geometry>
    </visual>
  </link>
  <joint name="front_camera" type="fixed">
    <origin rpy="0 0.38397 0" xyz="0.1067 0 0.1805"/>
    <parent link="body_link4"/>
    <child link="front_camera"/>
  </joint>
  <link name="back_camera">
    <visual>
      <geometry>
        <mesh filename="package://sensor_models/meshes/d435/d435.obj"/>
      </geometry>
    </visual>
  </link>
  <joint name="back_camera" type="fixed">
    <origin rpy="0 0.4887 3.14159" xyz="-0.1682 0 0.308"/>
    <parent link="body_link4"/>
    <child link="back_camera"/>
  </joint>
  <!-- head: head_link1 (neck), head_joint1, head_link2 (head), head_joint2 -->
  <link name="head_link1">
    <inertial>
      <origin xyz="-1.4269E-12 0.0053202 0.055582"/>
      <mass value="0.2237"/>
      <inertia ixx="8.9086E-05" ixy="2.4443E-15" ixz="5.7682E-20" iyy="6.5512E-05" iyz="3.0856E-06" izz="4.8068E-05"/>
    </inertial>
  </link>
  <joint name="head_joint1" type="revolute">
    <origin xyz="-0.041 0 0.46874"/>
    <parent link="body_link4"/>
    <child link="head_link1"/>
    <axis xyz="0 0 1"/>
    <limit effort="1000" lower="-1.5708" upper="1.5708" velocity="10"/>
  </joint>
  <link name="head_link2">
    <inertial>
      <origin xyz="0.028328 -0.035178 -0.00055178"/>
      <mass value="0.56733"/>
      <inertia ixx="0.0020659" ixy="-0.00054222" ixz="-7.9302E-07" iyy="0.0025822" iyz="-4.5882E-07" izz="0.002181"/>
    </inertial>
    <visual>
      <geometry>
        <mesh filename="package://ai2_bot2_description/meshes/Visual/body/head2.glb"/>
      </geometry>
    </visual>
    <collision>
      <geometry>
        <mesh filename="package://ai2_bot2_description/meshes/Visual/body/head2.glb"/>
      </geometry>
    </collision>
  </link>
  <joint name="head_joint2" type="revolute">
    <origin rpy="-1.5708 0 0" xyz="0 0 0.06"/>
    <parent link="head_link1"/>
    <child link="head_link2"/>
    <axis xyz="0 0 1"/>
    <limit effort="1000" lower="-0.4014" upper="0.38397" velocity="10"/>
  </joint>
  <link name="head_camera">
    <visual>
      <geometry>
        <mesh filename="package://sensor_models/meshes/d435/d435.obj"/>
      </geometry>
    </visual>
  </link>
  <joint name="head_camera" type="fixed">
    <origin rpy="1.5708 0 0.5236" xyz="0.089 0.0465 0"/>
    <parent link="head_link2"/>
    <child link="head_camera"/>
  </joint>
  <!-- ego frame (only in full robot; not used in component type=arms) -->
  <link name="ego"/>
  <joint name="ego_joint" type="fixed">
    <origin rpy="0 0 0" xyz="-0.061 0 0.3255"/>
    <parent link="body_link4"/>
    <child link="ego"/>
  </joint>
  <link name="left_base_link">
    <inertial>
      <origin xyz="1.7227967e-05 -2.7405976e-04 6.7417875e-02"/>
      <mass value="1.39"/>
      <inertia ixx="1.7468022e-03" ixy="4.4167244e-07" ixz="8.1232278e-07" iyy="1.7511135e-03" iyz="-1.7950155e-05" izz="1.1806738e-03"/>
    </inertial>
    <visual>
      <geometry>
        <mesh filename="package://ai2_bot2_description/meshes/Visual/arm/arm_base_link.glb" scale="1 1 1"/>
      </geometry>
      <material name="">
        <color rgba="0.86667 0.86667 0.8902 1"/>
      </material>
    </visual>
    <collision>
      <geometry>
        <mesh filename="package://ai2_bot2_description/meshes/Visual/arm/arm_base_link.glb" scale="1 1 1"/>
      </geometry>
    </collision>
  </link>
  <joint name="left_joint0" type="fixed">
    <origin rpy="-1.5708 -1.5708 0" xyz="-0.061 0.0485 0.3255"/>
    <parent link="body_link4"/>
    <child link="left_base_link"/>
    <axis xyz="0 0 0"/>
  </joint>
  <link name="left_link1">
    <inertial>
      <origin xyz="-1.1436e-3 -1.5043e-2 -3.0119e-2"/>
      <mass value="0.5885"/>
      <inertia ixx="1.6599262e-03" ixy="-6.1451353e-05" ixz="1.5137541e-04" iyy="1.5735435e-03" iyz="2.0085037e-04" izz="1.5710792e-03"/>
    </inertial>
    <visual>
      <geometry>
        <mesh filename="package://ai2_bot2_description/meshes/Visual/arm/link1.glb" scale="1 1 1"/>
      </geometry>
    </visual>
    <collision>
      <geometry>
        <mesh filename="package://ai2_bot2_description/meshes/Visual/arm/link1.glb" scale="1 1 1"/>
      </geometry>
    </collision>
  </link>
  <joint name="left_joint1" type="revolute">
    <origin xyz="0 0 0.1785"/>
    <parent link="left_base_link"/>
    <child link="left_link1"/>
    <axis xyz="0 0 1"/>
    <limit effort="60" lower="-3.1" upper="3.1" velocity="3.14"/>
  </joint>
  <link name="left_link2">
    <inertial>
      <origin xyz="1.255e-4 -6.489e-3 -1.5096e-2"/>
      <mass value="1.37"/>
      <inertia ixx="1.7992218e-03" ixy="-1.1620208e-06" ixz="-3.9132877e-06" iyy="1.2916690e-03" iyz="1.1836315e-04" izz="1.5723054e-03"/>
    </inertial>
    <visual>
      <geometry>
        <mesh filename="package://ai2_bot2_description/meshes/Visual/arm/link2.glb" scale="1 1 1"/>
      </geometry>
    </visual>
    <collision>
      <geometry>
        <mesh filename="package://ai2_bot2_description/meshes/Visual/arm/link2.glb" scale="1 1 1"/>
      </geometry>
    </collision>
  </link>
  <joint name="left_joint2" type="revolute">
    <origin rpy="-1.5708 -1.5708 0" xyz="0 0 0"/>
    <parent link="left_link1"/>
    <child link="left_link2"/>
    <axis xyz="0 0 1"/>
    <limit effort="60" lower="-0.44" upper="3.1" velocity="3.14"/>
  </joint>
  <link name="left_link3">
    <inertial>
      <origin xyz="4.7568e-3 3.1731e-3 -9.229e-2"/>
      <mass value="2.29"/>
      <inertia ixx="3.7492999e-02" ixy="-6.5328616e-05" ixz="6.1380090e-05" iyy="3.7362685e-02" iyz="-5.4729831e-05" izz="1.8817538e-03"/>
    </inertial>
    <visual>
      <geometry>
        <mesh filename="package://ai2_bot2_description/meshes/Visual/arm/link3.glb" scale="1 1 1"/>
      </geometry>
    </visual>
    <collision>
      <geometry>
        <mesh filename="package://ai2_bot2_description/meshes/Visual/arm/link3.glb" scale="1 1 1"/>
      </geometry>
    </collision>
  </link>
  <joint name="left_joint3" type="revolute">
    <origin rpy="1.5708 -1.5708 0" xyz="0 -0.28998 0"/>
    <parent link="left_link2"/>
    <child link="left_link3"/>
    <axis xyz="0 0 1"/>
    <limit effort="30" lower="-3.1" upper="3.1" velocity="3.14"/>
  </joint>
  <link name="left_link4">
    <inertial>
      <origin xyz="-9.542e-3 8.999e-2 -4.374e-3"/>
      <mass value="0.82"/>
      <inertia ixx="2.8633804e-03" ixy="-2.9024436e-05" ixz="2.8630445e-05" iyy="7.2655797e-04" iyz="-2.4077951e-04" izz="2.7356732e-03"/>
    </inertial>
    <visual>
      <geometry>
        <mesh filename="package://ai2_bot2_description/meshes/Visual/arm/link4.glb" scale="1 1 1"/>
      </geometry>
    </visual>
    <collision>
      <geometry>
        <mesh filename="package://ai2_bot2_description/meshes/Visual/arm/link4.glb" scale="1 1 1"/>
      </geometry>
    </collision>
  </link>
  <joint name="left_joint4" type="revolute">
    <origin rpy="1.5708 0 0" xyz="0.01 0 0"/>
    <parent link="left_link3"/>
    <child link="left_link4"/>
    <axis xyz="0 0 1"/>
    <limit effort="30" lower="-2.27" upper="0" velocity="3.14"/>
  </joint>
  <link name="left_link5">
    <inertial>
      <origin xyz="-2.3965e-5 -2.247e-2 -8.5293e-2"/>
      <mass value="1.017"/>
      <inertia ixx="2.2579574e-03" ixy="2.0270009e-07" ixz="3.2535431e-08" iyy="2.0417531e-03" iyz="3.7131069e-04" izz="9.5194483e-04"/>
    </inertial>
    <visual>
      <geometry>
        <mesh filename="package://ai2_bot2_description/meshes/Visual/arm/link5.glb" scale="1 1 1"/>
      </geometry>
    </visual>
    <collision>
      <geometry>
        <mesh filename="package://ai2_bot2_description/meshes/Visual/arm/link5.glb" scale="1 1 1"/>
      </geometry>
    </collision>
  </link>
  <joint name="left_joint5" type="revolute">
    <origin rpy="-1.5708 0 0" xyz="-0.01 0.3088 0"/>
    <parent link="left_link4"/>
    <child link="left_link5"/>
    <axis xyz="0 0 1"/>
    <limit effort="10" lower="-3.1" upper="3.1" velocity="3.14"/>
  </joint>
  <link name="left_link6">
    <inertial>
      <origin xyz="9.154e-3 -8.103e-3 2.957e-3"/>
      <mass value="0.55"/>
      <inertia ixx="3.7382788e-04" ixy="3.1477249e-06" ixz="1.5645983e-05" iyy="2.7467239e-04" iyz="-1.1682175e-05" izz="3.2231106e-04"/>
    </inertial>
    <visual>
      <geometry>
        <mesh filename="package://ai2_bot2_description/meshes/Visual/arm/link6.glb" scale="1 1 1"/>
      </geometry>
    </visual>
    <collision>
      <geometry>
        <mesh filename="package://ai2_bot2_description/meshes/Visual/arm/link6.glb" scale="1 1 1"/>
      </geometry>
    </collision>
  </link>
  <joint name="left_joint6" type="revolute">
    <origin rpy="1.5708 -1.5708 0" xyz="0 0 0"/>
    <parent link="left_link5"/>
    <child link="left_link6"/>
    <axis xyz="0 0 1"/>
    <limit effort="10" lower="-1.22" upper="1.22" velocity="3.14"/>
  </joint>
  <link name="left_link7">
    <inertial>
      <origin xyz="1.547e-4 5.483e-2 5.55e-3"/>
      <mass value="0.266"/>
      <inertia ixx="0.000132576941913423" ixy="9.13805899339808E-06" ixz="-9.14363365511958E-08" iyy="0.000151676252224174" iyz="-2.82790388376229E-05" izz="0.000142517590749322"/>
    </inertial>
    <visual>
      <geometry>
        <mesh filename="package://ai2_bot2_description/meshes/Visual/arm/link7.glb" scale="1 1 1"/>
      </geometry>
    </visual>
    <collision>
      <geometry>
        <mesh filename="package://ai2_bot2_description/meshes/Visual/arm/link7.glb" scale="1 1 1"/>
      </geometry>
    </collision>
  </link>
  <joint name="left_joint7" type="revolute">
    <origin rpy="1.5708 -1.5708 0" xyz="0.01 0 0"/>
    <parent link="left_link6"/>
    <child link="left_link7"/>
    <axis xyz="0 0 1"/>
    <limit effort="10" lower="-2.09" upper="0.49" velocity="3.14"/>
  </joint>
  <link name="left_link8">
    <inertial>
      <origin xyz="-0.000223537609806423 8.8367558294447E-05 -0.0171573759779855"/>
      <mass value="0.165822774021484"/>
      <inertia ixx="4.88486899397696E-05" ixy="-9.4591722796062E-08" ixz="3.0611887075293E-07" iyy="4.94603620572993E-05" iyz="8.02154219939052E-09" izz="7.6901626133018E-05"/>
    </inertial>
    <visual>
      <origin xyz="-0.033 -0.0085 0.01562"/>
      <geometry>
        <mesh filename="package://rm75_description/meshes/ee/camera_stand_d405.glb"/>
      </geometry>
    </visual>
    <visual>
      <geometry>
        <mesh filename="package://rm75_description/meshes/ee/ee_fb_camera.glb"/>
      </geometry>
    </visual>
    <visual>
      <origin rpy="0 0 3.1415" xyz="-0.13322 -0.0005 0.044651"/>
      <geometry>
        <mesh filename="package://sensor_models/meshes/realsense/d405.glb"/>
      </geometry>
    </visual>
  </link>
  <joint name="left_joint8" type="fixed">
    <origin rpy="1.5708 3.1415926 0" xyz="0 -0.04512 0"/>
    <parent link="left_link7"/>
    <child link="left_link8"/>
    <axis xyz="0 0 -1"/>
    <limit effort="0" lower="0" upper="0" velocity="0"/>
  </joint>
  <link name="left_ee"/>
  <joint name="left_ee_joint" type="fixed">
    <origin xyz="0 0 0.0695"/>
    <parent link="left_link8"/>
    <child link="left_ee"/>
  </joint>
  <link name="right_base_link">
    <inertial>
      <origin xyz="1.7227967e-05 2.7405976e-04 6.7417875e-02"/>
      <mass value="1.39"/>
      <inertia ixx="1.7468022e-03" ixy="4.4167244e-07" ixz="8.1232278e-07" iyy="1.7511135e-03" iyz="-1.7950155e-05" izz="1.1806738e-03"/>
    </inertial>
    <visual>
      <geometry>
        <mesh filename="package://ai2_bot2_description/meshes/Visual/arm/arm_base_link.glb" scale="1 -1 1"/>
      </geometry>
      <material name="">
        <color rgba="0.86667 0.86667 0.8902 1"/>
      </material>
    </visual>
    <collision>
      <geometry>
        <mesh filename="package://ai2_bot2_description/meshes/Visual/arm/arm_base_link.glb" scale="1 -1 1"/>
      </geometry>
    </collision>
  </link>
  <joint name="right_joint0" type="fixed">
    <origin rpy="1.5708 -1.5708 0" xyz="-0.061 -0.0485 0.3255"/>
    <parent link="body_link4"/>
    <child link="right_base_link"/>
    <axis xyz="0 0 0"/>
  </joint>
  <link name="right_link1">
    <inertial>
      <origin xyz="-1.1436e-3 1.5043e-2 -3.0119e-2"/>
      <mass value="0.5885"/>
      <inertia ixx="1.6599262e-03" ixy="-6.1451353e-05" ixz="1.5137541e-04" iyy="1.5735435e-03" iyz="2.0085037e-04" izz="1.5710792e-03"/>
    </inertial>
    <visual>
      <geometry>
        <mesh filename="package://ai2_bot2_description/meshes/Visual/arm/link1.glb" scale="1 -1 1"/>
      </geometry>
    </visual>
    <collision>
      <geometry>
        <mesh filename="package://ai2_bot2_description/meshes/Visual/arm/link1.glb" scale="1 -1 1"/>
      </geometry>
    </collision>
  </link>
  <joint name="right_joint1" type="revolute">
    <origin xyz="0 0 0.1785"/>
    <parent link="right_base_link"/>
    <child link="right_link1"/>
    <axis xyz="0 0 1"/>
    <limit effort="60" lower="-3.1" upper="3.1" velocity="3.14"/>
  </joint>
  <link name="right_link2">
    <inertial>
      <origin xyz="1.255e-4 -6.489e-3 1.5096e-2"/>
      <mass value="1.37"/>
      <inertia ixx="1.7992218e-03" ixy="-1.1620208e-06" ixz="-3.9132877e-06" iyy="1.2916690e-03" iyz="1.1836315e-04" izz="1.5723054e-03"/>
    </inertial>
    <visual>
      <geometry>
        <mesh filename="package://ai2_bot2_description/meshes/Visual/arm/link2.glb" scale="1 1 -1"/>
      </geometry>
    </visual>
    <collision>
      <geometry>
        <mesh filename="package://ai2_bot2_description/meshes/Visual/arm/link2.glb" scale="1 1 -1"/>
      </geometry>
    </collision>
  </link>
  <joint name="right_joint2" type="revolute">
    <origin rpy="-1.5708 -1.5708 0" xyz="0 0 0"/>
    <parent link="right_link1"/>
    <child link="right_link2"/>
    <axis xyz="0 0 1"/>
    <limit effort="60" lower="-0.44" upper="3.1" velocity="3.14"/>
  </joint>
  <link name="right_link3">
    <inertial>
      <origin xyz="-4.7568e-3 3.1731e-3 -9.229e-2"/>
      <mass value="2.29"/>
      <inertia ixx="3.7492999e-02" ixy="-6.5328616e-05" ixz="6.1380090e-05" iyy="3.7362685e-02" iyz="-5.4729831e-05" izz="1.8817538e-03"/>
    </inertial>
    <visual>
      <geometry>
        <mesh filename="package://ai2_bot2_description/meshes/Visual/arm/link3.glb" scale="-1 1 1"/>
      </geometry>
    </visual>
    <collision>
      <geometry>
        <mesh filename="package://ai2_bot2_description/meshes/Visual/arm/link3.glb" scale="-1 1 1"/>
      </geometry>
    </collision>
  </link>
  <joint name="right_joint3" type="revolute">
    <origin rpy="1.5708 -1.5708 0" xyz="0 -0.28998 0"/>
    <parent link="right_link2"/>
    <child link="right_link3"/>
    <axis xyz="0 0 -1"/>
    <limit effort="30" lower="-3.1" upper="3.1" velocity="3.14"/>
  </joint>
  <link name="right_link4">
    <inertial>
      <origin xyz="9.542e-3 8.999e-2 -4.374e-3"/>
      <mass value="0.82"/>
      <inertia ixx="2.8633804e-03" ixy="-2.9024436e-05" ixz="2.8630445e-05" iyy="7.2655797e-04" iyz="-2.4077951e-04" izz="2.7356732e-03"/>
    </inertial>
    <visual>
      <geometry>
        <mesh filename="package://ai2_bot2_description/meshes/Visual/arm/link4.glb" scale="-1 1 1"/>
      </geometry>
    </visual>
    <collision>
      <geometry>
        <mesh filename="package://ai2_bot2_description/meshes/Visual/arm/link4.glb" scale="-1 1 1"/>
      </geometry>
    </collision>
  </link>
  <joint name="right_joint4" type="revolute">
    <origin rpy="1.5708 0 0" xyz="-0.01 0 0"/>
    <parent link="right_link3"/>
    <child link="right_link4"/>
    <axis xyz="0 0 -1"/>
    <limit effort="30" lower="-2.27" upper="0" velocity="3.14"/>
  </joint>
  <link name="right_link5">
    <inertial>
      <origin xyz="2.3965e-5 -2.247e-2 -8.5293e-2"/>
      <mass value="1.017"/>
      <inertia ixx="2.2579574e-03" ixy="2.0270009e-07" ixz="3.2535431e-08" iyy="2.0417531e-03" iyz="3.7131069e-04" izz="9.5194483e-04"/>
    </inertial>
    <visual>
      <geometry>
        <mesh filename="package://ai2_bot2_description/meshes/Visual/arm/link5.glb" scale="-1 1 1"/>
      </geometry>
    </visual>
    <collision>
      <geometry>
        <mesh filename="package://ai2_bot2_description/meshes/Visual/arm/link5.glb" scale="-1 1 1"/>
      </geometry>
    </collision>
  </link>
  <joint name="right_joint5" type="revolute">
    <origin rpy="-1.5708 0 0" xyz="0.01 0.3088 0"/>
    <parent link="right_link4"/>
    <child link="right_link5"/>
    <axis xyz="0 0 -1"/>
    <limit effort="10" lower="-3.1" upper="3.1" velocity="3.14"/>
  </joint>
  <link name="right_link6">
    <inertial>
      <origin xyz="9.154e-3 8.103e-3 2.957e-3"/>
      <mass value="0.55"/>
      <inertia ixx="3.7382788e-04" ixy="3.1477249e-06" ixz="1.5645983e-05" iyy="2.7467239e-04" iyz="-1.1682175e-05" izz="3.2231106e-04"/>
    </inertial>
    <visual>
      <geometry>
        <mesh filename="package://ai2_bot2_description/meshes/Visual/arm/link6.glb" scale="1 -1 1"/>
      </geometry>
    </visual>
    <collision>
      <geometry>
        <mesh filename="package://ai2_bot2_description/meshes/Visual/arm/link6.glb" scale="1 -1 1"/>
      </geometry>
    </collision>
  </link>
  <joint name="right_joint6" type="revolute">
    <origin rpy="1.5708 -1.5708 0" xyz="0 0 0"/>
    <parent link="right_link5"/>
    <child link="right_link6"/>
    <axis xyz="0 0 -1"/>
    <limit effort="10" lower="-1.22" upper="1.22" velocity="3.14"/>
  </joint>
  <link name="right_link7">
    <inertial>
      <origin xyz="1.547e-4 5.483e-2 -5.55e-3"/>
      <mass value="0.266"/>
      <inertia ixx="0.000132576941913423" ixy="9.13805899339808E-06" ixz="-9.14363365511958E-08" iyy="0.000151676252224174" iyz="-2.82790388376229E-05" izz="0.000142517590749322"/>
    </inertial>
    <visual>
      <geometry>
        <mesh filename="package://ai2_bot2_description/meshes/Visual/arm/link7.glb" scale="1 1 -1"/>
      </geometry>
    </visual>
    <collision>
      <geometry>
        <mesh filename="package://ai2_bot2_description/meshes/Visual/arm/link7.glb" scale="1 1 -1"/>
      </geometry>
    </collision>
  </link>
  <joint name="right_joint7" type="revolute">
    <origin rpy="1.5708 -1.5708 0" xyz="0.01 0 0"/>
    <parent link="right_link6"/>
    <child link="right_link7"/>
    <axis xyz="0 0 1"/>
    <limit effort="10" lower="-2.09" upper="0.49" velocity="3.14"/>
  </joint>
  <link name="right_link8">
    <inertial>
      <origin xyz="0.000223537609806423 8.8367558294447E-05 -0.0171573759779855"/>
      <mass value="0.165822774021484"/>
      <inertia ixx="4.88486899397696E-05" ixy="-9.4591722796062E-08" ixz="3.0611887075293E-07" iyy="4.94603620572993E-05" iyz="8.02154219939052E-09" izz="7.6901626133018E-05"/>
    </inertial>
    <visual>
      <origin xyz="-0.033 -0.0085 0.01562"/>
      <geometry>
        <mesh filename="package://rm75_description/meshes/ee/camera_stand_d405.glb"/>
      </geometry>
    </visual>
    <visual>
      <geometry>
        <mesh filename="package://rm75_description/meshes/ee/ee_fb_camera.glb"/>
      </geometry>
    </visual>
    <visual>
      <origin rpy="0 0 3.1415" xyz="-0.13322 -0.0005 0.044651"/>
      <geometry>
        <mesh filename="package://sensor_models/meshes/realsense/d405.glb"/>
      </geometry>
    </visual>
  </link>
  <joint name="right_joint8" type="fixed">
    <origin rpy="1.5708 3.1415926 0" xyz="0 -0.04512 0"/>
    <parent link="right_link7"/>
    <child link="right_link8"/>
    <axis xyz="0 0 -1"/>
    <limit effort="0" lower="0" upper="0" velocity="0"/>
  </joint>
  <link name="right_ee"/>
  <joint name="right_ee_joint" type="fixed">
    <origin xyz="0 0 0.0695"/>
    <parent link="right_link8"/>
    <child link="right_ee"/>
  </joint>
  <link name="left_gripper_base">
    <inertial>
      <origin xyz="1.5645E-05 -4.1838E-06 0.038"/>
      <mass value="0.072633"/>
      <inertia ixx="5.095E-05" ixy="-7.3167E-13" ixz="2.0229E-08" iyy="6.0883E-05" iyz="-4.5583E-09" izz="1.933E-05"/>
    </inertial>
    <visual>
      <geometry>
        <mesh filename="package://inspire_description/meshes/EG2-4C2/baselink.obj"/>
      </geometry>
    </visual>
    <collision>
      <geometry>
        <mesh filename="package://inspire_description/meshes/EG2-4C2/baselink.obj"/>
      </geometry>
    </collision>
  </link>
  <link name="left_left_outer_link">
    <inertial>
      <origin xyz="0.0087669 0.009 0.013992"/>
      <mass value="0.0024292"/>
      <inertia ixx="5.1061E-07" ixy="-8.6739E-19" ixz="-2.508E-07" iyy="5.7398E-07" iyz="-1.3667E-18" izz="2.6747E-07"/>
    </inertial>
    <visual>
      <geometry>
        <mesh filename="package://inspire_description/meshes/EG2-4C2/outer_link.obj"/>
      </geometry>
    </visual>
    <collision>
      <geometry>
        <mesh filename="package://inspire_description/meshes/EG2-4C2/outer_link.obj"/>
      </geometry>
    </collision>
  </link>
  <joint name="left_gripper_joint" type="revolute">
    <origin xyz="-0.04 -0.009 0.079"/>
    <parent link="left_gripper_base"/>
    <child link="left_left_outer_link"/>
    <axis xyz="0 -1 0"/>
    <limit effort="50" lower="0" upper="0.82" velocity="3.141592653589793"/>
  </joint>
  <link name="left_left_inner_link">
    <inertial>
      <origin xyz="0.0087435 0.009 0.013955"/>
      <mass value="0.0038971"/>
      <inertia ixx="5.6941E-07" ixy="-1.0711E-18" ixz="-2.6891E-07" iyy="6.2305E-07" iyz="-1.6845E-18" izz="3.0871E-07"/>
    </inertial>
    <visual>
      <geometry>
        <mesh filename="package://inspire_description/meshes/EG2-4C2/inner_link.obj"/>
      </geometry>
    </visual>
    <collision>
      <geometry>
        <mesh filename="package://inspire_description/meshes/EG2-4C2/inner_link.obj"/>
      </geometry>
    </collision>
  </link>
  <joint name="left_left_inner_joint" type="revolute">
    <origin xyz="-0.03 -0.009 0.081"/>
    <parent link="left_gripper_base"/>
    <child link="left_left_inner_link"/>
    <axis xyz="0 -1 0"/>
    <limit effort="50" lower="0" upper="0.82" velocity="3.141592653589793"/>
    <mimic joint="left_gripper_joint"/>
  </joint>
  <link name="left_right_inner_link">
    <inertial>
      <origin xyz="-0.0087435 0.009 0.013955"/>
      <mass value="0.0038971"/>
      <inertia ixx="5.6941E-07" ixy="1.0666E-18" ixz="2.6891E-07" iyy="6.2305E-07" iyz="-1.8084E-18" izz="3.0871E-07"/>
    </inertial>
    <visual>
      <geometry>
        <mesh filename="package://inspire_description/meshes/EG2-4C2/inner_link.obj" scale="-1 1 1"/>
      </geometry>
    </visual>
    <collision>
      <geometry>
        <mesh filename="package://inspire_description/meshes/EG2-4C2/inner_link.obj" scale="-1 1 1"/>
      </geometry>
    </collision>
  </link>
  <joint name="left_right_inner_joint" type="revolute">
    <origin xyz="0.03 -0.009 0.081"/>
    <parent link="left_gripper_base"/>
    <child link="left_right_inner_link"/>
    <axis xyz="0 1 0"/>
    <limit effort="50" lower="0" upper="0.82" velocity="3.141592653589793"/>
    <mimic joint="left_gripper_joint" multiplier="1" offset="0"/>
  </joint>
  <link name="left_right_outer_link">
    <inertial>
      <origin xyz="-0.0087669 0.009 0.013992"/>
      <mass value="0.0024292"/>
      <inertia ixx="5.1061E-07" ixy="-9.5279E-19" ixz="2.508E-07" iyy="5.7398E-07" iyz="7.6863E-19" izz="2.6747E-07"/>
    </inertial>
    <visual>
      <geometry>
        <mesh filename="package://inspire_description/meshes/EG2-4C2/outer_link.obj" scale="-1 1 1"/>
      </geometry>
    </visual>
    <collision>
      <geometry>
        <mesh filename="package://inspire_description/meshes/EG2-4C2/outer_link.obj" scale="-1 1 1"/>
      </geometry>
    </collision>
  </link>
  <joint name="left_right_outer_joint" type="revolute">
    <origin xyz="0.04 -0.009 0.079"/>
    <parent link="left_gripper_base"/>
    <child link="left_right_outer_link"/>
    <axis xyz="0 1 0"/>
    <limit effort="50" lower="0" upper="0.82" velocity="3.141592653589793"/>
    <mimic joint="left_gripper_joint" multiplier="1" offset="0"/>
  </joint>
  <link name="left_left_pad">
    <inertial>
      <origin xyz="0.011864 0.006 0.011367"/>
      <mass value="0.0045068"/>
      <inertia ixx="5.1288E-07" ixy="-9.8137E-14" ixz="-9.4703E-08" iyy="5.3203E-07" iyz="-6.212E-14" izz="2.009E-07"/>
    </inertial>
    <visual>
      <geometry>
        <mesh filename="package://inspire_description/meshes/EG2-4C2/pad.obj"/>
      </geometry>
    </visual>
    <collision>
      <geometry>
        <mesh filename="package://inspire_description/meshes/EG2-4C2/pad.obj"/>
      </geometry>
    </collision>
  </link>
  <joint name="left_left_pad_joint" type="revolute">
    <origin xyz="0.0223 0.003 0.035591"/>
    <parent link="left_left_outer_link"/>
    <child link="left_left_pad"/>
    <axis xyz="0 1 0"/>
    <limit effort="50" lower="0" upper="0.82" velocity="3.141592653589793"/>
    <mimic joint="left_gripper_joint" multiplier="1" offset="0"/>
  </joint>
  <link name="left_right_pad">
    <inertial>
      <origin xyz="-0.011864 0.006 0.011367"/>
      <mass value="0.0045068"/>
      <inertia ixx="5.1288E-07" ixy="-9.8137E-14" ixz="9.4703E-08" iyy="5.3203E-07" iyz="6.2119E-14" izz="2.009E-07"/>
    </inertial>
    <visual>
      <geometry>
        <mesh filename="package://inspire_description/meshes/EG2-4C2/pad.obj" scale="-1 1 1"/>
      </geometry>
    </visual>
    <collision>
      <geometry>
        <mesh filename="package://inspire_description/meshes/EG2-4C2/pad.obj" scale="-1 1 1"/>
      </geometry>
    </collision>
  </link>
  <joint name="left_right_pad_joint" type="revolute">
    <origin xyz="-0.0223 0.003 0.035591"/>
    <parent link="left_right_outer_link"/>
    <child link="left_right_pad"/>
    <axis xyz="0 -1 0"/>
    <limit effort="50" lower="0" upper="0.82" velocity="3.141592653589793"/>
    <mimic joint="left_gripper_joint" multiplier="1" offset="0"/>
  </joint>
  <link name="left_eef"/>
  <joint name="left_eef_joint" type="fixed">
    <parent link="left_gripper_base"/>
    <child link="left_eef"/>
    <origin xyz="0 0 0.14"/>
  </joint>
  <!-- Tool-Center-Point: midpoint between the two pads when fully closed.
         z = 0.079 (outer-link) + 0.036 (pad joint) + 0.015 (pad contact face) ≈ 0.13 m.
         Adjust xyz z-value if the OCS2 marker does not sit at the actual grip point. -->
  <link name="left_gripper_tcp"/>
  <joint name="left_gripper_tcp_joint" type="fixed">
    <origin rpy="0 0 0" xyz="0 0 0.13"/>
    <parent link="left_gripper_base"/>
    <child link="left_gripper_tcp"/>
  </joint>
  <joint name="left_gripper_mount" type="fixed">
    <parent link="left_ee"/>
    <child link="left_gripper_base"/>
    <origin rpy="0 0 1.5708" xyz="0 0 0"/>
  </joint>
  <link name="right_gripper_base">
    <inertial>
      <origin xyz="1.5645E-05 -4.1838E-06 0.038"/>
      <mass value="0.072633"/>
      <inertia ixx="5.095E-05" ixy="-7.3167E-13" ixz="2.0229E-08" iyy="6.0883E-05" iyz="-4.5583E-09" izz="1.933E-05"/>
    </inertial>
    <visual>
      <geometry>
        <mesh filename="package://inspire_description/meshes/EG2-4C2/baselink.obj"/>
      </geometry>
    </visual>
    <collision>
      <geometry>
        <mesh filename="package://inspire_description/meshes/EG2-4C2/baselink.obj"/>
      </geometry>
    </collision>
  </link>
  <link name="right_left_outer_link">
    <inertial>
      <origin xyz="0.0087669 0.009 0.013992"/>
      <mass value="0.0024292"/>
      <inertia ixx="5.1061E-07" ixy="-8.6739E-19" ixz="-2.508E-07" iyy="5.7398E-07" iyz="-1.3667E-18" izz="2.6747E-07"/>
    </inertial>
    <visual>
      <geometry>
        <mesh filename="package://inspire_description/meshes/EG2-4C2/outer_link.obj"/>
      </geometry>
    </visual>
    <collision>
      <geometry>
        <mesh filename="package://inspire_description/meshes/EG2-4C2/outer_link.obj"/>
      </geometry>
    </collision>
  </link>
  <joint name="right_gripper_joint" type="revolute">
    <origin xyz="-0.04 -0.009 0.079"/>
    <parent link="right_gripper_base"/>
    <child link="right_left_outer_link"/>
    <axis xyz="0 -1 0"/>
    <limit effort="50" lower="0" upper="0.82" velocity="3.141592653589793"/>
  </joint>
  <link name="right_left_inner_link">
    <inertial>
      <origin xyz="0.0087435 0.009 0.013955"/>
      <mass value="0.0038971"/>
      <inertia ixx="5.6941E-07" ixy="-1.0711E-18" ixz="-2.6891E-07" iyy="6.2305E-07" iyz="-1.6845E-18" izz="3.0871E-07"/>
    </inertial>
    <visual>
      <geometry>
        <mesh filename="package://inspire_description/meshes/EG2-4C2/inner_link.obj"/>
      </geometry>
    </visual>
    <collision>
      <geometry>
        <mesh filename="package://inspire_description/meshes/EG2-4C2/inner_link.obj"/>
      </geometry>
    </collision>
  </link>
  <joint name="right_left_inner_joint" type="revolute">
    <origin xyz="-0.03 -0.009 0.081"/>
    <parent link="right_gripper_base"/>
    <child link="right_left_inner_link"/>
    <axis xyz="0 -1 0"/>
    <limit effort="50" lower="0" upper="0.82" velocity="3.141592653589793"/>
    <mimic joint="right_gripper_joint"/>
  </joint>
  <link name="right_right_inner_link">
    <inertial>
      <origin xyz="-0.0087435 0.009 0.013955"/>
      <mass value="0.0038971"/>
      <inertia ixx="5.6941E-07" ixy="1.0666E-18" ixz="2.6891E-07" iyy="6.2305E-07" iyz="-1.8084E-18" izz="3.0871E-07"/>
    </inertial>
    <visual>
      <geometry>
        <mesh filename="package://inspire_description/meshes/EG2-4C2/inner_link.obj" scale="-1 1 1"/>
      </geometry>
    </visual>
    <collision>
      <geometry>
        <mesh filename="package://inspire_description/meshes/EG2-4C2/inner_link.obj" scale="-1 1 1"/>
      </geometry>
    </collision>
  </link>
  <joint name="right_right_inner_joint" type="revolute">
    <origin xyz="0.03 -0.009 0.081"/>
    <parent link="right_gripper_base"/>
    <child link="right_right_inner_link"/>
    <axis xyz="0 1 0"/>
    <limit effort="50" lower="0" upper="0.82" velocity="3.141592653589793"/>
    <mimic joint="right_gripper_joint" multiplier="1" offset="0"/>
  </joint>
  <link name="right_right_outer_link">
    <inertial>
      <origin xyz="-0.0087669 0.009 0.013992"/>
      <mass value="0.0024292"/>
      <inertia ixx="5.1061E-07" ixy="-9.5279E-19" ixz="2.508E-07" iyy="5.7398E-07" iyz="7.6863E-19" izz="2.6747E-07"/>
    </inertial>
    <visual>
      <geometry>
        <mesh filename="package://inspire_description/meshes/EG2-4C2/outer_link.obj" scale="-1 1 1"/>
      </geometry>
    </visual>
    <collision>
      <geometry>
        <mesh filename="package://inspire_description/meshes/EG2-4C2/outer_link.obj" scale="-1 1 1"/>
      </geometry>
    </collision>
  </link>
  <joint name="right_right_outer_joint" type="revolute">
    <origin xyz="0.04 -0.009 0.079"/>
    <parent link="right_gripper_base"/>
    <child link="right_right_outer_link"/>
    <axis xyz="0 1 0"/>
    <limit effort="50" lower="0" upper="0.82" velocity="3.141592653589793"/>
    <mimic joint="right_gripper_joint" multiplier="1" offset="0"/>
  </joint>
  <link name="right_left_pad">
    <inertial>
      <origin xyz="0.011864 0.006 0.011367"/>
      <mass value="0.0045068"/>
      <inertia ixx="5.1288E-07" ixy="-9.8137E-14" ixz="-9.4703E-08" iyy="5.3203E-07" iyz="-6.212E-14" izz="2.009E-07"/>
    </inertial>
    <visual>
      <geometry>
        <mesh filename="package://inspire_description/meshes/EG2-4C2/pad.obj"/>
      </geometry>
    </visual>
    <collision>
      <geometry>
        <mesh filename="package://inspire_description/meshes/EG2-4C2/pad.obj"/>
      </geometry>
    </collision>
  </link>
  <joint name="right_left_pad_joint" type="revolute">
    <origin xyz="0.0223 0.003 0.035591"/>
    <parent link="right_left_outer_link"/>
    <child link="right_left_pad"/>
    <axis xyz="0 1 0"/>
    <limit effort="50" lower="0" upper="0.82" velocity="3.141592653589793"/>
    <mimic joint="right_gripper_joint" multiplier="1" offset="0"/>
  </joint>
  <link name="right_right_pad">
    <inertial>
      <origin xyz="-0.011864 0.006 0.011367"/>
      <mass value="0.0045068"/>
      <inertia ixx="5.1288E-07" ixy="-9.8137E-14" ixz="9.4703E-08" iyy="5.3203E-07" iyz="6.2119E-14" izz="2.009E-07"/>
    </inertial>
    <visual>
      <geometry>
        <mesh filename="package://inspire_description/meshes/EG2-4C2/pad.obj" scale="-1 1 1"/>
      </geometry>
    </visual>
    <collision>
      <geometry>
        <mesh filename="package://inspire_description/meshes/EG2-4C2/pad.obj" scale="-1 1 1"/>
      </geometry>
    </collision>
  </link>
  <joint name="right_right_pad_joint" type="revolute">
    <origin xyz="-0.0223 0.003 0.035591"/>
    <parent link="right_right_outer_link"/>
    <child link="right_right_pad"/>
    <axis xyz="0 -1 0"/>
    <limit effort="50" lower="0" upper="0.82" velocity="3.141592653589793"/>
    <mimic joint="right_gripper_joint" multiplier="1" offset="0"/>
  </joint>
  <link name="right_eef"/>
  <joint name="right_eef_joint" type="fixed">
    <parent link="right_gripper_base"/>
    <child link="right_eef"/>
    <origin xyz="0 0 0.14"/>
  </joint>
  <!-- Tool-Center-Point: midpoint between the two pads when fully closed.
         z = 0.079 (outer-link) + 0.036 (pad joint) + 0.015 (pad contact face) ≈ 0.13 m.
         Adjust xyz z-value if the OCS2 marker does not sit at the actual grip point. -->
  <link name="right_gripper_tcp"/>
  <joint name="right_gripper_tcp_joint" type="fixed">
    <origin rpy="0 0 0" xyz="0 0 0.13"/>
    <parent link="right_gripper_base"/>
    <child link="right_gripper_tcp"/>
  </joint>
  <joint name="right_gripper_mount" type="fixed">
    <parent link="right_ee"/>
    <child link="right_gripper_base"/>
    <origin rpy="0 0 1.5708" xyz="0 0 0"/>
  </joint>
</robot>
