<?xml version="1.0" encoding="utf-8"?>
<!-- This URDF was automatically created by SolidWorks to URDF Exporter! Originally created by Stephen Brawner (brawner@gmail.com) 
     Commit Version: 1.6.0-1-g15f4949  Build Version: 1.6.7594.29634
     For more information, please see http://wiki.ros.org/sw_urdf_exporter -->
<robot
  name="Bot2_ZPF_L2Fgripper_R2Fgripper_A_description">
  <link
    name="fixed_base_link">
    <inertial>
      <origin
        xyz="-0.026689 -0.0065193 0.14154"
        rpy="0 0 0" />
      <mass
        value="64.788" />
      <inertia
        ixx="0.346"
        ixy="0.00079709"
        ixz="-0.022691"
        iyy="0.65327"
        iyz="-6.4191E-05"
        izz="0.70449" />
    </inertial>
    <visual>
      <origin
        xyz="0 0 0"
        rpy="0 0 0" />
      <geometry>
        <mesh
          filename="Bot2_ZPF_L2Fgripper_R2Fgripper_A_description/meshes/fixed_base_link.STL" />
      </geometry>
      <material
        name="">
        <color
          rgba="1 1 1 1" />
      </material>
    </visual>
    <collision>
      <origin
        xyz="0 0 0"
        rpy="0 0 0" />
      <geometry>
        <mesh
          filename="Bot2_ZPF_L2Fgripper_R2Fgripper_A_description/meshes/fixed_base_link.STL" />
      </geometry>
    </collision>
  </link>
  <link
    name="driven_wheel_left_front_link_v">
    <inertial>
      <origin
        xyz="-0.0062589 -0.00011075 -0.022442"
        rpy="0 0 0" />
      <mass
        value="0.14099" />
      <inertia
        ixx="7.1508E-05"
        ixy="-1.482E-07"
        ixz="-1.8383E-05"
        iyy="6.6786E-05"
        iyz="-3.9314E-07"
        izz="3.6174E-05" />
    </inertial>
    <visual>
      <origin
        xyz="0 0 0"
        rpy="0 0 0" />
      <geometry>
        <mesh
          filename="Bot2_ZPF_L2Fgripper_R2Fgripper_A_description/meshes/driven_wheel_left_front_link_v.STL" />
      </geometry>
      <material
        name="">
        <color
          rgba="0.75294 0.75294 0.75294 1" />
      </material>
    </visual>
    <collision>
      <origin
        xyz="0 0 0"
        rpy="0 0 0" />
      <geometry>
        <mesh
          filename="Bot2_ZPF_L2Fgripper_R2Fgripper_A_description/meshes/driven_wheel_left_front_link_v.STL" />
      </geometry>
    </collision>
  </link>
  <joint
    name="driven_wheel_left_front_joint_v"
    type="continuous">
    <origin
      xyz="0.215 0.15 0.085704"
      rpy="0 0 0" />
    <parent
      link="fixed_base_link" />
    <child
      link="driven_wheel_left_front_link_v" />
    <axis
      xyz="0 0 1" />
    <limit
      effort="2000"
      velocity="10" />
  </joint>
  <link
    name="driven_wheel_left_front_link_h">
    <inertial>
      <origin
        xyz="1.14E-07 -1.5917E-10 -3.7309E-05"
        rpy="0 0 0" />
      <mass
        value="0.011636" />
      <inertia
        ixx="4.54E-06"
        ixy="-1.763E-13"
        ixz="-1.5907E-12"
        iyy="4.5401E-06"
        iyz="-4.6248E-12"
        izz="8.3204E-06" />
    </inertial>
    <visual>
      <origin
        xyz="0 0 0"
        rpy="0 0 0" />
      <geometry>
        <mesh
          filename="Bot2_ZPF_L2Fgripper_R2Fgripper_A_description/meshes/driven_wheel_left_front_link_h.STL" />
      </geometry>
      <material
        name="">
        <color
          rgba="0.84314 0.81569 0.75294 1" />
      </material>
    </visual>
    <collision>
      <origin
        xyz="0 0 0"
        rpy="0 0 0" />
      <geometry>
        <mesh
          filename="Bot2_ZPF_L2Fgripper_R2Fgripper_A_description/meshes/driven_wheel_left_front_link_h.STL" />
      </geometry>
    </collision>
  </link>
  <joint
    name="driven_wheel_left_front_joint_h"
    type="continuous">
    <origin
      xyz="-0.016001 0 -0.0482"
      rpy="-1.5708 0 0" />
    <parent
      link="driven_wheel_left_front_link_v" />
    <child
      link="driven_wheel_left_front_link_h" />
    <axis
      xyz="0 0 1" />
    <limit
      effort="2000"
      velocity="10" />
  </joint>
  <link
    name="driven_wheel_left_behind_link_v">
    <inertial>
      <origin
        xyz="-0.0062589 -0.00011075 -0.022442"
        rpy="0 0 0" />
      <mass
        value="0.14099" />
      <inertia
        ixx="7.1508E-05"
        ixy="-1.482E-07"
        ixz="-1.8383E-05"
        iyy="6.6786E-05"
        iyz="-3.9314E-07"
        izz="3.6174E-05" />
    </inertial>
    <visual>
      <origin
        xyz="0 0 0"
        rpy="0 0 0" />
      <geometry>
        <mesh
          filename="Bot2_ZPF_L2Fgripper_R2Fgripper_A_description/meshes/driven_wheel_left_behind_link_v.STL" />
      </geometry>
      <material
        name="">
        <color
          rgba="0.75294 0.75294 0.75294 1" />
      </material>
    </visual>
    <collision>
      <origin
        xyz="0 0 0"
        rpy="0 0 0" />
      <geometry>
        <mesh
          filename="Bot2_ZPF_L2Fgripper_R2Fgripper_A_description/meshes/driven_wheel_left_behind_link_v.STL" />
      </geometry>
    </collision>
  </link>
  <joint
    name="driven_wheel_left_behind_joint_v"
    type="continuous">
    <origin
      xyz="-0.215 0.15 0.085704"
      rpy="0 0 0" />
    <parent
      link="fixed_base_link" />
    <child
      link="driven_wheel_left_behind_link_v" />
    <axis
      xyz="0 0 1" />
    <limit
      effort="2000"
      velocity="10" />
  </joint>
  <link
    name="driven_wheel_left_behind_link_h">
    <inertial>
      <origin
        xyz="1.14E-07 -1.5917E-10 -3.7309E-05"
        rpy="0 0 0" />
      <mass
        value="0.011636" />
      <inertia
        ixx="4.54E-06"
        ixy="-1.763E-13"
        ixz="-1.5907E-12"
        iyy="4.5401E-06"
        iyz="-4.6248E-12"
        izz="8.3204E-06" />
    </inertial>
    <visual>
      <origin
        xyz="0 0 0"
        rpy="0 0 0" />
      <geometry>
        <mesh
          filename="Bot2_ZPF_L2Fgripper_R2Fgripper_A_description/meshes/driven_wheel_left_behind_link_h.STL" />
      </geometry>
      <material
        name="">
        <color
          rgba="0.84314 0.81569 0.75294 1" />
      </material>
    </visual>
    <collision>
      <origin
        xyz="0 0 0"
        rpy="0 0 0" />
      <geometry>
        <mesh
          filename="Bot2_ZPF_L2Fgripper_R2Fgripper_A_description/meshes/driven_wheel_left_behind_link_h.STL" />
      </geometry>
    </collision>
  </link>
  <joint
    name="driven_wheel_left_behind_joint_h"
    type="continuous">
    <origin
      xyz="-0.016001 0 -0.0482"
      rpy="-1.5708 0 0" />
    <parent
      link="driven_wheel_left_behind_link_v" />
    <child
      link="driven_wheel_left_behind_link_h" />
    <axis
      xyz="0 0 1" />
    <limit
      effort="2000"
      velocity="10" />
  </joint>
  <link
    name="driven_wheel_right_front_link_v">
    <inertial>
      <origin
        xyz="-0.0062589 -0.00011075 -0.022442"
        rpy="0 0 0" />
      <mass
        value="0.14099" />
      <inertia
        ixx="7.1508E-05"
        ixy="-1.482E-07"
        ixz="-1.8383E-05"
        iyy="6.6786E-05"
        iyz="-3.9314E-07"
        izz="3.6174E-05" />
    </inertial>
    <visual>
      <origin
        xyz="0 0 0"
        rpy="0 0 0" />
      <geometry>
        <mesh
          filename="Bot2_ZPF_L2Fgripper_R2Fgripper_A_description/meshes/driven_wheel_right_front_link_v.STL" />
      </geometry>
      <material
        name="">
        <color
          rgba="0.75294 0.75294 0.75294 1" />
      </material>
    </visual>
    <collision>
      <origin
        xyz="0 0 0"
        rpy="0 0 0" />
      <geometry>
        <mesh
          filename="Bot2_ZPF_L2Fgripper_R2Fgripper_A_description/meshes/driven_wheel_right_front_link_v.STL" />
      </geometry>
    </collision>
  </link>
  <joint
    name="driven_wheel_right_front_joint_v"
    type="continuous">
    <origin
      xyz="0.215 -0.15 0.085704"
      rpy="0 0 0" />
    <parent
      link="fixed_base_link" />
    <child
      link="driven_wheel_right_front_link_v" />
    <axis
      xyz="0 0 1" />
    <limit
      effort="2000"
      velocity="10" />
  </joint>
  <link
    name="driven_wheel_right_front_link_h">
    <inertial>
      <origin
        xyz="1.14E-07 -1.5917E-10 -3.7309E-05"
        rpy="0 0 0" />
      <mass
        value="0.011636" />
      <inertia
        ixx="4.54E-06"
        ixy="-1.763E-13"
        ixz="-1.5907E-12"
        iyy="4.5401E-06"
        iyz="-4.6248E-12"
        izz="8.3204E-06" />
    </inertial>
    <visual>
      <origin
        xyz="0 0 0"
        rpy="0 0 0" />
      <geometry>
        <mesh
          filename="Bot2_ZPF_L2Fgripper_R2Fgripper_A_description/meshes/driven_wheel_right_front_link_h.STL" />
      </geometry>
      <material
        name="">
        <color
          rgba="0.84314 0.81569 0.75294 1" />
      </material>
    </visual>
    <collision>
      <origin
        xyz="0 0 0"
        rpy="0 0 0" />
      <geometry>
        <mesh
          filename="Bot2_ZPF_L2Fgripper_R2Fgripper_A_description/meshes/driven_wheel_right_front_link_h.STL" />
      </geometry>
    </collision>
  </link>
  <joint
    name="driven_wheel_right_front_joint_h"
    type="continuous">
    <origin
      xyz="-0.016001 0 -0.0482"
      rpy="-1.5708 0 0" />
    <parent
      link="driven_wheel_right_front_link_v" />
    <child
      link="driven_wheel_right_front_link_h" />
    <axis
      xyz="0 0 1" />
    <limit
      effort="2000"
      velocity="10" />
  </joint>
  <link
    name="driven_wheel_right_behind_link_v">
    <inertial>
      <origin
        xyz="-0.0062589 -0.00011075 -0.022442"
        rpy="0 0 0" />
      <mass
        value="0.14099" />
      <inertia
        ixx="7.1508E-05"
        ixy="-1.482E-07"
        ixz="-1.8383E-05"
        iyy="6.6786E-05"
        iyz="-3.9314E-07"
        izz="3.6174E-05" />
    </inertial>
    <visual>
      <origin
        xyz="0 0 0"
        rpy="0 0 0" />
      <geometry>
        <mesh
          filename="Bot2_ZPF_L2Fgripper_R2Fgripper_A_description/meshes/driven_wheel_right_behind_link_v.STL" />
      </geometry>
      <material
        name="">
        <color
          rgba="0.75294 0.75294 0.75294 1" />
      </material>
    </visual>
    <collision>
      <origin
        xyz="0 0 0"
        rpy="0 0 0" />
      <geometry>
        <mesh
          filename="Bot2_ZPF_L2Fgripper_R2Fgripper_A_description/meshes/driven_wheel_right_behind_link_v.STL" />
      </geometry>
    </collision>
  </link>
  <joint
    name="driven_wheel_right_behind_joint_v"
    type="continuous">
    <origin
      xyz="-0.215 -0.15 0.085704"
      rpy="0 0 0" />
    <parent
      link="fixed_base_link" />
    <child
      link="driven_wheel_right_behind_link_v" />
    <axis
      xyz="0 0 1" />
    <limit
      effort="2000"
      velocity="10" />
  </joint>
  <link
    name="driven_wheel_right_behind_link_h">
    <inertial>
      <origin
        xyz="1.14E-07 -1.5917E-10 -3.7309E-05"
        rpy="0 0 0" />
      <mass
        value="0.011636" />
      <inertia
        ixx="4.54E-06"
        ixy="-1.763E-13"
        ixz="-1.5907E-12"
        iyy="4.5401E-06"
        iyz="-4.6248E-12"
        izz="8.3204E-06" />
    </inertial>
    <visual>
      <origin
        xyz="0 0 0"
        rpy="0 0 0" />
      <geometry>
        <mesh
          filename="Bot2_ZPF_L2Fgripper_R2Fgripper_A_description/meshes/driven_wheel_right_behind_link_h.STL" />
      </geometry>
      <material
        name="">
        <color
          rgba="0.84314 0.81569 0.75294 1" />
      </material>
    </visual>
    <collision>
      <origin
        xyz="0 0 0"
        rpy="0 0 0" />
      <geometry>
        <mesh
          filename="Bot2_ZPF_L2Fgripper_R2Fgripper_A_description/meshes/driven_wheel_right_behind_link_h.STL" />
      </geometry>
    </collision>
  </link>
  <joint
    name="driven_wheel_right_behind_joint_h"
    type="continuous">
    <origin
      xyz="-0.016001 0 -0.0482"
      rpy="-1.5708 0 0" />
    <parent
      link="driven_wheel_right_behind_link_v" />
    <child
      link="driven_wheel_right_behind_link_h" />
    <axis
      xyz="0 0 1" />
    <limit
      effort="2000"
      velocity="10" />
  </joint>
  <link
    name="driving_wheel_left_link">
    <inertial>
      <origin
        xyz="-1.0152E-05 -9.7038E-06 -0.00069667"
        rpy="0 0 0" />
      <mass
        value="0.11728" />
      <inertia
        ixx="0.00028315"
        ixy="5.098E-09"
        ixz="-2.3983E-08"
        iyy="0.00028315"
        iyz="-2.2922E-08"
        izz="0.00052364" />
    </inertial>
    <visual>
      <origin
        xyz="0 0 0"
        rpy="0 0 0" />
      <geometry>
        <mesh
          filename="Bot2_ZPF_L2Fgripper_R2Fgripper_A_description/meshes/driving_wheel_left_link.STL" />
      </geometry>
      <material
        name="">
        <color
          rgba="0.84314 0.81569 0.75294 1" />
      </material>
    </visual>
    <collision>
      <origin
        xyz="0 0 0"
        rpy="0 0 0" />
      <geometry>
        <mesh
          filename="Bot2_ZPF_L2Fgripper_R2Fgripper_A_description/meshes/driving_wheel_left_link.STL" />
      </geometry>
    </collision>
  </link>
  <joint
    name="driving_wheel_left_joint"
    type="continuous">
    <origin
      xyz="0 0.208 0.0845"
      rpy="-1.5708 0 0" />
    <parent
      link="fixed_base_link" />
    <child
      link="driving_wheel_left_link" />
    <axis
      xyz="0 0 1" />
    <limit
      effort="2000"
      velocity="10" />
  </joint>
  <link
    name="driving_wheel_right_link">
    <inertial>
      <origin
        xyz="1.0152E-05 -9.7038E-06 0.00069667"
        rpy="0 0 0" />
      <mass
        value="0.11728" />
      <inertia
        ixx="0.00028315"
        ixy="-5.098E-09"
        ixz="-2.3983E-08"
        iyy="0.00028315"
        iyz="2.2922E-08"
        izz="0.00052364" />
    </inertial>
    <visual>
      <origin
        xyz="0 0 0"
        rpy="0 0 0" />
      <geometry>
        <mesh
          filename="Bot2_ZPF_L2Fgripper_R2Fgripper_A_description/meshes/driving_wheel_right_link.STL" />
      </geometry>
      <material
        name="">
        <color
          rgba="0.84314 0.81569 0.75294 1" />
      </material>
    </visual>
    <collision>
      <origin
        xyz="0 0 0"
        rpy="0 0 0" />
      <geometry>
        <mesh
          filename="Bot2_ZPF_L2Fgripper_R2Fgripper_A_description/meshes/driving_wheel_right_link.STL" />
      </geometry>
    </collision>
  </link>
  <joint
    name="driving_wheel_right_joint"
    type="continuous">
    <origin
      xyz="0 -0.208 0.0845"
      rpy="-1.5708 0 0" />
    <parent
      link="fixed_base_link" />
    <child
      link="driving_wheel_right_link" />
    <axis
      xyz="0 0 1" />
    <limit
      effort="2000"
      velocity="10" />
  </joint>
  <link
    name="ankle_pitch_calf_link">
    <inertial>
      <origin
        xyz="0.0040321 -0.3007 0.0026114"
        rpy="0 0 0" />
      <mass
        value="8.2502" />
      <inertia
        ixx="0.093386"
        ixy="-0.0049619"
        ixz="-0.00010259"
        iyy="0.019887"
        iyz="0.00015883"
        izz="0.090475" />
    </inertial>
    <visual>
      <origin
        xyz="0 0 0"
        rpy="0 0 0" />
      <geometry>
        <mesh
          filename="Bot2_ZPF_L2Fgripper_R2Fgripper_A_description/meshes/ankle_pitch_calf_link.STL" />
      </geometry>
      <material
        name="">
        <color
          rgba="0.86667 0.86667 0.8902 1" />
      </material>
    </visual>
    <collision>
      <origin
        xyz="0 0 0"
        rpy="0 0 0" />
      <geometry>
        <mesh
          filename="Bot2_ZPF_L2Fgripper_R2Fgripper_A_description/meshes/ankle_pitch_calf_link.STL" />
      </geometry>
    </collision>
  </link>
  <joint
    name="ankle_pitch_joint"
    type="revolute">
    <origin
      xyz="0.19155 0 0.294"
      rpy="-1.5708 0 0" />
    <parent
      link="fixed_base_link" />
    <child
      link="ankle_pitch_calf_link" />
    <axis
      xyz="0 0 1" />
    <limit
      lower="-1.1868"
      upper="0"
      effort="1000"
      velocity="10" />
  </joint>
  <link
    name="knee_pitch_thigh_link">
    <inertial>
      <origin
        xyz="-0.0065356 -0.15379 -0.0042654"
        rpy="0 0 0" />
      <mass
        value="3.312" />
      <inertia
        ixx="0.03805"
        ixy="-0.00010138"
        ixz="1.1661E-06"
        iyy="0.0070468"
        iyz="6.6081E-06"
        izz="0.041003" />
    </inertial>
    <visual>
      <origin
        xyz="0 0 0"
        rpy="0 0 0" />
      <geometry>
        <mesh
          filename="Bot2_ZPF_L2Fgripper_R2Fgripper_A_description/meshes/knee_pitch_thigh_link.STL" />
      </geometry>
      <material
        name="">
        <color
          rgba="1 1 1 1" />
      </material>
    </visual>
    <collision>
      <origin
        xyz="0 0 0"
        rpy="0 0 0" />
      <geometry>
        <mesh
          filename="Bot2_ZPF_L2Fgripper_R2Fgripper_A_description/meshes/knee_pitch_thigh_link.STL" />
      </geometry>
    </collision>
  </link>
  <joint
    name="knee_pitch_joint"
    type="revolute">
    <origin
      xyz="0 -0.38704 0"
      rpy="0 0 0" />
    <parent
      link="ankle_pitch_calf_link" />
    <child
      link="knee_pitch_thigh_link" />
    <axis
      xyz="0 0 1" />
    <limit
      lower="-0.38397"
      upper="2.7576"
      effort="1000"
      velocity="10" />
  </joint>
  <link
    name="waist_pitch_waist_link">
    <inertial>
      <origin
        xyz="0.0057091 -0.043636 0.0033344"
        rpy="0 0 0" />
      <mass
        value="5.6895" />
      <inertia
        ixx="0.010503"
        ixy="0.00050418"
        ixz="1.2455E-05"
        iyy="0.0080802"
        iyz="-4.4802E-05"
        izz="0.011644" />
    </inertial>
    <visual>
      <origin
        xyz="0 0 0"
        rpy="0 0 0" />
      <geometry>
        <mesh
          filename="Bot2_ZPF_L2Fgripper_R2Fgripper_A_description/meshes/waist_pitch_waist_link.STL" />
      </geometry>
      <material
        name="">
        <color
          rgba="0.89804 0.91765 0.92941 1" />
      </material>
    </visual>
    <collision>
      <origin
        xyz="0 0 0"
        rpy="0 0 0" />
      <geometry>
        <mesh
          filename="Bot2_ZPF_L2Fgripper_R2Fgripper_A_description/meshes/waist_pitch_waist_link.STL" />
      </geometry>
    </collision>
  </link>
  <joint
    name="waist_pitch_joint"
    type="revolute">
    <origin
      xyz="0 -0.27 0"
      rpy="0 0 0" />
    <parent
      link="knee_pitch_thigh_link" />
    <child
      link="waist_pitch_waist_link" />
    <axis
      xyz="0 0 1" />
    <limit
      lower="-1.5708"
      upper="0.5236"
      effort="1000"
      velocity="10" />
  </joint>
  <link
    name="waist_yaw_torso_link">
    <inertial>
      <origin
        xyz="-0.014346 4.4158E-06 0.20167"
        rpy="0 0 0" />
      <mass
        value="4.6934" />
      <inertia
        ixx="0.048256"
        ixy="-1.0989E-06"
        ixz="0.0042551"
        iyy="0.041609"
        iyz="1.1206E-07"
        izz="0.017837" />
    </inertial>
    <visual>
      <origin
        xyz="0 0 0"
        rpy="0 0 0" />
      <geometry>
        <mesh
          filename="Bot2_ZPF_L2Fgripper_R2Fgripper_A_description/meshes/waist_yaw_torso_link.STL" />
      </geometry>
      <material
        name="">
        <color
          rgba="1 1 1 1" />
      </material>
    </visual>
    <collision>
      <origin
        xyz="0 0 0"
        rpy="0 0 0" />
      <geometry>
        <mesh
          filename="Bot2_ZPF_L2Fgripper_R2Fgripper_A_description/meshes/waist_yaw_torso_link.STL" />
      </geometry>
    </collision>
  </link>
  <joint
    name="waist_yaw_joint"
    type="revolute">
    <origin
      xyz="0 -0.1655 0"
      rpy="1.5708 0 0" />
    <parent
      link="waist_pitch_waist_link" />
    <child
      link="waist_yaw_torso_link" />
    <axis
      xyz="0 0 1" />
    <limit
      lower="-1.5708"
      upper="1.5708"
      effort="1000"
      velocity="10" />
  </joint>
  <link
    name="ego">
    <inertial>
      <origin
        xyz="0 1.1481E-20 2.2204E-16"
        rpy="0 0 0" />
      <mass
        value="5.236E-07" />
      <inertia
        ixx="5.236E-14"
        ixy="0"
        ixz="0"
        iyy="5.236E-14"
        iyz="-1.2903E-46"
        izz="5.236E-14" />
    </inertial>
    <visual>
      <origin
        xyz="0 0 0"
        rpy="0 0 0" />
      <geometry>
        <mesh
          filename="Bot2_ZPF_L2Fgripper_R2Fgripper_A_description/meshes/ego.STL" />
      </geometry>
      <material
        name="">
        <color
          rgba="1 0 0 1" />
      </material>
    </visual>
    <collision>
      <origin
        xyz="0 0 0"
        rpy="0 0 0" />
      <geometry>
        <mesh
          filename="Bot2_ZPF_L2Fgripper_R2Fgripper_A_description/meshes/ego.STL" />
      </geometry>
    </collision>
  </link>
  <joint
    name="ego_joint"
    type="fixed">
    <origin
      xyz="-0.061 0 0.3255"
      rpy="0 0 0" />
    <parent
      link="waist_yaw_torso_link" />
    <child
      link="ego" />
    <axis
      xyz="0 0 0" />
  </joint>
  <link
    name="head_yaw_neck_link">
    <inertial>
      <origin
        xyz="-1.4269E-12 0.0053202 0.055582"
        rpy="0 0 0" />
      <mass
        value="0.2237" />
      <inertia
        ixx="8.9086E-05"
        ixy="2.4443E-15"
        ixz="5.7682E-20"
        iyy="6.5512E-05"
        iyz="3.0856E-06"
        izz="4.8068E-05" />
    </inertial>
    <visual>
      <origin
        xyz="0 0 0"
        rpy="0 0 0" />
      <geometry>
        <mesh
          filename="Bot2_ZPF_L2Fgripper_R2Fgripper_A_description/meshes/head_yaw_neck_link.STL" />
      </geometry>
      <material
        name="">
        <color
          rgba="0.75294 0.75294 0.75294 1" />
      </material>
    </visual>
    <collision>
      <origin
        xyz="0 0 0"
        rpy="0 0 0" />
      <geometry>
        <mesh
          filename="Bot2_ZPF_L2Fgripper_R2Fgripper_A_description/meshes/head_yaw_neck_link.STL" />
      </geometry>
    </collision>
  </link>
  <joint
    name="head_yaw_joint"
    type="revolute">
    <origin
      xyz="-0.041 0 0.46874"
      rpy="0 0 0" />
    <parent
      link="waist_yaw_torso_link" />
    <child
      link="head_yaw_neck_link" />
    <axis
      xyz="0 0 1" />
    <limit
      lower="-1.5708"
      upper="1.5708"
      effort="1000"
      velocity="10" />
  </joint>
  <link
    name="head_pitch_head_link">
    <inertial>
      <origin
        xyz="0.028328 -0.035178 -0.00055178"
        rpy="0 0 0" />
      <mass
        value="0.56733" />
      <inertia
        ixx="0.0020659"
        ixy="-0.00054222"
        ixz="-7.9302E-07"
        iyy="0.0025822"
        iyz="-4.5882E-07"
        izz="0.002181" />
    </inertial>
    <visual>
      <origin
        xyz="0 0 0"
        rpy="0 0 0" />
      <geometry>
        <mesh
          filename="Bot2_ZPF_L2Fgripper_R2Fgripper_A_description/meshes/head_pitch_head_link.STL" />
      </geometry>
      <material
        name="">
        <color
          rgba="0.75294 0.75294 0.75294 1" />
      </material>
    </visual>
    <collision>
      <origin
        xyz="0 0 0"
        rpy="0 0 0" />
      <geometry>
        <mesh
          filename="Bot2_ZPF_L2Fgripper_R2Fgripper_A_description/meshes/head_pitch_head_link.STL" />
      </geometry>
    </collision>
  </link>
  <joint
    name="head_pitch_joint"
    type="revolute">
    <origin
      xyz="0 0 0.06"
      rpy="-1.5708 0 0" />
    <parent
      link="head_yaw_neck_link" />
    <child
      link="head_pitch_head_link" />
    <axis
      xyz="0 0 1" />
    <limit
      lower="-0.4014"
      upper="0.38397"
      effort="1000"
      velocity="10" />
  </joint>
  <link
    name="ZPF_left_base_link">
    <inertial>
      <origin
        xyz="1.7227967e-05 -2.7405976e-04  6.7417875e-02"
        rpy="0 0 0" />
      <mass
        value="1.39" />
      <inertia
        ixx="1.7468022e-03"
        ixy="4.4167244e-07"
        ixz="8.1232278e-07"
        iyy="1.7511135e-03 "
        iyz="-1.7950155e-05"
        izz="1.1806738e-03" />
    </inertial>
    <visual>
      <origin
        xyz="0 0 0"
        rpy="0 0 0" />
      <geometry>
        <mesh
          filename="Bot2_ZPF_L2Fgripper_R2Fgripper_A_description/meshes/ZPF_left_base_link.STL" />
      </geometry>
      <material
        name="">
        <color
          rgba="0.86667 0.86667 0.8902 1" />
      </material>
    </visual>
    <collision>
      <origin
        xyz="0 0 0"
        rpy="0 0 0" />
      <geometry>
        <mesh
          filename="Bot2_ZPF_L2Fgripper_R2Fgripper_A_description/meshes/ZPF_left_base_link.STL" />
      </geometry>
    </collision>
  </link>
  <joint
    name="ZPF_left_base_joint_0"
    type="fixed">
    <origin
      xyz="-0.061 0.0485 0.3255"
      rpy="-1.5708 -1.5708 0" />
    <parent
      link="waist_yaw_torso_link" />
    <child
      link="ZPF_left_base_link" />
    <axis
      xyz="0 0 0" />
  </joint>
<!-- 下面是左臂的LINK1和后续的所有link
空白
空白
空白 -->
<!-- 下面的要删除 -->
  <!-- <link
    name="ZM73_6FB_left_Link_1">
    <inertial>
      <origin
        xyz="-2.0626855e-03 -1.6559648e-02 -2.9563678e-02"
        rpy="0 0 0" />
      <mass
        value="0.628" />
      <inertia
        ixx="1.6599262e-03"
        ixy="-6.1451353e-05"
        ixz="1.5137541e-04"
        iyy="1.5735435e-03"
        iyz="2.0085037e-04"
        izz="1.5710792e-03" />
    </inertial>
    <visual>
      <origin
        xyz="0 0 0"
        rpy="0 0 0" />
      <geometry>
        <mesh
          filename="Bot2_ZPF_L2Fgripper_R2Fgripper_A_description/meshes/ZM73_6FB_left_Link_1.STL" />
      </geometry>
      <material
        name="">
        <color
          rgba="0.86667 0.86667 0.8902 1" />
      </material>
    </visual>
    <collision>
      <origin
        xyz="0 0 0"
        rpy="0 0 0" />
      <geometry>
        <mesh
          filename="Bot2_ZPF_L2Fgripper_R2Fgripper_A_description/meshes/ZM73_6FB_left_Link_1.STL" />
      </geometry>
    </collision>
  </link>
  <joint
    name="ZM73_6FB_left_joint_1"
    type="revolute">
    <origin
      xyz="0 0 0.1785"
      rpy="0 0 0" />
    <parent
      link="ZM73_6FB_left_base_link" />
    <child
      link="ZM73_6FB_left_Link_1" />
    <axis
      xyz="0 0 1" />
    <limit
      lower="-3.1"
      upper="3.1"
      effort="60"
      velocity="3.14" />
  </joint>
  <link
    name="ZM73_6FB_left_Link_2">
    <inertial>
      <origin
        xyz="1.2552172e-04 -6.4890315e-03 -1.5096105e-02"
        rpy="0 0 0" />
      <mass
        value="1.37" />
      <inertia
        ixx="1.7992218e-03"
        ixy="-1.1620208e-06"
        ixz="-3.9132877e-06"
        iyy="1.2916690e-03"
        iyz="1.1836315e-04"
        izz="1.5723054e-03" />
    </inertial>
    <visual>
      <origin
        xyz="0 0 0"
        rpy="0 0 0" />
      <geometry>
        <mesh
          filename="Bot2_ZPF_L2Fgripper_R2Fgripper_A_description/meshes/ZM73_6FB_left_Link_2.STL" />
      </geometry>
      <material
        name="">
        <color
          rgba="0.86667 0.86667 0.8902 1" />
      </material>
    </visual>
    <collision>
      <origin
        xyz="0 0 0"
        rpy="0 0 0" />
      <geometry>
        <mesh
          filename="Bot2_ZPF_L2Fgripper_R2Fgripper_A_description/meshes/ZM73_6FB_left_Link_2.STL" />
      </geometry>
    </collision>
  </link>
  <joint
    name="ZM73_6FB_left_joint_2"
    type="revolute">
    <origin
      xyz="0 0 0"
      rpy="-1.5708 -1.5708 0" />
    <parent
      link="ZM73_6FB_left_Link_1" />
    <child
      link="ZM73_6FB_left_Link_2" />
    <axis
      xyz="0 0 1" />
    <limit
      lower="-0.43"
      upper="3.1"
      effort="60"
      velocity="3.14" />
  </joint>
  <link
    name="ZM73_6FB_left_Link_3">
    <inertial>
      <origin
        xyz="4.7568354e-03  3.1731214e-03 -9.2292156e-02"
        rpy="0 0 0" />
      <mass
        value="2.29" />
      <inertia
        ixx="3.7492999e-02"
        ixy="-6.5328616e-05"
        ixz="6.1380090e-05"
        iyy="3.7362685e-02"
        iyz="-5.4729831e-05"
        izz="1.8817538e-03" />
    </inertial>
    <visual>
      <origin
        xyz="0 0 0"
        rpy="0 0 0" />
      <geometry>
        <mesh
          filename="Bot2_ZPF_L2Fgripper_R2Fgripper_A_description/meshes/ZM73_6FB_left_Link_3.STL" />
      </geometry>
      <material
        name="">
        <color
          rgba="0.86667 0.86667 0.8902 1" />
      </material>
    </visual>
    <collision>
      <origin
        xyz="0 0 0"
        rpy="0 0 0" />
      <geometry>
        <mesh
          filename="Bot2_ZPF_L2Fgripper_R2Fgripper_A_description/meshes/ZM73_6FB_left_Link_3.STL" />
      </geometry>
    </collision>
  </link>
  <joint
    name="ZM73_6FB_left_joint_3"
    type="revolute">
    <origin
      xyz="0 -0.28998 0"
      rpy="1.5708 -1.5708 0" />
    <parent
      link="ZM73_6FB_left_Link_2" />
    <child
      link="ZM73_6FB_left_Link_3" />
    <axis
      xyz="0 0 1" />
    <limit
      lower="-3.1"
      upper="3.1"
      effort="30"
      velocity="3.14" />
  </joint>
  <link
    name="ZM73_6FB_left_Link_4">
    <inertial>
      <origin
        xyz="-9.5427735e-03  8.9997066e-02 -4.3741023e-03"
        rpy="0 0 0" />
      <mass
        value="0.82" />
      <inertia
        ixx="2.8633804e-03"
        ixy="-2.9024436e-05"
        ixz="2.8630445e-05"
        iyy="7.2655797e-04"
        iyz="-2.4077951e-04"
        izz="2.7356732e-03" />
    </inertial>
    <visual>
      <origin
        xyz="0 0 0"
        rpy="0 0 0" />
      <geometry>
        <mesh
          filename="Bot2_ZPF_L2Fgripper_R2Fgripper_A_description/meshes/ZM73_6FB_left_Link_4.STL" />
      </geometry>
      <material
        name="">
        <color
          rgba="0.86667 0.86667 0.8902 1" />
      </material>
    </visual>
    <collision>
      <origin
        xyz="0 0 0"
        rpy="0 0 0" />
      <geometry>
        <mesh
          filename="Bot2_ZPF_L2Fgripper_R2Fgripper_A_description/meshes/ZM73_6FB_left_Link_4.STL" />
      </geometry>
    </collision>
  </link>
  <joint
    name="ZM73_6FB_left_joint_4"
    type="revolute">
    <origin
      xyz="0.01 0 0"
      rpy="1.5708 0 0" />
    <parent
      link="ZM73_6FB_left_Link_3" />
    <child
      link="ZM73_6FB_left_Link_4" />
    <axis
      xyz="0 0 1" />
    <limit
      lower="-2.26"
      upper="0"
      effort="30"
      velocity="3.925" />
  </joint>
  <link
    name="ZM73_6FB_left_Link_5">
    <inertial>
      <origin
        xyz="-2.3965047e-05 -2.2471002e-02 -8.5293007e-02"
        rpy="0 0 0" />
      <mass
        value="1.02" />
      <inertia
        ixx="2.2579574e-03"
        ixy="2.0270009e-07"
        ixz="3.2535431e-08"
        iyy="2.0417531e-03"
        iyz="3.7131069e-04"
        izz="9.5194483e-04" />
    </inertial>
    <visual>
      <origin
        xyz="0 0 0"
        rpy="0 0 0" />
      <geometry>
        <mesh
          filename="Bot2_ZPF_L2Fgripper_R2Fgripper_A_description/meshes/ZM73_6FB_left_Link_5.STL" />
      </geometry>
      <material
        name="">
        <color
          rgba="0.86667 0.86667 0.8902 1" />
      </material>
    </visual>
    <collision>
      <origin
        xyz="0 0 0"
        rpy="0 0 0" />
      <geometry>
        <mesh
          filename="Bot2_ZPF_L2Fgripper_R2Fgripper_A_description/meshes/ZM73_6FB_left_Link_5.STL" />
      </geometry>
    </collision>
  </link>
  <joint
    name="ZM73_6FB_left_joint_5"
    type="revolute">
    <origin
      xyz="-0.01 0.30879 0"
      rpy="-1.5708 0 0" />
    <parent
      link="ZM73_6FB_left_Link_4" />
    <child
      link="ZM73_6FB_left_Link_5" />
    <axis
      xyz="0 0 1" />
    <limit
      lower="-3.14"
      upper="3.14"
      effort="10"
      velocity="3.925" />
  </joint>
  <link
    name="ZM73_6FB_left_Link_6">
    <inertial>
      <origin
        xyz="9.1547783e-03 -8.1037339e-03  2.9572071e-03"
        rpy="0 0 0" />
      <mass
        value="0.55" />
      <inertia
        ixx="3.7382788e-04"
        ixy="3.1477249e-06"
        ixz="1.5645983e-05"
        iyy="2.7467239e-04"
        iyz="-1.1682175e-05"
        izz="3.2231106e-04" />
    </inertial>
    <visual>
      <origin
        xyz="0 0 0"
        rpy="0.34 0 0" />
      <geometry>
        <mesh
          filename="Bot2_ZPF_L2Fgripper_R2Fgripper_A_description/meshes/ZM73_6FB_left_Link_6.STL" />
      </geometry>
      <material
        name="">
        <color
          rgba="0.86667 0.86667 0.8902 1" />
      </material>
    </visual>
    <collision>
      <origin
        xyz="0 0 0"
        rpy="0.34 0 0" />
      <geometry>
        <mesh
          filename="Bot2_ZPF_L2Fgripper_R2Fgripper_A_description/meshes/ZM73_6FB_left_Link_6.STL" />
      </geometry>
    </collision>
  </link>
  <joint
    name="ZM73_6FB_left_joint_6"
    type="revolute">
    <origin
      xyz="0 0 0"
      rpy="1.5708 -1.5708 0" />
    <parent
      link="ZM73_6FB_left_Link_5" />
    <child
      link="ZM73_6FB_left_Link_6" />
    <axis
      xyz="0 0 1" />
    <limit
      lower="-1.22"
      upper="1.22"
      effort="10"
      velocity="3.925" />
  </joint>
  <link
    name="ZM73_6FB_left_Link_7">
    <inertial>
      <origin
        xyz="1.5471956e-04  5.4839631e-02  5.5525336e-03"
        rpy="0 0 0" />
      <mass
        value="0.27" />
      <inertia
        ixx="3.3554593e-04"
        ixy="-1.6407013e-07"
        ixz="3.6029190e-07"
        iyy="1.6713017e-04"
        iyz="7.9261965e-05"
        izz="3.0553926e-04" />
    </inertial>
    <visual>
      <origin
        xyz="0 0 0"
        rpy="0 0 0" />
      <geometry>
        <mesh
          filename="Bot2_ZPF_L2Fgripper_R2Fgripper_A_description/meshes/ZM73_6FB_left_Link_7.STL" />
      </geometry>
      <material
        name="">
        <color
          rgba="0.86667 0.86667 0.8902 1" />
      </material>
    </visual>
    <collision>
      <origin
        xyz="0 0 0"
        rpy="0 0 0" />
      <geometry>
        <mesh
          filename="Bot2_ZPF_L2Fgripper_R2Fgripper_A_description/meshes/ZM73_6FB_left_Link_7.STL" />
      </geometry>
    </collision>
  </link>
  <joint
    name="ZM73_6FB_left_joint_7"
    type="revolute">
    <origin
      xyz="0.01 0 0"
      rpy="1.5708 -1.5708 0" />
    <parent
      link="ZM73_6FB_left_Link_6" />
    <child
      link="ZM73_6FB_left_Link_7" />
    <axis
      xyz="0 0 1" />
    <limit
      lower="-2.09"
      upper="0.48"
      effort="10"
      velocity="3.925" />
  </joint>
  <link
    name="ZM73_6FB_left_Link_8">
    <inertial>
      <origin
        xyz="-0.00024477 7.5438E-05 -0.017161"
        rpy="0 0 0" />
      <mass
        value="0.16601" />
      <inertia
        ixx="4.8847E-05"
        ixy="-9.5847E-08"
        ixz="3.0777E-07"
        iyy="4.9461E-05"
        iyz="7.878E-09"
        izz="7.6898E-05" />
    </inertial>
    <visual>
      <origin
        xyz="0 0 0"
        rpy="0 0 0" />
      <geometry>
        <mesh
          filename="Bot2_ZPF_L2Fgripper_R2Fgripper_A_description/meshes/ZM73_6FB_left_Link_8.STL" />
      </geometry>
      <material
        name="">
        <color
          rgba="0.86667 0.86667 0.8902 1" />
      </material>
    </visual>
    <collision>
      <origin
        xyz="0 0 0"
        rpy="0 0 0" />
      <geometry>
        <mesh
          filename="Bot2_ZPF_L2Fgripper_R2Fgripper_A_description/meshes/ZM73_6FB_left_Link_8.STL" />
      </geometry>
    </collision>
  </link>
  <joint
    name="ZM73_6FB_left_joint_8"
    type="fixed">
    <origin
      xyz="0 -0.0912 0"
      rpy="1.5708 0 0" />
    <parent
      link="ZM73_6FB_left_Link_7" />
    <child
      link="ZM73_6FB_left_Link_8" />
    <axis
      xyz="0 0 1" />
  </joint>
  <link
    name="Camera_flange_L_link">
    <inertial>
      <origin
        xyz="0.061357 0.0040163 0.0055939"
        rpy="0 0 0" />
      <mass
        value="0.17555" />
      <inertia
        ixx="8.6461E-05"
        ixy="-5.153E-06"
        ixz="-5.8712E-07"
        iyy="0.00022691"
        iyz="-1.3578E-11"
        izz="0.00031166" />
    </inertial>
    <visual>
      <origin
        xyz="0 0 0"
        rpy="0 0 0" />
      <geometry>
        <mesh
          filename="Bot2_ZPF_L2Fgripper_R2Fgripper_A_description/meshes/Camera_flange_L_link.STL" />
      </geometry>
      <material
        name="">
        <color
          rgba="0.89804 0.91765 0.92941 1" />
      </material>
    </visual>
    <collision>
      <origin
        xyz="0 0 0"
        rpy="0 0 0" />
      <geometry>
        <mesh
          filename="Bot2_ZPF_L2Fgripper_R2Fgripper_A_description/meshes/Camera_flange_L_link.STL" />
      </geometry>
    </collision>
  </link>
  <joint
    name="Camera_flange_L_joint"
    type="fixed">
    <origin
      xyz="0 0 0"
      rpy="0 0 0" />
    <parent
      link="ZM73_6FB_left_Link_8" />
    <child
      link="Camera_flange_L_link" />
    <axis
      xyz="0 0 0" />
  </joint>
  <link
    name="Camera_linear_adjustment_L_link">
    <inertial>
      <origin
        xyz="5.7855E-05 0.0047628 1.3878E-16"
        rpy="0 0 0" />
      <mass
        value="0.0032684" />
      <inertia
        ixx="2.3915E-06"
        ixy="-3.1894E-09"
        ixz="1.0214E-19"
        iyy="2.3587E-06"
        iyz="1.5154E-21"
        izz="1.559E-07" />
    </inertial>
    <visual>
      <origin
        xyz="0 0 0"
        rpy="0 0 0" />
      <geometry>
        <mesh
          filename="Bot2_ZPF_L2Fgripper_R2Fgripper_A_description/meshes/Camera_linear_adjustment_L_link.STL" />
      </geometry>
      <material
        name="">
        <color
          rgba="0.98824 0.73725 0.51765 1" />
      </material>
    </visual>
    <collision>
      <origin
        xyz="0 0 0"
        rpy="0 0 0" />
      <geometry>
        <mesh
          filename="Bot2_ZPF_L2Fgripper_R2Fgripper_A_description/meshes/Camera_linear_adjustment_L_link.STL" />
      </geometry>
    </collision>
  </link>
  <joint
    name="Camera_linear_adjustment_L_joint"
    type="prismatic">
    <origin
      xyz="0.114 0.055 0.014"
      rpy="1.5708 0 0" />
    <parent
      link="Camera_flange_L_link" />
    <child
      link="Camera_linear_adjustment_L_link" />
    <axis
      xyz="0 0 1" />
    <limit
      lower="0"
      upper="0.055"
      effort="1000"
      velocity="10" />
  </joint>
  <link
    name="Camera_angle_adjustment_L_link">
    <inertial>
      <origin
        xyz="0.0013153 0.020995 0.0015349"
        rpy="0 0 0" />
      <mass
        value="0.039369" />
      <inertia
        ixx="2.3314E-05"
        ixy="-1.7357E-07"
        ixz="-1.3649E-08"
        iyy="2.4575E-05"
        iyz="4.1992E-08"
        izz="2.1811E-06" />
    </inertial>
    <visual>
      <origin
        xyz="0 0 0"
        rpy="0 0 0" />
      <geometry>
        <mesh
          filename="Bot2_ZPF_L2Fgripper_R2Fgripper_A_description/meshes/Camera_angle_adjustment_L_link.STL" />
      </geometry>
      <material
        name="">
        <color
          rgba="1 1 0.50196 1" />
      </material>
    </visual>
    <collision>
      <origin
        xyz="0 0 0"
        rpy="0 0 0" />
      <geometry>
        <mesh
          filename="Bot2_ZPF_L2Fgripper_R2Fgripper_A_description/meshes/Camera_angle_adjustment_L_link.STL" />
      </geometry>
    </collision>
  </link>
  <joint
    name="Camera_angle_adjustment_L_joint"
    type="revolute">
    <origin
      xyz="-0.0039 0.015 0"
      rpy="0 0 0" />
    <parent
      link="Camera_linear_adjustment_L_link" />
    <child
      link="Camera_angle_adjustment_L_link" />
    <axis
      xyz="0 0 1" />
    <limit
      lower="0"
      upper="1.5708"
      effort="1000"
      velocity="10" />
  </joint> -->
<!-- 空白 -->
  <!-- 上面应该删除 -->
  <!-- 下面的ZPFL的左臂
  空白
  空白
  空白
  空白 -->
  <link
    name="ZPF_left_Link1">
    <inertial>
      <origin
        xyz="-1.1436e-3 -1.5043e-2 -3.0119e-2"
        rpy="0 0 0" />
      <mass
        value="0.5885" />
      <inertia
        ixx="1.6599262e-03"
        ixy="-6.1451353e-05"
        ixz="1.5137541e-04"
        iyy="1.5735435e-03"
        iyz="2.0085037e-04"
        izz="1.5710792e-03" />
    </inertial>
    <visual>
      <origin
        xyz="0 0 0"
        rpy="0 0 0" />
      <geometry>
        <mesh
          filename="Bot2_ZPF_L2Fgripper_R2Fgripper_A_description/meshes/ZPF_left_Link1.STL" />
      </geometry>
      <material
        name="">
        <color
          rgba="1 1 1 1" />
      </material>
    </visual>
    <collision>
      <origin
        xyz="0 0 0"
        rpy="0 0 0" />
      <geometry>
        <mesh
          filename="Bot2_ZPF_L2Fgripper_R2Fgripper_A_description/meshes/ZPF_left_Link1.STL" />
      </geometry>
    </collision>
  </link>
  <joint
    name="ZPF_left_Joint1"
    type="revolute">
    <origin
      xyz="0 0 0.1785"
      rpy="0 0 0" />
    <parent
      link="ZPF_left_base_link" />
    <child
      link="ZPF_left_Link1" />
    <axis
      xyz="0 0 1" />
    <limit
      lower="-3.1"
      upper="3.1"
      effort="60"
      velocity="3.14" />
  </joint>
  <link
    name="ZPF_left_Link2">
    <inertial>
      <origin
        xyz="1.255e-4 -6.489e-3 -1.5096e-2"
        rpy="0 0 0" />
      <mass
        value="1.37" />
      <inertia
        ixx="1.7992218e-03"
        ixy="-1.1620208e-06"
        ixz="-3.9132877e-06"
        iyy="1.2916690e-03"
        iyz="1.1836315e-04"
        izz="1.5723054e-03" />
    </inertial>
    <visual>
      <origin
        xyz="0 0 0"
        rpy="0 0 0" />
      <geometry>
        <mesh
          filename="Bot2_ZPF_L2Fgripper_R2Fgripper_A_description/meshes/ZPF_left_Link2.STL" />
      </geometry>
      <material
        name="">
        <color
          rgba="1 1 1 1" />
      </material>
    </visual>
    <collision>
      <origin
        xyz="0 0 0"
        rpy="0 0 0" />
      <geometry>
        <mesh
          filename="Bot2_ZPF_L2Fgripper_R2Fgripper_A_description/meshes/ZPF_left_Link2.STL" />
      </geometry>
    </collision>
  </link>
  <joint
    name="ZPF_left_Joint2"
    type="revolute">
    <origin
      xyz="0 0 0"
      rpy="-1.5708 -1.5708 0" />
    <parent
      link="ZPF_left_Link1" />
    <child
      link="ZPF_left_Link2" />
    <axis
      xyz="0 0 1" />
    <limit
      lower="-0.44"
      upper="3.1"
      effort="60"
      velocity="3.14" />
  </joint>
  <link
    name="ZPF_left_Link3">
    <inertial>
      <origin
        xyz="4.7568e-3 3.1731e-3 -9.229e-2"
        rpy="0 0 0" />
      <mass
        value="2.29" />
      <inertia
        ixx="3.7492999e-02"
        ixy="-6.5328616e-05"
        ixz="6.1380090e-05"
        iyy="3.7362685e-02"
        iyz="-5.4729831e-05"
        izz="1.8817538e-03" />
    </inertial>
    <visual>
      <origin
        xyz="0 0 0"
        rpy="0 0 0" />
      <geometry>
        <mesh
          filename="Bot2_ZPF_L2Fgripper_R2Fgripper_A_description/meshes/ZPF_left_Link3.STL" />
      </geometry>
      <material
        name="">
        <color
          rgba="1 1 1 1" />
      </material>
    </visual>
    <collision>
      <origin
        xyz="0 0 0"
        rpy="0 0 0" />
      <geometry>
        <mesh
          filename="Bot2_ZPF_L2Fgripper_R2Fgripper_A_description/meshes/ZPF_left_Link3.STL" />
      </geometry>
    </collision>
  </link>
  <joint
    name="ZPF_left_Joint3"
    type="revolute">
    <origin
      xyz="0 -0.28998 0"
      rpy="1.5708 -1.5708 0" />
    <parent
      link="ZPF_left_Link2" />
    <child
      link="ZPF_left_Link3" />
    <axis
      xyz="0 0 1" />
    <limit
      lower="-3.1"
      upper="3.1"
      effort="30"
      velocity="3.14" />
  </joint>
  <link
    name="ZPF_left_Link4">
    <inertial>
      <origin
        xyz="-9.542e-3 8.999e-2 -4.374e-3"
        rpy="0 0 0" />
      <mass
        value="0.82" />
      <inertia
        ixx="2.8633804e-03"
        ixy="-2.9024436e-05"
        ixz="2.8630445e-05"
        iyy="7.2655797e-04"
        iyz="-2.4077951e-04"
        izz="2.7356732e-03" />
    </inertial>
    <visual>
      <origin
        xyz="0 0 0"
        rpy="0 0 0" />
      <geometry>
        <mesh
          filename="Bot2_ZPF_L2Fgripper_R2Fgripper_A_description/meshes/ZPF_left_Link4.STL" />
      </geometry>
      <material
        name="">
        <color
          rgba="1 1 1 1" />
      </material>
    </visual>
    <collision>
      <origin
        xyz="0 0 0"
        rpy="0 0 0" />
      <geometry>
        <mesh
          filename="Bot2_ZPF_L2Fgripper_R2Fgripper_A_description/meshes/ZPF_left_Link4.STL" />
      </geometry>
    </collision>
  </link>
  <joint
    name="ZPF_left_Joint4"
    type="revolute">
    <origin
      xyz="0.01 0 0"
      rpy="1.5708 0 0" />
    <parent
      link="ZPF_left_Link3" />
    <child
      link="ZPF_left_Link4" />
    <axis
      xyz="0 0 1" />
    <limit
      lower="-2.27"
      upper="0"
      effort="30"
      velocity="3.14" />
  </joint>
  <link
    name="ZPF_left_Link5">
    <inertial>
      <origin
        xyz="-2.3965e-5 -2.247e-2 -8.5293e-2"
        rpy="0 0 0" />
      <mass
        value="1.017" />
      <inertia
        ixx="2.2579574e-03"
        ixy="2.0270009e-07"
        ixz="3.2535431e-08"
        iyy="2.0417531e-03"
        iyz="3.7131069e-04"
        izz="9.5194483e-04" />
    </inertial>
    <visual>
      <origin
        xyz="0 0 0"
        rpy="0 0 0" />
      <geometry>
        <mesh
          filename="Bot2_ZPF_L2Fgripper_R2Fgripper_A_description/meshes/ZPF_left_Link5.STL" />
      </geometry>
      <material
        name="">
        <color
          rgba="1 1 1 1" />
      </material>
    </visual>
    <collision>
      <origin
        xyz="0 0 0"
        rpy="0 0 0" />
      <geometry>
        <mesh
          filename="Bot2_ZPF_L2Fgripper_R2Fgripper_A_description/meshes/ZPF_left_Link5.STL" />
      </geometry>
    </collision>
  </link>
  <joint
    name="ZPF_left_Joint5"
    type="revolute">
    <origin
      xyz="-0.01 0.3088 0"
      rpy="-1.5708 0 0" />
    <parent
      link="ZPF_left_Link4" />
    <child
      link="ZPF_left_Link5" />
    <axis
      xyz="0 0 1" />
    <limit
      lower="-3.1"
      upper="3.1"
      effort="10"
      velocity="3.14" />
  </joint>
  <link
    name="ZPF_left_Link6">
    <inertial>
      <origin
        xyz="9.154e-3 -8.103e-3 2.957e-3"
        rpy="0 0 0" />
      <mass
        value="0.55" />
      <inertia
        ixx="3.7382788e-04"
        ixy="3.1477249e-06"
        ixz="1.5645983e-05"
        iyy="2.7467239e-04"
        iyz="-1.1682175e-05"
        izz="3.2231106e-04" />
    </inertial>
    <visual>
      <origin
        xyz="0 0 0"
        rpy="0 0 0" />
      <geometry>
        <mesh
          filename="Bot2_ZPF_L2Fgripper_R2Fgripper_A_description/meshes/ZPF_left_Link6.STL" />
      </geometry>
      <material
        name="">
        <color
          rgba="1 1 1 1" />
      </material>
    </visual>
    <collision>
      <origin
        xyz="0 0 0"
        rpy="0 0 0" />
      <geometry>
        <mesh
          filename="Bot2_ZPF_L2Fgripper_R2Fgripper_A_description/meshes/ZPF_left_Link6.STL" />
      </geometry>
    </collision>
  </link>
  <joint
    name="ZPF_left_Joint6"
    type="revolute">
    <origin
      xyz="0 0 0"
      rpy="1.5708 -1.5708 0" />
    <parent
      link="ZPF_left_Link5" />
    <child
      link="ZPF_left_Link6" />
    <axis
      xyz="0 0 1" />
    <limit
      lower="-1.22"
      upper="1.22"
      effort="10"
      velocity="3.14" />
  </joint>
  <link
    name="ZPF_left_Link7">
    <inertial>
      <origin
        xyz="1.547e-4 5.483e-2 5.55e-3"
        rpy="0 0 0" />
      <mass
        value="0.266" />
      <inertia
        ixx="0.000132576941913423"
        ixy="9.13805899339808E-06"
        ixz="-9.14363365511958E-08"
        iyy="0.000151676252224174"
        iyz="-2.82790388376229E-05"
        izz="0.000142517590749322" />
    </inertial>
    <visual>
      <origin
        xyz="0 0 0"
        rpy="0 0 0" />
      <geometry>
        <mesh
          filename="Bot2_ZPF_L2Fgripper_R2Fgripper_A_description/meshes/ZPF_left_Link7.STL" />
      </geometry>
      <material
        name="">
        <color
          rgba="1 1 1 1" />
      </material>
    </visual>
    <collision>
      <origin
        xyz="0 0 0"
        rpy="0 0 0" />
      <geometry>
        <mesh
          filename="Bot2_ZPF_L2Fgripper_R2Fgripper_A_description/meshes/ZPF_left_Link7.STL" />
      </geometry>
    </collision>
  </link>
  <joint
    name="ZPF_left_Joint7"
    type="revolute">
    <origin
      xyz="0.01 0 0"
      rpy="1.5708 -1.5708 0" />
    <parent
      link="ZPF_left_Link6" />
    <child
      link="ZPF_left_Link7" />
    <axis
      xyz="0 0 1" />
    <limit
      lower="-2.09"
      upper="0.49"
      effort="10"
      velocity="3.14" />
  </joint>
  <link
    name="ZPF_left_Link8">
    <inertial>
      <origin
        xyz="-0.000223537609806423 8.8367558294447E-05 -0.0171573759779855"
        rpy="0 0 0" />
      <mass
        value="0.165822774021484" />
      <inertia
        ixx="4.88486899397696E-05"
        ixy="-9.4591722796062E-08"
        ixz="3.0611887075293E-07"
        iyy="4.94603620572993E-05"
        iyz="8.02154219939052E-09"
        izz="7.6901626133018E-05" />
    </inertial>
    <visual>
      <origin
        xyz="0 0 0"
        rpy="0 0 0" />
      <geometry>
        <mesh
          filename="Bot2_ZPF_L2Fgripper_R2Fgripper_A_description/meshes/ZPF_left_Link8.STL" />
      </geometry>
      <material
        name="">
        <color
          rgba="1 1 1 1" />
      </material>
    </visual>
    <collision>
      <origin
        xyz="0 0 0"
        rpy="0 0 0" />
      <geometry>
        <mesh
          filename="Bot2_ZPF_L2Fgripper_R2Fgripper_A_description/meshes/ZPF_left_Link8.STL" />
      </geometry>
    </collision>
  </link>
  <joint
    name="ZPF_left_Joint8"
    type="fixed">
    <origin
      xyz="0 -0.11462 0"
      rpy="1.5708 0 0" />
    <parent
      link="ZPF_left_Link7" />
    <child
      link="ZPF_left_Link8" />
    <axis
      xyz="0 0 -1" />
    <limit
      lower="0"
      upper="0"
      effort="0"
      velocity="0" />
  </joint>
  <!-- 上面是ZPFL的左臂 -->
  <link
    name="2FEG_l_baselink">
    <inertial>
      <origin
        xyz="1.5645E-05 -4.1838E-06 0.038"
        rpy="0 0 0" />
      <mass
        value="0.072633" />
      <inertia
        ixx="5.095E-05"
        ixy="-7.3167E-13"
        ixz="2.0229E-08"
        iyy="6.0883E-05"
        iyz="-4.5583E-09"
        izz="1.933E-05" />
    </inertial>
    <visual>
      <origin
        xyz="0 0 0"
        rpy="0 0 0" />
      <geometry>
        <mesh
          filename="Bot2_ZPF_L2Fgripper_R2Fgripper_A_description/meshes/2FEG_l_baselink.STL" />
      </geometry>
      <material
        name="">
        <color
          rgba="0.75294 0.75294 0.75294 1" />
      </material>
    </visual>
    <collision>
      <origin
        xyz="0 0 0"
        rpy="0 0 0" />
      <geometry>
        <mesh
          filename="Bot2_ZPF_L2Fgripper_R2Fgripper_A_description/meshes/2FEG_l_baselink.STL" />
      </geometry>
    </collision>
  </link>
  <joint
    name="2FEG_l_baselink_joint"
    type="fixed">
    <origin
      xyz="0 0 0"
      rpy="0 0 1.5708" />
      <!-- 调整一下减去0.008 -->
    <parent
      link="ZPF_left_Link8" />
<!-- 我把这个线暂时设置为BASE_LINK -->
    <child
      link="2FEG_l_baselink" />
    <axis
      xyz="0 0 0" />
  </joint>
  <link
    name="2FEG_l_Link1">
    <inertial>
      <origin
        xyz="0.0087669 0.009 0.013992"
        rpy="0 0 0" />
      <mass
        value="0.0024292" />
      <inertia
        ixx="5.1061E-07"
        ixy="-8.6739E-19"
        ixz="-2.508E-07"
        iyy="5.7398E-07"
        iyz="-1.3667E-18"
        izz="2.6747E-07" />
    </inertial>
    <visual>
      <origin
        xyz="0 0 0"
        rpy="0 0 0" />
      <geometry>
        <mesh
          filename="Bot2_ZPF_L2Fgripper_R2Fgripper_A_description/meshes/2FEG_l_Link1.STL" />
      </geometry>
      <material
        name="">
        <color
          rgba="0.75294 0.75294 0.75294 1" />
      </material>
    </visual>
    <collision>
      <origin
        xyz="0 0 0"
        rpy="0 0 0" />
      <geometry>
        <mesh
          filename="Bot2_ZPF_L2Fgripper_R2Fgripper_A_description/meshes/2FEG_l_Link1.STL" />
      </geometry>
    </collision>
  </link>
  <joint
    name="2FEG_l_Joint1"
    type="revolute">
    <origin
      xyz="-0.04 -0.009 0.079"
      rpy="0 0 0" />
    <parent
      link="2FEG_l_baselink" />
    <child
      link="2FEG_l_Link1" />
    <axis
      xyz="0 -1 0" />
    <limit
      lower="0"
      upper="0.82"
      effort="1"
      velocity="1" />
  </joint>
  <link
    name="2FEG_l_Link5">
    <inertial>
      <origin
        xyz="0.011864 0.006 0.011367"
        rpy="0 0 0" />
      <mass
        value="0.0045068" />
      <inertia
        ixx="5.1288E-07"
        ixy="-9.8137E-14"
        ixz="-9.4703E-08"
        iyy="5.3203E-07"
        iyz="-6.212E-14"
        izz="2.009E-07" />
    </inertial>
    <visual>
      <origin
        xyz="0 0 0"
        rpy="0 0 0" />
      <geometry>
        <mesh
          filename="Bot2_ZPF_L2Fgripper_R2Fgripper_A_description/meshes/2FEG_l_Link5.STL" />
      </geometry>
      <material
        name="">
        <color
          rgba="0.75294 0.75294 0.75294 1" />
      </material>
    </visual>
    <collision>
      <origin
        xyz="0 0 0"
        rpy="0 0 0" />
      <geometry>
        <mesh
          filename="Bot2_ZPF_L2Fgripper_R2Fgripper_A_description/meshes/2FEG_l_Link5.STL" />
      </geometry>
    </collision>
  </link>
  <joint
    name="2FEG_l_Joint5"
    type="revolute">
    <origin
      xyz="0.0223 0.003 0.035591"
      rpy="0 0 0" />
    <parent
      link="2FEG_l_Link1" />
    <child
      link="2FEG_l_Link5" />
    <axis
      xyz="0 1 0" />
    <limit
      lower="0"
      upper="0.82"
      effort="1"
      velocity="1" />
    <mimic joint="2FEG_l_Joint1"/>
  </joint>
  <link
    name="2FEG_l_Link2">
    <inertial>
      <origin
        xyz="0.0087435 0.009 0.013955"
        rpy="0 0 0" />
      <mass
        value="0.0038971" />
      <inertia
        ixx="5.6941E-07"
        ixy="-1.0711E-18"
        ixz="-2.6891E-07"
        iyy="6.2305E-07"
        iyz="-1.6845E-18"
        izz="3.0871E-07" />
    </inertial>
    <visual>
      <origin
        xyz="0 0 0"
        rpy="0 0 0" />
      <geometry>
        <mesh
          filename="Bot2_ZPF_L2Fgripper_R2Fgripper_A_description/meshes/2FEG_l_Link2.STL" />
      </geometry>
      <material
        name="">
        <color
          rgba="0.75294 0.75294 0.75294 1" />
      </material>
    </visual>
    <collision>
      <origin
        xyz="0 0 0"
        rpy="0 0 0" />
      <geometry>
        <mesh
          filename="Bot2_ZPF_L2Fgripper_R2Fgripper_A_description/meshes/2FEG_l_Link2.STL" />
      </geometry>
    </collision>
  </link>
  <joint
    name="2FEG_l_Joint2"
    type="revolute">
    <origin
      xyz="-0.03 -0.009 0.081"
      rpy="0 0 0" />
    <parent
      link="2FEG_l_baselink" />
    <child
      link="2FEG_l_Link2" />
    <axis
      xyz="0 -1 0" />
    <limit
      lower="0"
      upper="0.82"
      effort="1"
      velocity="1" />
    <mimic joint="2FEG_l_Joint1"/>
  </joint>
  <link
    name="2FEG_l_Link3">
    <inertial>
      <origin
        xyz="-0.0087435 0.009 0.013955"
        rpy="0 0 0" />
      <mass
        value="0.0038971" />
      <inertia
        ixx="5.6941E-07"
        ixy="1.0666E-18"
        ixz="2.6891E-07"
        iyy="6.2305E-07"
        iyz="-1.8084E-18"
        izz="3.0871E-07" />
    </inertial>
    <visual>
      <origin
        xyz="0 0 0"
        rpy="0 0 0" />
      <geometry>
        <mesh
          filename="Bot2_ZPF_L2Fgripper_R2Fgripper_A_description/meshes/2FEG_l_Link3.STL" />
      </geometry>
      <material
        name="">
        <color
          rgba="0.75294 0.75294 0.75294 1" />
      </material>
    </visual>
    <collision>
      <origin
        xyz="0 0 0"
        rpy="0 0 0" />
      <geometry>
        <mesh
          filename="Bot2_ZPF_L2Fgripper_R2Fgripper_A_description/meshes/2FEG_l_Link3.STL" />
      </geometry>
    </collision>
  </link>
  <joint
    name="2FEG_l_Joint3"
    type="revolute">
    <origin
      xyz="0.03 -0.009 0.081"
      rpy="0 0 0" />
    <parent
      link="2FEG_l_baselink" />
    <child
      link="2FEG_l_Link3" />
    <axis
      xyz="0 -1 0" />
    <limit
      lower="-0.82"
      upper="0"
      effort="1"
      velocity="1" />
    <mimic joint="2FEG_l_Joint1" multiplier="-1"  offset="0"/>
  </joint>
  <link
    name="2FEG_l_Link4">
    <inertial>
      <origin
        xyz="-0.0087669 0.009 0.013992"
        rpy="0 0 0" />
      <mass
        value="0.0024292" />
      <inertia
        ixx="5.1061E-07"
        ixy="-9.5279E-19"
        ixz="2.508E-07"
        iyy="5.7398E-07"
        iyz="7.6863E-19"
        izz="2.6747E-07" />
    </inertial>
    <visual>
      <origin
        xyz="0 0 0"
        rpy="0 0 0" />
      <geometry>
        <mesh
          filename="Bot2_ZPF_L2Fgripper_R2Fgripper_A_description/meshes/2FEG_l_Link4.STL" />
      </geometry>
      <material
        name="">
        <color
          rgba="0.75294 0.75294 0.75294 1" />
      </material>
    </visual>
    <collision>
      <origin
        xyz="0 0 0"
        rpy="0 0 0" />
      <geometry>
        <mesh
          filename="Bot2_ZPF_L2Fgripper_R2Fgripper_A_description/meshes/2FEG_l_Link4.STL" />
      </geometry>
    </collision>
  </link>
  <joint
    name="2FEG_l_Joint4"
    type="revolute">
    <origin
      xyz="0.04 -0.009 0.079"
      rpy="0 0 0" />
    <parent
      link="2FEG_l_baselink" />
    <child
      link="2FEG_l_Link4" />
    <axis
      xyz="0 -1 0" />
    <limit
      lower="-0.82"
      upper="0"
      effort="1"
      velocity="1" />
    <mimic joint="2FEG_l_Joint1" multiplier="-1"  offset="0"/>
  </joint>
  <link
    name="2FEG_l_Link6">
    <inertial>
      <origin
        xyz="-0.011864 0.006 0.011367"
        rpy="0 0 0" />
      <mass
        value="0.0045068" />
      <inertia
        ixx="5.1288E-07"
        ixy="-9.8137E-14"
        ixz="9.4703E-08"
        iyy="5.3203E-07"
        iyz="6.2119E-14"
        izz="2.009E-07" />
    </inertial>
    <visual>
      <origin
        xyz="0 0 0"
        rpy="0 0 0" />
      <geometry>
        <mesh
          filename="Bot2_ZPF_L2Fgripper_R2Fgripper_A_description/meshes/2FEG_l_Link6.STL" />
      </geometry>
      <material
        name="">
        <color
          rgba="0.75294 0.75294 0.75294 1" />
      </material>
    </visual>
    <collision>
      <origin
        xyz="0 0 0"
        rpy="0 0 0" />
      <geometry>
        <mesh
          filename="Bot2_ZPF_L2Fgripper_R2Fgripper_A_description/meshes/2FEG_l_Link6.STL" />
      </geometry>
    </collision>
  </link>
  <joint
    name="2FEG_l_Joint6"
    type="revolute">
    <origin
      xyz="-0.0223 0.003 0.035591"
      rpy="0 0 0" />
    <parent
      link="2FEG_l_Link4" />
    <child
      link="2FEG_l_Link6" />
    <axis
      xyz="0 -1 0" />
    <limit
      lower="0"
      upper="0.82"
      effort="1"
      velocity="1" />
    <mimic joint="2FEG_l_Joint1"/>
  </joint>
  <link
    name="ZPF_right_base_link">
    <inertial>
      <origin
        xyz="2.6156962e-04  -8.8049196e-05  3.9913685e-02"
        rpy="0 0 0" />
      <mass
        value="1.39" />
      <inertia
        ixx="1.7514573e-03"
        ixy="-7.1608268e-07"
        ixz="1.7226023e-05"
        iyy="1.7472324e-03"
        iyz="-5.4661047e-06"
        izz="1.1808076e-03" />
    </inertial>
    <visual>
      <origin
        xyz="0 0 0"
        rpy="0 0 0" />
      <geometry>
        <mesh
          filename="Bot2_ZPF_L2Fgripper_R2Fgripper_A_description/meshes/ZPF_right_base_link.STL" />
      </geometry>
      <material
        name="">
        <color
          rgba="0.86667 0.86667 0.8902 1" />
      </material>
    </visual>
    <collision>
      <origin
        xyz="0 0 0"
        rpy="0 0 0" />
      <geometry>
        <mesh
          filename="Bot2_ZPF_L2Fgripper_R2Fgripper_A_description/meshes/ZPF_right_base_link.STL" />
      </geometry>
    </collision>
  </link>
  <joint
    name="ZPF_right_base_joint_0"
    type="fixed">
    <origin
      xyz="-0.061 -0.0485 0.3255"
      rpy="1.5708 -1.5708 0" />
    <parent
      link="waist_yaw_torso_link" />
    <child
      link="ZPF_right_base_link" />
    <axis
      xyz="0 0 0" />
  </joint>
<!-- 以下是原来版本的urdf，应删除
空白
空白
空白 -->
  <!-- <link
    name="ZM73_6FB_right_Link_1">
    <inertial>
      <origin
        xyz="-2.0626788e-03  1.6924446e-02 -2.8847482e-02"
        rpy="0 0 0" />
      <mass
        value="0.65" />
      <inertia
        ixx="1.7020262e-03"
        ixy="5.9529311e-05"
        ixz="1.5086619e-04"
        iyy="1.6194527e-03"
        iyz="-2.1354425e-04"
        izz="1.5939956e-03" />
    </inertial>
    <visual>
      <origin
        xyz="0 0 0"
        rpy="0 0 3.1416" />
      <geometry>
        <mesh
          filename="Bot2_ZPF_L2Fgripper_R2Fgripper_A_description/meshes/ZM73_6FB_right_Link_1.STL" />
      </geometry>
      <material
        name="">
        <color
          rgba="0.86667 0.86667 0.8902 1" />
      </material>
    </visual>
    <collision>
      <origin
        xyz="0 0 0"
        rpy="0 0 3.1416" />
      <geometry>
        <mesh
          filename="Bot2_ZPF_L2Fgripper_R2Fgripper_A_description/meshes/ZM73_6FB_right_Link_1.STL" />
      </geometry>
    </collision>
  </link>
  <joint
    name="ZM73_6FB_right_joint_1"
    type="revolute">
    <origin
      xyz="0 0 0.1785"
      rpy="0 0 0" />
    <parent
      link="ZM73_6FB_right_base_link" />
    <child
      link="ZM73_6FB_right_Link_1" />
    <axis
      xyz="0 0 1" />
    <limit
      lower="-3.1"
      upper="3.1"
      effort="60"
      velocity="3.14" />
  </joint>
  <link
    name="ZM73_6FB_right_Link_2">
    <inertial>
      <origin
        xyz=" 1.1680230e-04 -6.5574182e-03  1.5049631e-02"
        rpy="0 0 0" />
      <mass
        value="1.37" />
      <inertia
        ixx="1.8034273e-03"
        ixy="-1.0921536e-06"
        ixz="4.0562036e-06"
        iyy="1.2896722e-03"
        iyz="-1.1968272e-04"
        izz="1.5737028e-03" />
    </inertial>
    <visual>
      <origin
        xyz="0 0 0"
        rpy="0 0 0" />
      <geometry>
        <mesh
          filename="Bot2_ZPF_L2Fgripper_R2Fgripper_A_description/meshes/ZM73_6FB_right_Link_2.STL" />
      </geometry>
      <material
        name="">
        <color
          rgba="0.86667 0.86667 0.8902 1" />
      </material>
    </visual>
    <collision>
      <origin
        xyz="0 0 0"
        rpy="0 0 0" />
      <geometry>
        <mesh
          filename="Bot2_ZPF_L2Fgripper_R2Fgripper_A_description/meshes/ZM73_6FB_right_Link_2.STL" />
      </geometry>
    </collision>
  </link>
  <joint
    name="ZM73_6FB_right_joint_2"
    type="revolute">
    <origin
      xyz="0 0 0"
      rpy="-1.5708 -1.5708 0" />
    <parent
      link="ZM73_6FB_right_Link_1" />
    <child
      link="ZM73_6FB_right_Link_2" />
    <axis
      xyz="0 0 1" />
    <limit
      lower="-0.43"
      upper="3.1"
      effort="60"
      velocity="3.14" />
  </joint>
  <link
    name="ZM73_6FB_right_Link_3">
    <inertial>
      <origin
        xyz="4.7865444e-03 -3.1920489e-03 -9.2988379e-02"
        rpy="0 0 0" />
      <mass
        value="2.25" />
      <inertia
        ixx="1.7835120e-02"
        ixy="2.9186739e-05 "
        ixz="-9.4187028e-04"
        iyy="1.7664305e-02"
        iyz="7.1721148e-04"
        izz="1.7726268e-03" />
    </inertial>
    <visual>
      <origin
        xyz="0 0 0"
        rpy="0 0 0" />
      <geometry>
        <mesh
          filename="Bot2_ZPF_L2Fgripper_R2Fgripper_A_description/meshes/ZM73_6FB_right_Link_3.STL" />
      </geometry>
      <material
        name="">
        <color
          rgba="0.86667 0.86667 0.8902 1" />
      </material>
    </visual>
    <collision>
      <origin
        xyz="0 0 0"
        rpy="0 0 0" />
      <geometry>
        <mesh
          filename="Bot2_ZPF_L2Fgripper_R2Fgripper_A_description/meshes/ZM73_6FB_right_Link_3.STL" />
      </geometry>
    </collision>
  </link>
  <joint
    name="ZM73_6FB_right_joint_3"
    type="revolute">
    <origin
      xyz="0 -0.28998 0"
      rpy="1.5708 1.5708 0" />
    <parent
      link="ZM73_6FB_right_Link_2" />
    <child
      link="ZM73_6FB_right_Link_3" />
    <axis
      xyz="0 0 1" />
    <limit
      lower="-3.1"
      upper="3.1"
      effort="30"
      velocity="3.925" />
  </joint>
  <link
    name="ZM73_6FB_right_Link_4">
    <inertial>
      <origin
        xyz="-9.4244792e-03  8.6907631e-02  4.9490148e-03"
        rpy="0 0 0" />
      <mass
        value="0.86" />
      <inertia
        ixx="3.0979180e-03"
        ixy="-2.2400381e-05"
        ixz="-3.5082686e-05"
        iyy="7.6662000e-04"
        iyz="2.7748587e-04"
        izz="2.9734939e-03" />
    </inertial>
    <visual>
      <origin
        xyz="0 0 0"
        rpy="0 0 0" />
      <geometry>
        <mesh
          filename="Bot2_ZPF_L2Fgripper_R2Fgripper_A_description/meshes/ZM73_6FB_right_Link_4.STL" />
      </geometry>
      <material
        name="">
        <color
          rgba="0.86667 0.86667 0.8902 1" />
      </material>
    </visual>
    <collision>
      <origin
        xyz="0 0 0"
        rpy="0 0 0" />
      <geometry>
        <mesh
          filename="Bot2_ZPF_L2Fgripper_R2Fgripper_A_description/meshes/ZM73_6FB_right_Link_4.STL" />
      </geometry>
    </collision>
  </link>
  <joint
    name="ZM73_6FB_right_joint_4"
    type="revolute">
    <origin
      xyz="0.01 0 0"
      rpy="1.5708 0 0" />
    <parent
      link="ZM73_6FB_right_Link_3" />
    <child
      link="ZM73_6FB_right_Link_4" />
    <axis
      xyz="0 0 1" />
    <limit
      lower="-2.26"
      upper="0"
      effort="30"
      velocity="3.925" />
  </joint>
  <link
    name="ZM73_6FB_right_Link_5">
    <inertial>
      <origin
        xyz="-2.4492878e-05  2.2626784e-02 -8.5111454e-02"
        rpy="0 0 0" />
      <mass
        value="1.02" />
      <inertia
        ixx="2.2862825e-03"
        ixy="-1.8499609e-07"
        ixz="4.9891167e-08"
        iyy="2.0659134e-03"
        iyz="-3.7974533e-04"
        izz="9.6048783e-04" />
    </inertial>
    <visual>
      <origin
        xyz="0 0 0"
        rpy="0 0 0" />
      <geometry>
        <mesh
          filename="Bot2_ZPF_L2Fgripper_R2Fgripper_A_description/meshes/ZM73_6FB_right_Link_5.STL" />
      </geometry>
      <material
        name="">
        <color
          rgba="0.86667 0.86667 0.8902 1" />
      </material>
    </visual>
    <collision>
      <origin
        xyz="0 0 0"
        rpy="0 0 0" />
      <geometry>
        <mesh
          filename="Bot2_ZPF_L2Fgripper_R2Fgripper_A_description/meshes/ZM73_6FB_right_Link_5.STL" />
      </geometry>
    </collision>
  </link>
  <joint
    name="ZM73_6FB_right_joint_5"
    type="revolute">
    <origin
      xyz="-0.01 0.30879 0"
      rpy="-1.5708 0 0" />
    <parent
      link="ZM73_6FB_right_Link_4" />
    <child
      link="ZM73_6FB_right_Link_5" />
    <axis
      xyz="0 0 1" />
    <limit
      lower="-3.14"
      upper="3.14"
      effort="10"
      velocity="3.925" />
  </joint>
  <link
    name="ZM73_6FB_right_Link_6">
    <inertial>
      <origin
        xyz="9.1493443e-03 -8.1014674e-03 -3.0066734e-03"
        rpy="0 0 0" />
      <mass
        value="0.55" />
      <inertia
        ixx="3.7537073e-04"
        ixy="3.1868444e-06"
        ixz="-1.5769918e-05"
        iyy="2.7629393e-04"
        iyz="1.1957640e-05"
        izz="3.2291903e-04" />
    </inertial>
    <visual>
      <origin
        xyz="0 0 0"
        rpy="0 0 0" />
      <geometry>
        <mesh
          filename="Bot2_ZPF_L2Fgripper_R2Fgripper_A_description/meshes/ZM73_6FB_right_Link_6.STL" />
      </geometry>
      <material
        name="">
        <color
          rgba="0.86667 0.86667 0.8902 1" />
      </material>
    </visual>
    <collision>
      <origin
        xyz="0 0 0"
        rpy="0 0 0" />
      <geometry>
        <mesh
          filename="Bot2_ZPF_L2Fgripper_R2Fgripper_A_description/meshes/ZM73_6FB_right_Link_6.STL" />
      </geometry>
    </collision>
  </link>
  <joint
    name="ZM73_6FB_right_joint_6"
    type="revolute">
    <origin
      xyz="0 0 0"
      rpy="1.5708 -1.5708 0" />
    <parent
      link="ZM73_6FB_right_Link_5" />
    <child
      link="ZM73_6FB_right_Link_6" />
    <axis
      xyz="0 0 1" />
    <limit
      lower="-1.22"
      upper="1.22"
      effort="10"
      velocity="3.925" />
  </joint>
  <link
    name="ZM73_6FB_right_Link_7">
    <inertial>
      <origin
        xyz="-6.8522347e-04  5.4274486e-02  5.4410129e-03"
        rpy="0 0 0" />
      <mass
        value="0.28" />
      <inertia
        ixx="3.4122621e-04"
        ixy="-1.3285267e-06"
        ixz="-1.1687335e-06"
        iyy="1.6866795e-04"
        iyz="8.0271964e-05"
        izz="3.1200735e-04" />
    </inertial>
    <visual>
      <origin
        xyz="0 0 0"
        rpy="0 0 0" />
      <geometry>
        <mesh
          filename="Bot2_ZPF_L2Fgripper_R2Fgripper_A_description/meshes/ZM73_6FB_right_Link_7.STL" />
      </geometry>
      <material
        name="">
        <color
          rgba="0.86667 0.86667 0.8902 1" />
      </material>
    </visual>
    <collision>
      <origin
        xyz="0 0 0"
        rpy="0 0 0" />
      <geometry>
        <mesh
          filename="Bot2_ZPF_L2Fgripper_R2Fgripper_A_description/meshes/ZM73_6FB_right_Link_7.STL" />
      </geometry>
    </collision>
  </link>
  <joint
    name="ZM73_6FB_right_joint_7"
    type="revolute">
    <origin
      xyz="0.01 0 0"
      rpy="1.5708 1.5708 0" />
    <parent
      link="ZM73_6FB_right_Link_6" />
    <child
      link="ZM73_6FB_right_Link_7" />
    <axis
      xyz="0 0 1" />
    <limit
      lower="-0.48"
      upper="2.09"
      effort="10"
      velocity="3.925" />
  </joint>
  <link
    name="ZM73_6FB_right_Link_8">
    <inertial>
      <origin
        xyz="-0.00024477 7.5449E-05 -0.017161"
        rpy="0 0 0" />
      <mass
        value="0.16601" />
      <inertia
        ixx="4.8847E-05"
        ixy="-9.5848E-08"
        ixz="3.0777E-07"
        iyy="4.9461E-05"
        iyz="7.8601E-09"
        izz="7.6898E-05" />
    </inertial>
    <visual>
      <origin
        xyz="0 0 0"
        rpy="0 0 0" />
      <geometry>
        <mesh
          filename="Bot2_ZPF_L2Fgripper_R2Fgripper_A_description/meshes/ZM73_6FB_right_Link_8.STL" />
      </geometry>
      <material
        name="">
        <color
          rgba="0.86667 0.86667 0.8902 1" />
      </material>
    </visual>
    <collision>
      <origin
        xyz="0 0 0"
        rpy="0 0 0" />
      <geometry>
        <mesh
          filename="Bot2_ZPF_L2Fgripper_R2Fgripper_A_description/meshes/ZM73_6FB_right_Link_8.STL" />
      </geometry>
    </collision>
  </link>
  <joint
    name="ZM73_6FB_right_joint_8"
    type="fixed">
    <origin
      xyz="0 0.0912 0"
      rpy="-1.5708 0 0" />
    <parent
      link="ZM73_6FB_right_Link_7" />
    <child
      link="ZM73_6FB_right_Link_8" />
    <axis
      xyz="0 0 1" />
  </joint>
  <link
    name="Camera_flange_R_link">
    <inertial>
      <origin
        xyz="0.061357 -0.0040163 0.0055939"
        rpy="0 0 0" />
      <mass
        value="0.17555" />
      <inertia
        ixx="8.6461E-05"
        ixy="5.1529E-06"
        ixz="-5.8712E-07"
        iyy="0.00022691"
        iyz="-1.3578E-11"
        izz="0.00031166" />
    </inertial>
    <visual>
      <origin
        xyz="0 0 0"
        rpy="0 0 0" />
      <geometry>
        <mesh
          filename="Bot2_ZPF_L2Fgripper_R2Fgripper_A_description/meshes/Camera_flange_R_link.STL" />
      </geometry>
      <material
        name="">
        <color
          rgba="0.89804 0.91765 0.92941 1" />
      </material>
    </visual>
    <collision>
      <origin
        xyz="0 0 0"
        rpy="0 0 0" />
      <geometry>
        <mesh
          filename="Bot2_ZPF_L2Fgripper_R2Fgripper_A_description/meshes/Camera_flange_R_link.STL" />
      </geometry>
    </collision>
  </link>
  <joint
    name="Camera_flange_R_joint"
    type="fixed">
    <origin
      xyz="0 0 0"
      rpy="0 0 0" />
    <parent
      link="ZM73_6FB_right_Link_8" />
    <child
      link="Camera_flange_R_link" />
    <axis
      xyz="0 0 0" />
  </joint>
  <link
    name="Camera_linear_adjustment_R_link">
    <inertial>
      <origin
        xyz="5.7855E-05 -0.010763 1.3878E-16"
        rpy="0 0 0" />
      <mass
        value="0.0032684" />
      <inertia
        ixx="2.3915E-06"
        ixy="3.1894E-09"
        ixz="-1.0178E-19"
        iyy="2.3587E-06"
        iyz="6.1675E-22"
        izz="1.559E-07" />
    </inertial>
    <visual>
      <origin
        xyz="0 0 0"
        rpy="0 0 0" />
      <geometry>
        <mesh
          filename="Bot2_ZPF_L2Fgripper_R2Fgripper_A_description/meshes/Camera_linear_adjustment_R_link.STL" />
      </geometry>
      <material
        name="">
        <color
          rgba="0.98824 0.73725 0.51765 1" />
      </material>
    </visual>
    <collision>
      <origin
        xyz="0 0 0"
        rpy="0 0 0" />
      <geometry>
        <mesh
          filename="Bot2_ZPF_L2Fgripper_R2Fgripper_A_description/meshes/Camera_linear_adjustment_R_link.STL" />
      </geometry>
    </collision>
  </link>
  <joint
    name="Camera_linear_adjustment_R_joint"
    type="prismatic">
    <origin
      xyz="0.114 -0.055 0.008"
      rpy="-1.5708 0 0" />
    <parent
      link="Camera_flange_R_link" />
    <child
      link="Camera_linear_adjustment_R_link" />
    <axis
      xyz="0 0 1" />
    <limit
      lower="0"
      upper="0.055"
      effort="1000"
      velocity="10" />
  </joint>
  <link
    name="Camera_angle_adjustment_R_link">
    <inertial>
      <origin
        xyz="0.0039375 0.02065 0.0015017"
        rpy="0 0 0" />
      <mass
        value="0.03937" />
      <inertia
        ixx="2.3294E-05"
        ixy="-1.0638E-08"
        ixz="-7.8553E-09"
        iyy="2.4601E-05"
        iyz="4.5141E-08"
        izz="2.1824E-06" />
    </inertial>
    <visual>
      <origin
        xyz="0 0 0"
        rpy="0 0 0" />
      <geometry>
        <mesh
          filename="Bot2_ZPF_L2Fgripper_R2Fgripper_A_description/meshes/Camera_angle_adjustment_R_link.STL" />
      </geometry>
      <material
        name="">
        <color
          rgba="1 1 0.50196 1" />
      </material>
    </visual>
    <collision>
      <origin
        xyz="0 0 0"
        rpy="0 0 0" />
      <geometry>
        <mesh
          filename="Bot2_ZPF_L2Fgripper_R2Fgripper_A_description/meshes/Camera_angle_adjustment_R_link.STL" />
      </geometry>
    </collision>
  </link>
  <joint
    name="Camera_angle_adjustment_R_joint"
    type="revolute">
    <origin
      xyz="-0.0039 -0.021 0"
      rpy="3.1416 0 0" />
    <parent
      link="Camera_linear_adjustment_R_link" />
    <child
      link="Camera_angle_adjustment_R_link" />
    <axis
      xyz="0 0 1" />
    <limit
      lower="0"
      upper="1.5708"
      effort="1000"
      velocity="10" />
  </joint> -->
  <!-- 以上是原来版本的urdf，应删除 -->
  <link
    name="ZPF_right_Link1">
    <inertial>
      <origin
        xyz="-2.0626e-3 1.692e-2 -2.885e-2"
        rpy="0 0 0" />
      <mass
        value="0.6469" />
      <inertia
        ixx="1.7020262e-03"
        ixy="5.9529311e-05"
        ixz="1.5086619e-04"
        iyy="1.6194527e-03"
        iyz="-2.1354425e-04"
        izz="1.5939956e-03" />
    </inertial>
    <visual>
      <origin
        xyz="0 0 0"
        rpy="0 0 0" />
      <geometry>
        <mesh
          filename="Bot2_ZPF_L2Fgripper_R2Fgripper_A_description/meshes/ZPF_right_Link1.STL" />
      </geometry>
      <material
        name="">
        <color
          rgba="1 1 1 1" />
      </material>
    </visual>
    <collision>
      <origin
        xyz="0 0 0"
        rpy="0 0 0" />
      <geometry>
        <mesh
          filename="Bot2_ZPF_L2Fgripper_R2Fgripper_A_description/meshes/ZPF_right_Link1.STL" />
      </geometry>
    </collision>
  </link>
  <joint
    name="ZPF_right_Joint1"
    type="revolute">
    <origin
      xyz="0 0 0.1785"
      rpy="0 0 0" />
    <parent
      link="ZPF_right_base_link" />
      <!-- 这块还没改 -->
    <child
      link="ZPF_right_Link1" />
    <axis
      xyz="0 0 1" />
    <limit
      lower="-3.1"
      upper="3.1"
      effort="60"
      velocity="3.14" />
  </joint>
  <link
    name="ZPF_right_Link2">
    <inertial>
      <origin
        xyz="1.168e-4 -6.557e-3 1.5049e-2"
        rpy="0 0 0" />
      <mass
        value="1.37" />
      <inertia
        ixx="1.8034273e-03"
        ixy="-1.0921536e-06"
        ixz="4.0562036e-06"
        iyy="1.2896722e-03"
        iyz="-1.1968272e-04"
        izz="1.5737028e-03" />
    </inertial>
    <visual>
      <origin
        xyz="0 0 0"
        rpy="0 0 0" />
      <geometry>
        <mesh
          filename="Bot2_ZPF_L2Fgripper_R2Fgripper_A_description/meshes/ZPF_right_Link2.STL" />
      </geometry>
      <material
        name="">
        <color
          rgba="1 1 1 1" />
      </material>
    </visual>
    <collision>
      <origin
        xyz="0 0 0"
        rpy="0 0 0" />
      <geometry>
        <mesh
          filename="Bot2_ZPF_L2Fgripper_R2Fgripper_A_description/meshes/ZPF_right_Link2.STL" />
      </geometry>
    </collision>
  </link>
  <joint
    name="ZPF_right_Joint2"
    type="revolute">
    <origin
      xyz="0 0 0"
      rpy="-1.5708 -1.5708 0" />
    <parent
      link="ZPF_right_Link1" />
    <child
      link="ZPF_right_Link2" />
    <axis
      xyz="0 0 1" />
    <limit
      lower="-0.44"
      upper="3.1"
      effort="60"
      velocity="3.14" />
  </joint>
  <link
    name="ZPF_right_Link3">
    <inertial>
      <origin
        xyz="4.7865e-3 -3.192e-3 -9.2988e-2"
        rpy="0 0 0" />
      <mass
        value="2.25" />
      <inertia
        ixx="1.7835120e-02"
        ixy="2.9186739e-05 "
        ixz="-9.4187028e-04"
        iyy="1.7664305e-02"
        iyz="7.1721148e-04"
        izz="1.7726268e-03" />
    </inertial>
    <visual>
      <origin
        xyz="0 0 0"
        rpy="0 0 0" />
      <geometry>
        <mesh
          filename="Bot2_ZPF_L2Fgripper_R2Fgripper_A_description/meshes/ZPF_right_Link3.STL" />
      </geometry>
      <material
        name="">
        <color
          rgba="1 1 1 1" />
      </material>
    </visual>
    <collision>
      <origin
        xyz="0 0 0"
        rpy="0 0 0" />
      <geometry>
        <mesh
          filename="Bot2_ZPF_L2Fgripper_R2Fgripper_A_description/meshes/ZPF_right_Link3.STL" />
      </geometry>
    </collision>
  </link>
  <joint
    name="ZPF_right_Joint3"
    type="revolute">
    <origin
      xyz="0 -0.28998 0"
      rpy="1.5708 1.5708 0" />
    <parent
      link="ZPF_right_Link2" />
    <child
      link="ZPF_right_Link3" />
    <axis
      xyz="0 0 1" />
    <limit
      lower="-3.1"
      upper="3.1"
      effort="30"
      velocity="3.14" />
  </joint>
  <link
    name="ZPF_right_Link4">
    <inertial>
      <origin
        xyz="-9.4244e-3 8.6907e-2 4.949e-3"
        rpy="0 0 0" />
      <mass
        value="0.86" />
      <inertia
        ixx="3.0979180e-03"
        ixy="-2.2400381e-05"
        ixz="-3.5082686e-05"
        iyy="7.6662000e-04"
        iyz="2.7748587e-04"
        izz="2.9734939e-03" />
    </inertial>
    <visual>
      <origin
        xyz="0 0 0"
        rpy="0 0 0" />
      <geometry>
        <mesh
          filename="Bot2_ZPF_L2Fgripper_R2Fgripper_A_description/meshes/ZPF_right_Link4.STL" />
      </geometry>
      <material
        name="">
        <color
          rgba="1 1 1 1" />
      </material>
    </visual>
    <collision>
      <origin
        xyz="0 0 0"
        rpy="0 0 0" />
      <geometry>
        <mesh
          filename="Bot2_ZPF_L2Fgripper_R2Fgripper_A_description/meshes/ZPF_right_Link4.STL" />
      </geometry>
    </collision>
  </link>
  <joint
    name="ZPF_right_Joint4"
    type="revolute">
    <origin
      xyz="0.01 0 0"
      rpy="1.5708 0 0" />
    <parent
      link="ZPF_right_Link3" />
    <child
      link="ZPF_right_Link4" />
    <axis
      xyz="0 0 1" />
    <limit
      lower="-2.27"
      upper="0"
      effort="30"
      velocity="3.14" />
  </joint>
  <link
    name="ZPF_right_Link5">
    <inertial>
      <origin
        xyz="-2.4492e-5 2.26e-2 -8.511e-2"
        rpy="0 0 0" />
      <mass
        value="1.02" />
      <inertia
        ixx="2.2862825e-03"
        ixy="-1.8499609e-07"
        ixz="4.9891167e-08"
        iyy="2.0659134e-03"
        iyz="-3.7974533e-04"
        izz="9.6048783e-04" />
    </inertial>
    <visual>
      <origin
        xyz="0 0 0"
        rpy="0 0 0" />
      <geometry>
        <mesh
          filename="Bot2_ZPF_L2Fgripper_R2Fgripper_A_description/meshes/ZPF_right_Link5.STL" />
      </geometry>
      <material
        name="">
        <color
          rgba="1 1 1 1" />
      </material>
    </visual>
    <collision>
      <origin
        xyz="0 0 0"
        rpy="0 0 0" />
      <geometry>
        <mesh
          filename="Bot2_ZPF_L2Fgripper_R2Fgripper_A_description/meshes/ZPF_right_Link5.STL" />
      </geometry>
    </collision>
  </link>
  <joint
    name="ZPF_right_Joint5"
    type="revolute">
    <origin
      xyz="-0.01 0.3088 0"
      rpy="-1.5708 0 0" />
    <parent
      link="ZPF_right_Link4" />
    <child
      link="ZPF_right_Link5" />
    <axis
      xyz="0 0 1" />
    <limit
      lower="-3.1"
      upper="3.1"
      effort="10"
      velocity="3.14" />
  </joint>
  <link
    name="ZPF_right_Link6">
    <inertial>
      <origin
        xyz="9.1493e-3 -8.101e-3 -3.00667e-3"
        rpy="0 0 0" />
      <mass
        value="0.55" />
      <inertia
        ixx="3.7537073e-04"
        ixy="3.1868444e-06"
        ixz="-1.5769918e-05"
        iyy="2.7629393e-04"
        iyz="1.1957640e-05"
        izz="3.2291903e-04" />
    </inertial>
    <visual>
      <origin
        xyz="0 0 0"
        rpy="0 0 0" />
      <geometry>
        <mesh
          filename="Bot2_ZPF_L2Fgripper_R2Fgripper_A_description/meshes/ZPF_right_Link6.STL" />
      </geometry>
      <material
        name="">
        <color
          rgba="1 1 1 1" />
      </material>
    </visual>
    <collision>
      <origin
        xyz="0 0 0"
        rpy="0 0 0" />
      <geometry>
        <mesh
          filename="Bot2_ZPF_L2Fgripper_R2Fgripper_A_description/meshes/ZPF_right_Link6.STL" />
      </geometry>
    </collision>
  </link>
  <joint
    name="ZPF_right_Joint6"
    type="revolute">
    <origin
      xyz="0 0 0"
      rpy="1.5708 -1.5708 0" />
    <parent
      link="ZPF_right_Link5" />
    <child
      link="ZPF_right_Link6" />
    <axis
      xyz="0 0 1" />
    <limit
      lower="-1.22"
      upper="1.22"
      effort="10"
      velocity="3.14" />
  </joint>
  <link
    name="ZPF_right_Link7">
    <inertial>
      <origin
        xyz="-6.8522e-4 5.4274e-2 5.44e-3"
        rpy="0 0 0" />
      <mass
        value="0.278" />
      <inertia
        ixx="0.000132576283150348"
        ixy="-9.13925548006411E-06"
        ixz="4.20109574651154E-07"
        iyy="0.000151675646214133"
        iyz="2.83539055428198E-05"
        izz="0.000142517526382716" />
    </inertial>
    <visual>
      <origin
        xyz="0 0 0"
        rpy="0 0 0" />
      <geometry>
        <mesh
          filename="Bot2_ZPF_L2Fgripper_R2Fgripper_A_description/meshes/ZPF_right_Link7.STL" />
      </geometry>
      <material
        name="">
        <color
          rgba="1 1 1 1" />
      </material>
    </visual>
    <collision>
      <origin
        xyz="0 0 0"
        rpy="0 0 0" />
      <geometry>
        <mesh
          filename="Bot2_ZPF_L2Fgripper_R2Fgripper_A_description/meshes/ZPF_right_Link7.STL" />
      </geometry>
    </collision>
  </link>
  <joint
    name="ZPF_right_Joint7"
    type="revolute">
    <origin
      xyz="0.01 0 0"
      rpy="1.5708 1.5708 0" />
    <parent
      link="ZPF_right_Link6" />
    <child
      link="ZPF_right_Link7" />
    <axis
      xyz="0 0 1" />
    <limit
      lower="-0.49"
      upper="2.09"
      effort="10"
      velocity="3.14" />
  </joint>
  <link
    name="ZPF_right_Link8">
    <inertial>
      <origin
        xyz="-0.000223537301525578 8.83815960186004E-05 -0.0171573736296614"
        rpy="0 0 0" />
      <mass
        value="0.165822770817375" />
      <inertia
        ixx="4.88486835315513E-05"
        ixy="-9.4591517590295E-08"
        ixz="3.06121334035521E-07"
        iyy="4.94603562925533E-05"
        iyz="8.02679892105756E-09"
        izz="7.69016251075802E-05" />
    </inertial>
    <visual>
      <origin
        xyz="0 0 0"
        rpy="0 0 0" />
      <geometry>
        <mesh
          filename="Bot2_ZPF_L2Fgripper_R2Fgripper_A_description/meshes/ZPF_right_Link8.STL" />
      </geometry>
      <material
        name="">
        <color
          rgba="0.898039215686275 0.917647058823529 0.929411764705882 1" />
      </material>
    </visual>
    <collision>
      <origin
        xyz="0 0 0"
        rpy="0 0 0" />
      <geometry>
        <mesh
          filename="Bot2_ZPF_L2Fgripper_R2Fgripper_A_description/meshes/ZPF_right_Link8.STL" />
      </geometry>
    </collision>
  </link>
  <joint
    name="ZPF_right_Joint8"
    type="fixed">
    <origin
      xyz="0 0.11462 0"
      rpy="-1.5708 0 0" />
    <parent
      link="ZPF_right_Link7" />
    <child
      link="ZPF_right_Link8" />
    <axis
      xyz="0 0 1" />
  </joint>
  <!-- 上面是ZPFR的右臂 -->
  <link
    name="2FEG_r_baselink">
    <inertial>
      <origin
        xyz="1.5645E-05 -4.1838E-06 0.038"
        rpy="0 0 0" />
      <mass
        value="0.072633" />
      <inertia
        ixx="5.095E-05"
        ixy="-7.3167E-13"
        ixz="2.0229E-08"
        iyy="6.0883E-05"
        iyz="-4.5583E-09"
        izz="1.933E-05" />
    </inertial>
    <visual>
      <origin
        xyz="0 0 0"
        rpy="0 0 0" />
      <geometry>
        <mesh
          filename="Bot2_ZPF_L2Fgripper_R2Fgripper_A_description/meshes/2FEG_r_baselink.STL" />
      </geometry>
      <material
        name="">
        <color
          rgba="0.75294 0.75294 0.75294 1" />
      </material>
    </visual>
    <collision>
      <origin
        xyz="0 0 0"
        rpy="0 0 0" />
      <geometry>
        <mesh
          filename="Bot2_ZPF_L2Fgripper_R2Fgripper_A_description/meshes/2FEG_r_baselink.STL" />
      </geometry>
    </collision>
  </link>
  <joint
    name="2FEG_r_baselink_joint"
    type="fixed">
    <origin
      xyz="0 0 0"
      rpy="0 0 -1.5708" />
      <!-- Z改为0 -->
    <parent
      link="ZPF_right_Link8" />
    <child
      link="2FEG_r_baselink" />
    <axis
      xyz="0 0 0" />
  </joint>
  <link
    name="2FEG_r_Link1">
    <inertial>
      <origin
        xyz="0.0087669 0.009 0.013992"
        rpy="0 0 0" />
      <mass
        value="0.0024292" />
      <inertia
        ixx="5.1061E-07"
        ixy="-8.6739E-19"
        ixz="-2.508E-07"
        iyy="5.7398E-07"
        iyz="-1.3667E-18"
        izz="2.6747E-07" />
    </inertial>
    <visual>
      <origin
        xyz="0 0 0"
        rpy="0 0 0" />
      <geometry>
        <mesh
          filename="Bot2_ZPF_L2Fgripper_R2Fgripper_A_description/meshes/2FEG_r_Link1.STL" />
      </geometry>
      <material
        name="">
        <color
          rgba="0.75294 0.75294 0.75294 1" />
      </material>
    </visual>
    <collision>
      <origin
        xyz="0 0 0"
        rpy="0 0 0" />
      <geometry>
        <mesh
          filename="Bot2_ZPF_L2Fgripper_R2Fgripper_A_description/meshes/2FEG_r_Link1.STL" />
      </geometry>
    </collision>
  </link>
  <joint
    name="2FEG_r_Joint1"
    type="revolute">
    <origin
      xyz="-0.04 -0.009 0.079"
      rpy="0 0 0" />
    <parent
      link="2FEG_r_baselink" />
    <child
      link="2FEG_r_Link1" />
    <axis
      xyz="0 -1 0" />
    <limit
      lower="0"
      upper="0.82"
      effort="1"
      velocity="1" />
  </joint>
  <link
    name="2FEG_r_Link5">
    <inertial>
      <origin
        xyz="0.011864 0.006 0.011367"
        rpy="0 0 0" />
      <mass
        value="0.0045068" />
      <inertia
        ixx="5.1288E-07"
        ixy="-9.8137E-14"
        ixz="-9.4703E-08"
        iyy="5.3203E-07"
        iyz="-6.212E-14"
        izz="2.009E-07" />
    </inertial>
    <visual>
      <origin
        xyz="0 0 0"
        rpy="0 0 0" />
      <geometry>
        <mesh
          filename="Bot2_ZPF_L2Fgripper_R2Fgripper_A_description/meshes/2FEG_r_Link5.STL" />
      </geometry>
      <material
        name="">
        <color
          rgba="0.75294 0.75294 0.75294 1" />
      </material>
    </visual>
    <collision>
      <origin
        xyz="0 0 0"
        rpy="0 0 0" />
      <geometry>
        <mesh
          filename="Bot2_ZPF_L2Fgripper_R2Fgripper_A_description/meshes/2FEG_r_Link5.STL" />
      </geometry>
    </collision>
  </link>
  <joint
    name="2FEG_r_Joint5"
    type="revolute">
    <origin
      xyz="0.0223 0.003 0.035591"
      rpy="0 0 0" />
    <parent
      link="2FEG_r_Link1" />
    <child
      link="2FEG_r_Link5" />
    <axis
      xyz="0 1 0" />
    <limit
      lower="0"
      upper="0.82"
      effort="1"
      velocity="1" />
    <mimic joint="2FEG_r_Joint1"/>
  </joint>
  <link
    name="2FEG_r_Link2">
    <inertial>
      <origin
        xyz="0.0087435 0.009 0.013955"
        rpy="0 0 0" />
      <mass
        value="0.0038971" />
      <inertia
        ixx="5.6941E-07"
        ixy="-1.0711E-18"
        ixz="-2.6891E-07"
        iyy="6.2305E-07"
        iyz="-1.6845E-18"
        izz="3.0871E-07" />
    </inertial>
    <visual>
      <origin
        xyz="0 0 0"
        rpy="0 0 0" />
      <geometry>
        <mesh
          filename="Bot2_ZPF_L2Fgripper_R2Fgripper_A_description/meshes/2FEG_r_Link2.STL" />
      </geometry>
      <material
        name="">
        <color
          rgba="0.75294 0.75294 0.75294 1" />
      </material>
    </visual>
    <collision>
      <origin
        xyz="0 0 0"
        rpy="0 0 0" />
      <geometry>
        <mesh
          filename="Bot2_ZPF_L2Fgripper_R2Fgripper_A_description/meshes/2FEG_r_Link2.STL" />
      </geometry>
    </collision>
  </link>
  <joint
    name="2FEG_r_Joint2"
    type="revolute">
    <origin
      xyz="-0.03 -0.009 0.081"
      rpy="0 0 0" />
    <parent
      link="2FEG_r_baselink" />
    <child
      link="2FEG_r_Link2" />
    <axis
      xyz="0 -1 0" />
    <limit
      lower="0"
      upper="0.82"
      effort="1"
      velocity="1" />
    <mimic joint="2FEG_r_Joint1"/>
  </joint>
  <link
    name="2FEG_r_Link3">
    <inertial>
      <origin
        xyz="-0.0087435 0.009 0.013955"
        rpy="0 0 0" />
      <mass
        value="0.0038971" />
      <inertia
        ixx="5.6941E-07"
        ixy="1.0666E-18"
        ixz="2.6891E-07"
        iyy="6.2305E-07"
        iyz="-1.8084E-18"
        izz="3.0871E-07" />
    </inertial>
    <visual>
      <origin
        xyz="0 0 0"
        rpy="0 0 0" />
      <geometry>
        <mesh
          filename="Bot2_ZPF_L2Fgripper_R2Fgripper_A_description/meshes/2FEG_r_Link3.STL" />
      </geometry>
      <material
        name="">
        <color
          rgba="0.75294 0.75294 0.75294 1" />
      </material>
    </visual>
    <collision>
      <origin
        xyz="0 0 0"
        rpy="0 0 0" />
      <geometry>
        <mesh
          filename="Bot2_ZPF_L2Fgripper_R2Fgripper_A_description/meshes/2FEG_r_Link3.STL" />
      </geometry>
    </collision>
  </link>
  <joint
    name="2FEG_r_Joint3"
    type="revolute">
    <origin
      xyz="0.03 -0.009 0.081"
      rpy="0 0 0" />
    <parent
      link="2FEG_r_baselink" />
    <child
      link="2FEG_r_Link3" />
    <axis
      xyz="0 -1 0" />
    <limit
      lower="-0.82"
      upper="0"
      effort="1"
      velocity="1" />
    <mimic joint="2FEG_r_Joint1" multiplier="-1"  offset="0"/>
  </joint>
  <link
    name="2FEG_r_Link4">
    <inertial>
      <origin
        xyz="-0.0087669 0.009 0.013992"
        rpy="0 0 0" />
      <mass
        value="0.0024292" />
      <inertia
        ixx="5.1061E-07"
        ixy="-9.5279E-19"
        ixz="2.508E-07"
        iyy="5.7398E-07"
        iyz="7.6863E-19"
        izz="2.6747E-07" />
    </inertial>
    <visual>
      <origin
        xyz="0 0 0"
        rpy="0 0 0" />
      <geometry>
        <mesh
          filename="Bot2_ZPF_L2Fgripper_R2Fgripper_A_description/meshes/2FEG_r_Link4.STL" />
      </geometry>
      <material
        name="">
        <color
          rgba="0.75294 0.75294 0.75294 1" />
      </material>
    </visual>
    <collision>
      <origin
        xyz="0 0 0"
        rpy="0 0 0" />
      <geometry>
        <mesh
          filename="Bot2_ZPF_L2Fgripper_R2Fgripper_A_description/meshes/2FEG_r_Link4.STL" />
      </geometry>
    </collision>
  </link>
  <joint
    name="2FEG_r_Joint4"
    type="revolute">
    <origin
      xyz="0.04 -0.009 0.079"
      rpy="0 0 0" />
    <parent
      link="2FEG_r_baselink" />
    <child
      link="2FEG_r_Link4" />
    <axis
      xyz="0 -1 0" />
    <limit
      lower="-0.82"
      upper="0"
      effort="1"
      velocity="1" />
    <mimic joint="2FEG_r_Joint1" multiplier="-1"  offset="0"/>
  </joint>
  <link
    name="2FEG_r_Link6">
    <inertial>
      <origin
        xyz="-0.011864 0.006 0.011367"
        rpy="0 0 0" />
      <mass
        value="0.0045068" />
      <inertia
        ixx="5.1288E-07"
        ixy="-9.8137E-14"
        ixz="9.4703E-08"
        iyy="5.3203E-07"
        iyz="6.2119E-14"
        izz="2.009E-07" />
    </inertial>
    <visual>
      <origin
        xyz="0 0 0"
        rpy="0 0 0" />
      <geometry>
        <mesh
          filename="Bot2_ZPF_L2Fgripper_R2Fgripper_A_description/meshes/2FEG_r_Link6.STL" />
      </geometry>
      <material
        name="">
        <color
          rgba="0.75294 0.75294 0.75294 1" />
      </material>
    </visual>
    <collision>
      <origin
        xyz="0 0 0"
        rpy="0 0 0" />
      <geometry>
        <mesh
          filename="Bot2_ZPF_L2Fgripper_R2Fgripper_A_description/meshes/2FEG_r_Link6.STL" />
      </geometry>
    </collision>
  </link>
  <joint
    name="2FEG_r_Joint6"
    type="revolute">
    <origin
      xyz="-0.0223 0.003 0.035591"
      rpy="0 0 0" />
    <parent
      link="2FEG_r_Link4" />
    <child
      link="2FEG_r_Link6" />
    <axis
      xyz="0 -1 0" />
    <limit
      lower="0"
      upper="0.82"
      effort="1"
      velocity="1" />
    <mimic joint="2FEG_r_Joint1"/>
  </joint>
  <transmission name="gripper_finger1_trans">
    <type>transmission_interface/SimpleTransmission</type>
    <joint name="2FEG_l_Joint1">
      <hardwareInterface>PositionJointInterface</hardwareInterface>
    </joint>
    <joint name="2FEG_r_Joint1">
      <hardwareInterface>PositionJointInterface</hardwareInterface>
    </joint>
    <actuator name="gripper_finger1_motor">
      <mechanicalReduction>1</mechanicalReduction>
      <hardwareInterface>PositionJointInterface</hardwareInterface>
    </actuator>
  </transmission>
</robot>